Workbook

Sheet Instruções
A1: Avaliação de Desempenho por Squad — GP + Líder Técnico
A2: Versão 1 · construída com as visões de RH, Gerência de Projetos e Liderança Técnica · revisar e ajustar antes de usar em produção
A4: COMO ESTA PLANILHA FUNCIONA
B5: O registro contínuo é o produto; a nota é subproduto. Se você só conseguir manter uma aba viva, mantenha 'Ocorrências'. Uma nota sem ocorrência vinculada não é avaliação, é impressão.
A6: RITMO DE USO
A7: Quando acontecer (60 segundos) | B7: Lance uma ocorrência. Meta realista: 2 a 4 por colaborador por mês, com ao menos 1 positiva a cada 2 registros.
A8: Sexta-feira (15 min / squad) | B8: Abra o 'Painel'. Olhe quem está sem registro e sem 1:1. Não avalie nada.
A9: Fim de ciclo (20 min / pessoa) | B9: Preencha 'Avaliação'. Você não escreve do zero: lê o que já foi acumulado.
A10: Antes da devolutiva | B10: Calibração GP × Líder Técnico apenas nos itens divergentes. Depois, 1:1 com a aba 'Pauta 1a1'.
A11: QUEM AVALIA O QUÊ
A12: Líder Técnico (palavra final no técnico) | B12: Qualidade da entrega, domínio técnico, design de solução, rigor operacional, colaboração e review, desenvolvimento de outros.
A13: GP (palavra final na entrega) | B13: Previsibilidade, comunicação, confiabilidade e conduta.
A14: Compartilhado | B14: Foco em valor, autonomia e ownership. Quem não tem evidência deixa em branco — em branco é resposta legítima e melhor que chute.
A15: AS SEIS REGRAS DURAS
A16: Regra 1 | B16: 3 é 'atende plenamente o esperado PARA A SENIORIDADE'. Não é nota ruim. Um Júnior 3 e um Sênior 3 são comportamentos diferentes — leia a âncora do nível na aba 'Âncoras'.
A17: Regra 2 | B17: Nota 1, 2 ou 5 exige pelo menos uma ocorrência vinculada àquela competência no ciclo. Sem lastro, a célula acusa e a avaliação não fecha.
A18: Regra 3 | B18: Nunca calcule a média entre a nota do GP e a do Líder Técnico. A divergência é a informação mais valiosa da planilha — ela é a pauta da calibração.
A19: Regra 4 | B19: Ocorrência negativa que nunca foi conversada com a pessoa não entra no ciclo. Surpresa na avaliação é falha de gestão, não do colaborador.
A20: Regra 5 | B20: O campo 'Fato observável' não aceita adjetivo de personalidade. Escreva 'Subiu hotfix sem aprovação na sexta 18h', não 'é descuidado'. O juízo vai em 'Impacto', e tem que ser defensável a partir do fato ao lado.
A21: Regra 6 | B21: Comparação e ranking usam SEMPRE o gap contra a expectativa da senioridade, nunca a nota bruta, e nunca entre squads diferentes.
A22: LGPD E CONDUTA — LEIA ANTES DE ESCREVER
B23: Não registre dado sensível: saúde, diagnóstico, religião, orientação sexual, filiação sindical, origem racial, vida familiar. Ausência registra o FATO, nunca o motivo.
B24: Caso de conduta, assédio, discriminação ou segurança da informação NÃO é apurado aqui: registre apenas 'encaminhado ao RH em <data>' e a apuração corre em processo próprio.
B25: O colaborador pode pedir acesso ao que se registrou sobre ele. Regra prática: não escreva nada que você não sustentaria lendo em voz alta para a pessoa.
B26: Arquivo único no drive corporativo, com coautoria. Nunca anexo de e-mail, nunca cópia local. Senha de planilha do Excel não é controle de acesso.
A27: LEGENDA DE CORES
A28: Fundo amarelo, texto azul | B28: Célula que VOCÊ preenche.
A29: Fundo cinza | B29: Célula calculada. Não digite por cima — você quebra o cálculo do painel.
B30: As abas 'Colaboradores', 'Competências', 'Âncoras' e 'Config' são o cadastro: ajuste-as uma vez, no começo, e não mexa mais no dia a dia.
A31: LIMITE HONESTO DESTA FERRAMENTA
B32: Excel não tem controle de acesso por linha nem trilha de auditoria confiável. Ocorrências 'RH-restrito' deveriam viver em arquivo separado, só do RH. Use esta planilha para provar o modelo em 2–3 ciclos; se funcionar, migre para um sistema.

Sheet Painel
A1: Painel do gestor — o que abrir na segunda de manhã
A2: Uma linha por alocação, no ciclo ativo definido em Config. Comparação SEMPRE por gap contra a expectativa da senioridade, nunca por nota bruta.
A3: ="Ciclo ativo: "&Config!$B$4&" · Sinal ⚠ = bloqueio de integridade (nota sem lastro ou ocorrência negativa nunca conversada). Resolva antes de fechar o ciclo."
A4: ID | B4: Colaborador | C4: Squad | D4: Papel | E4: Senioridade | F4: Situação | G4: Em rampa? | H4: Eixo A | I4: Eixo B | J4: Eixo C | K4: Eixo D | L4: Nota ponderada | M4: Expectativa | N4: Gap | O4: Faixa | P4: Ocorr. no ciclo | Q4: Positivas | R4: Atenção / Incidente | S4: Dias s/ ocorrência | T4: Dias desde 1:1 | U4: Divergências ≥2 | V4: Notas sem lastro | W4: Negativas não informadas | X4: Amplitude das notas | Y4: Sinal | AA4: aux peso A | AB4: aux peso B | AC4: aux peso C | AD4: aux peso D | AE4: aux numerador | AF4: aux denominador
A5: =IF(Colaboradores!$B5="","",Colaboradores!$A5) | B5: =IF(Colaboradores!$B5="","",Colaboradores!$B5) | C5: =IF(Colaboradores!$B5="","",Colaboradores!$F5) | D5: =IF(Colaboradores!$B5="","",Colaboradores!$D5) | E5: =IF(Colaboradores!$B5="","",Colaboradores!$E5) | F5: =IF(Colaboradores!$B5="","",Colaboradores!$O5) | G5: =IF(Colaboradores!$B5="","",Colaboradores!$P5) | H5: =IF($B5="","",IFERROR(AVERAGEIFS(Avaliação!$M:$M,Avaliação!$B:$B,$A5,Avaliação!$A:$A,Config!$B$4,Avaliação!$G:$G,Config!$A$17),"")) | I5: =IF($B5="","",IFERROR(AVERAGEIFS(Avaliação!$M:$M,Avaliação!$B:$B,$A5,Avaliação!$A:$A,Config!$B$4,Avaliação!$G:$G,Config!$A$18),"")) | J5: =IF($B5="","",IFERROR(AVERAGEIFS(Avaliação!$M:$M,Avaliação!$B:$B,$A5,Avaliação!$A:$A,Config!$B$4,Avaliação!$G:$G,Config!$A$19),"")) | K5: =IF($B5="","",IFERROR(AVERAGEIFS(Avaliação!$M:$M,Avaliação!$B:$B,$A5,Avaliação!$A:$A,Config!$B$4,Avaliação!$G:$G,Config!$A$20),"")) | L5: =IF($AF5=0,"",$AE5/$AF5) | M5: =IFERROR(INDEX(Config!$B$25:$B$28,MATCH($E5,Config!$A$25:$A$28,0)),"") | N5: =IF(OR($L5="",$M5=""),"",$L5-$M5) | O5: =IF($L5="","",IF($L5<2.5,"Abaixo",IF($L5<3.5,"Atende",IF($L5<=4.2,"Supera","Referência")))) | P5: =IF($B5="","",COUNTIFS(Ocorrências!$B:$B,$B5,Ocorrências!$N:$N,Config!$B$4)) | Q5: =IF($B5="","",COUNTIFS(Ocorrências!$B:$B,$B5,Ocorrências!$N:$N,Config!$B$4,Ocorrências!$E:$E,"Reconhecimento")+COUNTIFS(Ocorrências!$B:$B,$B5,Ocorrências!$N:$N,Config!$B$4,Ocorrências!$E:$E,"Positiva")) | R5: =IF($B5="","",COUNTIFS(Ocorrências!$B:$B,$B5,Ocorrências!$N:$N,Config!$B$4,Ocorrências!$E:$E,"Ponto de atenção")+COUNTIFS(Ocorrências!$B:$B,$B5,Ocorrências!$N:$N,Config!$B$4,Ocorrências!$E:$E,"Incidente")) | S5: =IF($B5="","",IF(COUNTIF(Ocorrências!$B:$B,$B5)=0,"",TODAY()-_xlfn.MAXIFS(Ocorrências!$A:$A,Ocorrências!$B:$B,$B5))) | T5: =IF($B5="","",IF(COUNTIF('Reuniões 1a1'!$B:$B,$B5)=0,"",TODAY()-_xlfn.MAXIFS('Reuniões 1a1'!$A:$A,'Reuniões 1a1'!$B:$B,$B5))) | U5: =IF($B5="","",COUNTIFS(Avaliação!$B:$B,$A5,Avaliação!$A:$A,Config!$B$4,Avaliação!$K:$K,">=2")) | V5: =IF($B5="","",COUNTIFS(Avaliação!$B:$B,$A5,Avaliação!$A:$A,Config!$B$4,Avaliação!$O:$O,"SEM LASTRO")) | W5: =IF($B5="","",COUNTIFS(Ocorrências!$B:$B,$B5,Ocorrências!$N:$N,Config!$B$4,Ocorrências!$K:$K,"Não",Ocorrências!$E:$E,"Ponto de atenção")+COUNTIFS(Ocorrências!$B:$B,$B5,Ocorrências!$N:$N,Config!$B$4,Ocorrências!$K:$K,"Não",Ocorrências!$E:$E,"Incidente")) | X5: =IF($L5="","",_xlfn.MAXIFS(Avaliação!$M:$M,Avaliação!$B:$B,$A5,Avaliação!$A:$A,Config!$B$4)-_xlfn.MINIFS(Avaliação!$M:$M,Avaliação!$B:$B,$A5,Avaliação!$A:$A,Config!$B$4)) | Y5: =IF($B5="","",IF(OR($V5>0,$W5>0),"BLOQUEIO",IF($L5="","Sem avaliação",IF($N5<-0.3,"Abaixo da expectativa",IF($U5>0,"Calibrar",IF($X5=0,"Nota chapada",IF(IF($T5="",0,$T5)>30,"1:1 atrasada",IF(IF($S5="",99,$S5)>45,"Sem registro","OK")))))))) | AA5: =IFERROR(INDEX(Config!$B$17:$E$20,MATCH(Config!$A$17,Config!$A$17:$A$20,0),MATCH($D5,Config!$B$16:$E$16,0)),0) | AB5: =IFERROR(INDEX(Config!$B$17:$E$20,MATCH(Config!$A$18,Config!$A$17:$A$20,0),MATCH($D5,Config!$B$16:$E$16,0)),0) | AC5: =IFERROR(INDEX(Config!$B$17:$E$20,MATCH(Config!$A$19,Config!$A$17:$A$20,0),MATCH($D5,Config!$B$16:$E$16,0)),0) | AD5: =IFERROR(INDEX(Config!$B$17:$E$20,MATCH(Config!$A$20,Config!$A$17:$A$20,0),MATCH($D5,Config!$B$16:$E$16,0)),0) | AE5: =IFERROR($H5*$AA5,0)+IFERROR($I5*$AB5,0)+IFERROR($J5*$AC5,0)+IFERROR($K5*$AD5,0) | AF5: =IF(ISNUMBER($H5),$AA5,0)+IF(ISNUMBER($I5),$AB5,0)+IF(ISNUMBER($J5),$AC5,0)+IF(ISNUMBER($K5),$AD5,0)
A6: =IF(Colaboradores!$B6="","",Colaboradores!$A6) | B6: =IF(Colaboradores!$B6="","",Colaboradores!$B6) | C6: =IF(Colaboradores!$B6="","",Colaboradores!$F6) | D6: =IF(Colaboradores!$B6="","",Colaboradores!$D6) | E6: =IF(Colaboradores!$B6="","",Colaboradores!$E6) | F6: =IF(Colaboradores!$B6="","",Colaboradores!$O6) | G6: =IF(Colaboradores!$B6="","",Colaboradores!$P6) | H6: =IF($B6="","",IFERROR(AVERAGEIFS(Avaliação!$M:$M,Avaliação!$B:$B,$A6,Avaliação!$A:$A,Config!$B$4,Avaliação!$G:$G,Config!$A$17),"")) | I6: =IF($B6="","",IFERROR(AVERAGEIFS(Avaliação!$M:$M,Avaliação!$B:$B,$A6,Avaliação!$A:$A,Config!$B$4,Avaliação!$G:$G,Config!$A$18),"")) | J6: =IF($B6="","",IFERROR(AVERAGEIFS(Avaliação!$M:$M,Avaliação!$B:$B,$A6,Avaliação!$A:$A,Config!$B$4,Avaliação!$G:$G,Config!$A$19),"")) | K6: =IF($B6="","",IFERROR(AVERAGEIFS(Avaliação!$M:$M,Avaliação!$B:$B,$A6,Avaliação!$A:$A,Config!$B$4,Avaliação!$G:$G,Config!$A$20),"")) | L6: =IF($AF6=0,"",$AE6/$AF6) | M6: =IFERROR(INDEX(Config!$B$25:$B$28,MATCH($E6,Config!$A$25:$A$28,0)),"") | N6: =IF(OR($L6="",$M6=""),"",$L6-$M6) | O6: =IF($L6="","",IF($L6<2.5,"Abaixo",IF($L6<3.5,"Atende",IF($L6<=4.2,"Supera","Referência")))) | P6: =IF($B6="","",COUNTIFS(Ocorrências!$B:$B,$B6,Ocorrências!$N:$N,Config!$B$4)) | Q6: =IF($B6="","",COUNTIFS(Ocorrências!$B:$B,$B6,Ocorrências!$N:$N,Config!$B$4,Ocorrências!$E:$E,"Reconhecimento")+COUNTIFS(Ocorrências!$B:$B,$B6,Ocorrências!$N:$N,Config!$B$4,Ocorrências!$E:$E,"Positiva")) | R6: =IF($B6="","",COUNTIFS(Ocorrências!$B:$B,$B6,Ocorrências!$N:$N,Config!$B$4,Ocorrências!$E:$E,"Ponto de atenção")+COUNTIFS(Ocorrências!$B:$B,$B6,Ocorrências!$N:$N,Config!$B$4,Ocorrências!$E:$E,"Incidente")) | S6: =IF($B6="","",IF(COUNTIF(Ocorrências!$B:$B,$B6)=0,"",TODAY()-_xlfn.MAXIFS(Ocorrências!$A:$A,Ocorrências!$B:$B,$B6))) | T6: =IF($B6="","",IF(COUNTIF('Reuniões 1a1'!$B:$B,$B6)=0,"",TODAY()-_xlfn.MAXIFS('Reuniões 1a1'!$A:$A,'Reuniões 1a1'!$B:$B,$B6))) | U6: =IF($B6="","",COUNTIFS(Avaliação!$B:$B,$A6,Avaliação!$A:$A,Config!$B$4,Avaliação!$K:$K,">=2")) | V6: =IF($B6="","",COUNTIFS(Avaliação!$B:$B,$A6,Avaliação!$A:$A,Config!$B$4,Avaliação!$O:$O,"SEM LASTRO")) | W6: =IF($B6="","",COUNTIFS(Ocorrências!$B:$B,$B6,Ocorrências!$N:$N,Config!$B$4,Ocorrências!$K:$K,"Não",Ocorrências!$E:$E,"Ponto de atenção")+COUNTIFS(Ocorrências!$B:$B,$B6,Ocorrências!$N:$N,Config!$B$4,Ocorrências!$K:$K,"Não",Ocorrências!$E:$E,"Incidente")) | X6: =IF($L6="","",_xlfn.MAXIFS(Avaliação!$M:$M,Avaliação!$B:$B,$A6,Avaliação!$A:$A,Config!$B$4)-_xlfn.MINIFS(Avaliação!$M:$M,Avaliação!$B:$B,$A6,Avaliação!$A:$A,Config!$B$4)) | Y6: =IF($B6="","",IF(OR($V6>0,$W6>0),"BLOQUEIO",IF($L6="","Sem avaliação",IF($N6<-0.3,"Abaixo da expectativa",IF($U6>0,"Calibrar",IF($X6=0,"Nota chapada",IF(IF($T6="",0,$T6)>30,"1:1 atrasada",IF(IF($S6="",99,$S6)>45,"Sem registro","OK")))))))) | AA6: =IFERROR(INDEX(Config!$B$17:$E$20,MATCH(Config!$A$17,Config!$A$17:$A$20,0),MATCH($D6,Config!$B$16:$E$16,0)),0) | AB6: =IFERROR(INDEX(Config!$B$17:$E$20,MATCH(Config!$A$18,Config!$A$17:$A$20,0),MATCH($D6,Config!$B$16:$E$16,0)),0) | AC6: =IFERROR(INDEX(Config!$B$17:$E$20,MATCH(Config!$A$19,Config!$A$17:$A$20,0),MATCH($D6,Config!$B$16:$E$16,0)),0) | AD6: =IFERROR(INDEX(Config!$B$17:$E$20,MATCH(Config!$A$20,Config!$A$17:$A$20,0),MATCH($D6,Config!$B$16:$E$16,0)),0) | AE6: =IFERROR($H6*$AA6,0)+IFERROR($I6*$AB6,0)+IFERROR($J6*$AC6,0)+IFERROR($K6*$AD6,0) | AF6: =IF(ISNUMBER($H6),$AA6,0)+IF(ISNUMBER($I6),$AB6,0)+IF(ISNUMBER($J6),$AC6,0)+IF(ISNUMBER($K6),$AD6,0)
A7: =IF(Colaboradores!$B7="","",Colaboradores!$A7) | B7: =IF(Colaboradores!$B7="","",Colaboradores!$B7) | C7: =IF(Colaboradores!$B7="","",Colaboradores!$F7) | D7: =IF(Colaboradores!$B7="","",Colaboradores!$D7) | E7: =IF(Colaboradores!$B7="","",Colaboradores!$E7) | F7: =IF(Colaboradores!$B7="","",Colaboradores!$O7) | G7: =IF(Colaboradores!$B7="","",Colaboradores!$P7) | H7: =IF($B7="","",IFERROR(AVERAGEIFS(Avaliação!$M:$M,Avaliação!$B:$B,$A7,Avaliação!$A:$A,Config!$B$4,Avaliação!$G:$G,Config!$A$17),"")) | I7: =IF($B7="","",IFERROR(AVERAGEIFS(Avaliação!$M:$M,Avaliação!$B:$B,$A7,Avaliação!$A:$A,Config!$B$4,Avaliação!$G:$G,Config!$A$18),"")) | J7: =IF($B7="","",IFERROR(AVERAGEIFS(Avaliação!$M:$M,Avaliação!$B:$B,$A7,Avaliação!$A:$A,Config!$B$4,Avaliação!$G:$G,Config!$A$19),"")) | K7: =IF($B7="","",IFERROR(AVERAGEIFS(Avaliação!$M:$M,Avaliação!$B:$B,$A7,Avaliação!$A:$A,Config!$B$4,Avaliação!$G:$G,Config!$A$20),"")) | L7: =IF($AF7=0,"",$AE7/$AF7) | M7: =IFERROR(INDEX(Config!$B$25:$B$28,MATCH($E7,Config!$A$25:$A$28,0)),"") | N7: =IF(OR($L7="",$M7=""),"",$L7-$M7) | O7: =IF($L7="","",IF($L7<2.5,"Abaixo",IF($L7<3.5,"Atende",IF($L7<=4.2,"Supera","Referência")))) | P7: =IF($B7="","",COUNTIFS(Ocorrências!$B:$B,$B7,Ocorrências!$N:$N,Config!$B$4)) | Q7: =IF($B7="","",COUNTIFS(Ocorrências!$B:$B,$B7,Ocorrências!$N:$N,Config!$B$4,Ocorrências!$E:$E,"Reconhecimento")+COUNTIFS(Ocorrências!$B:$B,$B7,Ocorrências!$N:$N,Config!$B$4,Ocorrências!$E:$E,"Positiva")) | R7: =IF($B7="","",COUNTIFS(Ocorrências!$B:$B,$B7,Ocorrências!$N:$N,Config!$B$4,Ocorrências!$E:$E,"Ponto de atenção")+COUNTIFS(Ocorrências!$B:$B,$B7,Ocorrências!$N:$N,Config!$B$4,Ocorrências!$E:$E,"Incidente")) | S7: =IF($B7="","",IF(COUNTIF(Ocorrências!$B:$B,$B7)=0,"",TODAY()-_xlfn.MAXIFS(Ocorrências!$A:$A,Ocorrências!$B:$B,$B7))) | T7: =IF($B7="","",IF(COUNTIF('Reuniões 1a1'!$B:$B,$B7)=0,"",TODAY()-_xlfn.MAXIFS('Reuniões 1a1'!$A:$A,'Reuniões 1a1'!$B:$B,$B7))) | U7: =IF($B7="","",COUNTIFS(Avaliação!$B:$B,$A7,Avaliação!$A:$A,Config!$B$4,Avaliação!$K:$K,">=2")) | V7: =IF($B7="","",COUNTIFS(Avaliação!$B:$B,$A7,Avaliação!$A:$A,Config!$B$4,Avaliação!$O:$O,"SEM LASTRO")) | W7: =IF($B7="","",COUNTIFS(Ocorrências!$B:$B,$B7,Ocorrências!$N:$N,Config!$B$4,Ocorrências!$K:$K,"Não",Ocorrências!$E:$E,"Ponto de atenção")+COUNTIFS(Ocorrências!$B:$B,$B7,Ocorrências!$N:$N,Config!$B$4,Ocorrências!$K:$K,"Não",Ocorrências!$E:$E,"Incidente")) | X7: =IF($L7="","",_xlfn.MAXIFS(Avaliação!$M:$M,Avaliação!$B:$B,$A7,Avaliação!$A:$A,Config!$B$4)-_xlfn.MINIFS(Avaliação!$M:$M,Avaliação!$B:$B,$A7,Avaliação!$A:$A,Config!$B$4)) | Y7: =IF($B7="","",IF(OR($V7>0,$W7>0),"BLOQUEIO",IF($L7="","Sem avaliação",IF($N7<-0.3,"Abaixo da expectativa",IF($U7>0,"Calibrar",IF($X7=0,"Nota chapada",IF(IF($T7="",0,$T7)>30,"1:1 atrasada",IF(IF($S7="",99,$S7)>45,"Sem registro","OK")))))))) | AA7: =IFERROR(INDEX(Config!$B$17:$E$20,MATCH(Config!$A$17,Config!$A$17:$A$20,0),MATCH($D7,Config!$B$16:$E$16,0)),0) | AB7: =IFERROR(INDEX(Config!$B$17:$E$20,MATCH(Config!$A$18,Config!$A$17:$A$20,0),MATCH($D7,Config!$B$16:$E$16,0)),0) | AC7: =IFERROR(INDEX(Config!$B$17:$E$20,MATCH(Config!$A$19,Config!$A$17:$A$20,0),MATCH($D7,Config!$B$16:$E$16,0)),0) | AD7: =IFERROR(INDEX(Config!$B$17:$E$20,MATCH(Config!$A$20,Config!$A$17:$A$20,0),MATCH($D7,Config!$B$16:$E$16,0)),0) | AE7: =IFERROR($H7*$AA7,0)+IFERROR($I7*$AB7,0)+IFERROR($J7*$AC7,0)+IFERROR($K7*$AD7,0) | AF7: =IF(ISNUMBER($H7),$AA7,0)+IF(ISNUMBER($I7),$AB7,0)+IF(ISNUMBER($J7),$AC7,0)+IF(ISNUMBER($K7),$AD7,0)
A8: =IF(Colaboradores!$B8="","",Colaboradores!$A8) | B8: =IF(Colaboradores!$B8="","",Colaboradores!$B8) | C8: =IF(Colaboradores!$B8="","",Colaboradores!$F8) | D8: =IF(Colaboradores!$B8="","",Colaboradores!$D8) | E8: =IF(Colaboradores!$B8="","",Colaboradores!$E8) | F8: =IF(Colaboradores!$B8="","",Colaboradores!$O8) | G8: =IF(Colaboradores!$B8="","",Colaboradores!$P8) | H8: =IF($B8="","",IFERROR(AVERAGEIFS(Avaliação!$M:$M,Avaliação!$B:$B,$A8,Avaliação!$A:$A,Config!$B$4,Avaliação!$G:$G,Config!$A$17),"")) | I8: =IF($B8="","",IFERROR(AVERAGEIFS(Avaliação!$M:$M,Avaliação!$B:$B,$A8,Avaliação!$A:$A,Config!$B$4,Avaliação!$G:$G,Config!$A$18),"")) | J8: =IF($B8="","",IFERROR(AVERAGEIFS(Avaliação!$M:$M,Avaliação!$B:$B,$A8,Avaliação!$A:$A,Config!$B$4,Avaliação!$G:$G,Config!$A$19),"")) | K8: =IF($B8="","",IFERROR(AVERAGEIFS(Avaliação!$M:$M,Avaliação!$B:$B,$A8,Avaliação!$A:$A,Config!$B$4,Avaliação!$G:$G,Config!$A$20),"")) | L8: =IF($AF8=0,"",$AE8/$AF8) | M8: =IFERROR(INDEX(Config!$B$25:$B$28,MATCH($E8,Config!$A$25:$A$28,0)),"") | N8: =IF(OR($L8="",$M8=""),"",$L8-$M8) | O8: =IF($L8="","",IF($L8<2.5,"Abaixo",IF($L8<3.5,"Atende",IF($L8<=4.2,"Supera","Referência")))) | P8: =IF($B8="","",COUNTIFS(Ocorrências!$B:$B,$B8,Ocorrências!$N:$N,Config!$B$4)) | Q8: =IF($B8="","",COUNTIFS(Ocorrências!$B:$B,$B8,Ocorrências!$N:$N,Config!$B$4,Ocorrências!$E:$E,"Reconhecimento")+COUNTIFS(Ocorrências!$B:$B,$B8,Ocorrências!$N:$N,Config!$B$4,Ocorrências!$E:$E,"Positiva")) | R8: =IF($B8="","",COUNTIFS(Ocorrências!$B:$B,$B8,Ocorrências!$N:$N,Config!$B$4,Ocorrências!$E:$E,"Ponto de atenção")+COUNTIFS(Ocorrências!$B:$B,$B8,Ocorrências!$N:$N,Config!$B$4,Ocorrências!$E:$E,"Incidente")) | S8: =IF($B8="","",IF(COUNTIF(Ocorrências!$B:$B,$B8)=0,"",TODAY()-_xlfn.MAXIFS(Ocorrências!$A:$A,Ocorrências!$B:$B,$B8))) | T8: =IF($B8="","",IF(COUNTIF('Reuniões 1a1'!$B:$B,$B8)=0,"",TODAY()-_xlfn.MAXIFS('Reuniões 1a1'!$A:$A,'Reuniões 1a1'!$B:$B,$B8))) | U8: =IF($B8="","",COUNTIFS(Avaliação!$B:$B,$A8,Avaliação!$A:$A,Config!$B$4,Avaliação!$K:$K,">=2")) | V8: =IF($B8="","",COUNTIFS(Avaliação!$B:$B,$A8,Avaliação!$A:$A,Config!$B$4,Avaliação!$O:$O,"SEM LASTRO")) | W8: =IF($B8="","",COUNTIFS(Ocorrências!$B:$B,$B8,Ocorrências!$N:$N,Config!$B$4,Ocorrências!$K:$K,"Não",Ocorrências!$E:$E,"Ponto de atenção")+COUNTIFS(Ocorrências!$B:$B,$B8,Ocorrências!$N:$N,Config!$B$4,Ocorrências!$K:$K,"Não",Ocorrências!$E:$E,"Incidente")) | X8: =IF($L8="","",_xlfn.MAXIFS(Avaliação!$M:$M,Avaliação!$B:$B,$A8,Avaliação!$A:$A,Config!$B$4)-_xlfn.MINIFS(Avaliação!$M:$M,Avaliação!$B:$B,$A8,Avaliação!$A:$A,Config!$B$4)) | Y8: =IF($B8="","",IF(OR($V8>0,$W8>0),"BLOQUEIO",IF($L8="","Sem avaliação",IF($N8<-0.3,"Abaixo da expectativa",IF($U8>0,"Calibrar",IF($X8=0,"Nota chapada",IF(IF($T8="",0,$T8)>30,"1:1 atrasada",IF(IF($S8="",99,$S8)>45,"Sem registro","OK")))))))) | AA8: =IFERROR(INDEX(Config!$B$17:$E$20,MATCH(Config!$A$17,Config!$A$17:$A$20,0),MATCH($D8,Config!$B$16:$E$16,0)),0) | AB8: =IFERROR(INDEX(Config!$B$17:$E$20,MATCH(Config!$A$18,Config!$A$17:$A$20,0),MATCH($D8,Config!$B$16:$E$16,0)),0) | AC8: =IFERROR(INDEX(Config!$B$17:$E$20,MATCH(Config!$A$19,Config!$A$17:$A$20,0),MATCH($D8,Config!$B$16:$E$16,0)),0) | AD8: =IFERROR(INDEX(Config!$B$17:$E$20,MATCH(Config!$A$20,Config!$A$17:$A$20,0),MATCH($D8,Config!$B$16:$E$16,0)),0) | AE8: =IFERROR($H8*$AA8,0)+IFERROR($I8*$AB8,0)+IFERROR($J8*$AC8,0)+IFERROR($K8*$AD8,0) | AF8: =IF(ISNUMBER($H8),$AA8,0)+IF(ISNUMBER($I8),$AB8,0)+IF(ISNUMBER($J8),$AC8,0)+IF(ISNUMBER($K8),$AD8,0)
A9: =IF(Colaboradores!$B9="","",Colaboradores!$A9) | B9: =IF(Colaboradores!$B9="","",Colaboradores!$B9) | C9: =IF(Colaboradores!$B9="","",Colaboradores!$F9) | D9: =IF(Colaboradores!$B9="","",Colaboradores!$D9) | E9: =IF(Colaboradores!$B9="","",Colaboradores!$E9) | F9: =IF(Colaboradores!$B9="","",Colaboradores!$O9) | G9: =IF(Colaboradores!$B9="","",Colaboradores!$P9) | H9: =IF($B9="","",IFERROR(AVERAGEIFS(Avaliação!$M:$M,Avaliação!$B:$B,$A9,Avaliação!$A:$A,Config!$B$4,Avaliação!$G:$G,Config!$A$17),"")) | I9: =IF($B9="","",IFERROR(AVERAGEIFS(Avaliação!$M:$M,Avaliação!$B:$B,$A9,Avaliação!$A:$A,Config!$B$4,Avaliação!$G:$G,Config!$A$18),"")) | J9: =IF($B9="","",IFERROR(AVERAGEIFS(Avaliação!$M:$M,Avaliação!$B:$B,$A9,Avaliação!$A:$A,Config!$B$4,Avaliação!$G:$G,Config!$A$19),"")) | K9: =IF($B9="","",IFERROR(AVERAGEIFS(Avaliação!$M:$M,Avaliação!$B:$B,$A9,Avaliação!$A:$A,Config!$B$4,Avaliação!$G:$G,Config!$A$20),"")) | L9: =IF($AF9=0,"",$AE9/$AF9) | M9: =IFERROR(INDEX(Config!$B$25:$B$28,MATCH($E9,Config!$A$25:$A$28,0)),"") | N9: =IF(OR($L9="",$M9=""),"",$L9-$M9) | O9: =IF($L9="","",IF($L9<2.5,"Abaixo",IF($L9<3.5,"Atende",IF($L9<=4.2,"Supera","Referência")))) | P9: =IF($B9="","",COUNTIFS(Ocorrências!$B:$B,$B9,Ocorrências!$N:$N,Config!$B$4)) | Q9: =IF($B9="","",COUNTIFS(Ocorrências!$B:$B,$B9,Ocorrências!$N:$N,Config!$B$4,Ocorrências!$E:$E,"Reconhecimento")+COUNTIFS(Ocorrências!$B:$B,$B9,Ocorrências!$N:$N,Config!$B$4,Ocorrências!$E:$E,"Positiva")) | R9: =IF($B9="","",COUNTIFS(Ocorrências!$B:$B,$B9,Ocorrências!$N:$N,Config!$B$4,Ocorrências!$E:$E,"Ponto de atenção")+COUNTIFS(Ocorrências!$B:$B,$B9,Ocorrências!$N:$N,Config!$B$4,Ocorrências!$E:$E,"Incidente")) | S9: =IF($B9="","",IF(COUNTIF(Ocorrências!$B:$B,$B9)=0,"",TODAY()-_xlfn.MAXIFS(Ocorrências!$A:$A,Ocorrências!$B:$B,$B9))) | T9: =IF($B9="","",IF(COUNTIF('Reuniões 1a1'!$B:$B,$B9)=0,"",TODAY()-_xlfn.MAXIFS('Reuniões 1a1'!$A:$A,'Reuniões 1a1'!$B:$B,$B9))) | U9: =IF($B9="","",COUNTIFS(Avaliação!$B:$B,$A9,Avaliação!$A:$A,Config!$B$4,Avaliação!$K:$K,">=2")) | V9: =IF($B9="","",COUNTIFS(Avaliação!$B:$B,$A9,Avaliação!$A:$A,Config!$B$4,Avaliação!$O:$O,"SEM LASTRO")) | W9: =IF($B9="","",COUNTIFS(Ocorrências!$B:$B,$B9,Ocorrências!$N:$N,Config!$B$4,Ocorrências!$K:$K,"Não",Ocorrências!$E:$E,"Ponto de atenção")+COUNTIFS(Ocorrências!$B:$B,$B9,Ocorrências!$N:$N,Config!$B$4,Ocorrências!$K:$K,"Não",Ocorrências!$E:$E,"Incidente")) | X9: =IF($L9="","",_xlfn.MAXIFS(Avaliação!$M:$M,Avaliação!$B:$B,$A9,Avaliação!$A:$A,Config!$B$4)-_xlfn.MINIFS(Avaliação!$M:$M,Avaliação!$B:$B,$A9,Avaliação!$A:$A,Config!$B$4)) | Y9: =IF($B9="","",IF(OR($V9>0,$W9>0),"BLOQUEIO",IF($L9="","Sem avaliação",IF($N9<-0.3,"Abaixo da expectativa",IF($U9>0,"Calibrar",IF($X9=0,"Nota chapada",IF(IF($T9="",0,$T9)>30,"1:1 atrasada",IF(IF($S9="",99,$S9)>45,"Sem registro","OK")))))))) | AA9: =IFERROR(INDEX(Config!$B$17:$E$20,MATCH(Config!$A$17,Config!$A$17:$A$20,0),MATCH($D9,Config!$B$16:$E$16,0)),0) | AB9: =IFERROR(INDEX(Config!$B$17:$E$20,MATCH(Config!$A$18,Config!$A$17:$A$20,0),MATCH($D9,Config!$B$16:$E$16,0)),0) | AC9: =IFERROR(INDEX(Config!$B$17:$E$20,MATCH(Config!$A$19,Config!$A$17:$A$20,0),MATCH($D9,Config!$B$16:$E$16,0)),0) | AD9: =IFERROR(INDEX(Config!$B$17:$E$20,MATCH(Config!$A$20,Config!$A$17:$A$20,0),MATCH($D9,Config!$B$16:$E$16,0)),0) | AE9: =IFERROR($H9*$AA9,0)+IFERROR($I9*$AB9,0)+IFERROR($J9*$AC9,0)+IFERROR($K9*$AD9,0) | AF9: =IF(ISNUMBER($H9),$AA9,0)+IF(ISNUMBER($I9),$AB9,0)+IF(ISNUMBER($J9),$AC9,0)+IF(ISNUMBER($K9),$AD9,0)
A10: =IF(Colaboradores!$B10="","",Colaboradores!$A10) | B10: =IF(Colaboradores!$B10="","",Colaboradores!$B10) | C10: =IF(Colaboradores!$B10="","",Colaboradores!$F10) | D10: =IF(Colaboradores!$B10="","",Colaboradores!$D10) | E10: =IF(Colaboradores!$B10="","",Colaboradores!$E10) | F10: =IF(Colaboradores!$B10="","",Colaboradores!$O10) | G10: =IF(Colaboradores!$B10="","",Colaboradores!$P10) | H10: =IF($B10="","",IFERROR(AVERAGEIFS(Avaliação!$M:$M,Avaliação!$B:$B,$A10,Avaliação!$A:$A,Config!$B$4,Avaliação!$G:$G,Config!$A$17),"")) | I10: =IF($B10="","",IFERROR(AVERAGEIFS(Avaliação!$M:$M,Avaliação!$B:$B,$A10,Avaliação!$A:$A,Config!$B$4,Avaliação!$G:$G,Config!$A$18),"")) | J10: =IF($B10="","",IFERROR(AVERAGEIFS(Avaliação!$M:$M,Avaliação!$B:$B,$A10,Avaliação!$A:$A,Config!$B$4,Avaliação!$G:$G,Config!$A$19),"")) | K10: =IF($B10="","",IFERROR(AVERAGEIFS(Avaliação!$M:$M,Avaliação!$B:$B,$A10,Avaliação!$A:$A,Config!$B$4,Avaliação!$G:$G,Config!$A$20),"")) | L10: =IF($AF10=0,"",$AE10/$AF10) | M10: =IFERROR(INDEX(Config!$B$25:$B$28,MATCH($E10,Config!$A$25:$A$28,0)),"") | N10: =IF(OR($L10="",$M10=""),"",$L10-$M10) | O10: =IF($L10="","",IF($L10<2.5,"Abaixo",IF($L10<3.5,"Atende",IF($L10<=4.2,"Supera","Referência")))) | P10: =IF($B10="","",COUNTIFS(Ocorrências!$B:$B,$B10,Ocorrências!$N:$N,Config!$B$4)) | Q10: =IF($B10="","",COUNTIFS(Ocorrências!$B:$B,$B10,Ocorrências!$N:$N,Config!$B$4,Ocorrências!$E:$E,"Reconhecimento")+COUNTIFS(Ocorrências!$B:$B,$B10,Ocorrências!$N:$N,Config!$B$4,Ocorrências!$E:$E,"Positiva")) | R10: =IF($B10="","",COUNTIFS(Ocorrências!$B:$B,$B10,Ocorrências!$N:$N,Config!$B$4,Ocorrências!$E:$E,"Ponto de atenção")+COUNTIFS(Ocorrências!$B:$B,$B10,Ocorrências!$N:$N,Config!$B$4,Ocorrências!$E:$E,"Incidente")) | S10: =IF($B10="","",IF(COUNTIF(Ocorrências!$B:$B,$B10)=0,"",TODAY()-_xlfn.MAXIFS(Ocorrências!$A:$A,Ocorrências!$B:$B,$B10))) | T10: =IF($B10="","",IF(COUNTIF('Reuniões 1a1'!$B:$B,$B10)=0,"",TODAY()-_xlfn.MAXIFS('Reuniões 1a1'!$A:$A,'Reuniões 1a1'!$B:$B,$B10))) | U10: =IF($B10="","",COUNTIFS(Avaliação!$B:$B,$A10,Avaliação!$A:$A,Config!$B$4,Avaliação!$K:$K,">=2")) | V10: =IF($B10="","",COUNTIFS(Avaliação!$B:$B,$A10,Avaliação!$A:$A,Config!$B$4,Avaliação!$O:$O,"SEM LASTRO")) | W10: =IF($B10="","",COUNTIFS(Ocorrências!$B:$B,$B10,Ocorrências!$N:$N,Config!$B$4,Ocorrências!$K:$K,"Não",Ocorrências!$E:$E,"Ponto de atenção")+COUNTIFS(Ocorrências!$B:$B,$B10,Ocorrências!$N:$N,Config!$B$4,Ocorrências!$K:$K,"Não",Ocorrências!$E:$E,"Incidente")) | X10: =IF($L10="","",_xlfn.MAXIFS(Avaliação!$M:$M,Avaliação!$B:$B,$A10,Avaliação!$A:$A,Config!$B$4)-_xlfn.MINIFS(Avaliação!$M:$M,Avaliação!$B:$B,$A10,Avaliação!$A:$A,Config!$B$4)) | Y10: =IF($B10="","",IF(OR($V10>0,$W10>0),"BLOQUEIO",IF($L10="","Sem avaliação",IF($N10<-0.3,"Abaixo da expectativa",IF($U10>0,"Calibrar",IF($X10=0,"Nota chapada",IF(IF($T10="",0,$T10)>30,"1:1 atrasada",IF(IF($S10="",99,$S10)>45,"Sem registro","OK")))))))) | AA10: =IFERROR(INDEX(Config!$B$17:$E$20,MATCH(Config!$A$17,Config!$A$17:$A$20,0),MATCH($D10,Config!$B$16:$E$16,0)),0) | AB10: =IFERROR(INDEX(Config!$B$17:$E$20,MATCH(Config!$A$18,Config!$A$17:$A$20,0),MATCH($D10,Config!$B$16:$E$16,0)),0) | AC10: =IFERROR(INDEX(Config!$B$17:$E$20,MATCH(Config!$A$19,Config!$A$17:$A$20,0),MATCH($D10,Config!$B$16:$E$16,0)),0) | AD10: =IFERROR(INDEX(Config!$B$17:$E$20,MATCH(Config!$A$20,Config!$A$17:$A$20,0),MATCH($D10,Config!$B$16:$E$16,0)),0) | AE10: =IFERROR($H10*$AA10,0)+IFERROR($I10*$AB10,0)+IFERROR($J10*$AC10,0)+IFERROR($K10*$AD10,0) | AF10: =IF(ISNUMBER($H10),$AA10,0)+IF(ISNUMBER($I10),$AB10,0)+IF(ISNUMBER($J10),$AC10,0)+IF(ISNUMBER($K10),$AD10,0)
A11: =IF(Colaboradores!$B11="","",Colaboradores!$A11) | B11: =IF(Colaboradores!$B11="","",Colaboradores!$B11) | C11: =IF(Colaboradores!$B11="","",Colaboradores!$F11) | D11: =IF(Colaboradores!$B11="","",Colaboradores!$D11) | E11: =IF(Colaboradores!$B11="","",Colaboradores!$E11) | F11: =IF(Colaboradores!$B11="","",Colaboradores!$O11) | G11: =IF(Colaboradores!$B11="","",Colaboradores!$P11) | H11: =IF($B11="","",IFERROR(AVERAGEIFS(Avaliação!$M:$M,Avaliação!$B:$B,$A11,Avaliação!$A:$A,Config!$B$4,Avaliação!$G:$G,Config!$A$17),"")) | I11: =IF($B11="","",IFERROR(AVERAGEIFS(Avaliação!$M:$M,Avaliação!$B:$B,$A11,Avaliação!$A:$A,Config!$B$4,Avaliação!$G:$G,Config!$A$18),"")) | J11: =IF($B11="","",IFERROR(AVERAGEIFS(Avaliação!$M:$M,Avaliação!$B:$B,$A11,Avaliação!$A:$A,Config!$B$4,Avaliação!$G:$G,Config!$A$19),"")) | K11: =IF($B11="","",IFERROR(AVERAGEIFS(Avaliação!$M:$M,Avaliação!$B:$B,$A11,Avaliação!$A:$A,Config!$B$4,Avaliação!$G:$G,Config!$A$20),"")) | L11: =IF($AF11=0,"",$AE11/$AF11) | M11: =IFERROR(INDEX(Config!$B$25:$B$28,MATCH($E11,Config!$A$25:$A$28,0)),"") | N11: =IF(OR($L11="",$M11=""),"",$L11-$M11) | O11: =IF($L11="","",IF($L11<2.5,"Abaixo",IF($L11<3.5,"Atende",IF($L11<=4.2,"Supera","Referência")))) | P11: =IF($B11="","",COUNTIFS(Ocorrências!$B:$B,$B11,Ocorrências!$N:$N,Config!$B$4)) | Q11: =IF($B11="","",COUNTIFS(Ocorrências!$B:$B,$B11,Ocorrências!$N:$N,Config!$B$4,Ocorrências!$E:$E,"Reconhecimento")+COUNTIFS(Ocorrências!$B:$B,$B11,Ocorrências!$N:$N,Config!$B$4,Ocorrências!$E:$E,"Positiva")) | R11: =IF($B11="","",COUNTIFS(Ocorrências!$B:$B,$B11,Ocorrências!$N:$N,Config!$B$4,Ocorrências!$E:$E,"Ponto de atenção")+COUNTIFS(Ocorrências!$B:$B,$B11,Ocorrências!$N:$N,Config!$B$4,Ocorrências!$E:$E,"Incidente")) | S11: =IF($B11="","",IF(COUNTIF(Ocorrências!$B:$B,$B11)=0,"",TODAY()-_xlfn.MAXIFS(Ocorrências!$A:$A,Ocorrências!$B:$B,$B11))) | T11: =IF($B11="","",IF(COUNTIF('Reuniões 1a1'!$B:$B,$B11)=0,"",TODAY()-_xlfn.MAXIFS('Reuniões 1a1'!$A:$A,'Reuniões 1a1'!$B:$B,$B11))) | U11: =IF($B11="","",COUNTIFS(Avaliação!$B:$B,$A11,Avaliação!$A:$A,Config!$B$4,Avaliação!$K:$K,">=2")) | V11: =IF($B11="","",COUNTIFS(Avaliação!$B:$B,$A11,Avaliação!$A:$A,Config!$B$4,Avaliação!$O:$O,"SEM LASTRO")) | W11: =IF($B11="","",COUNTIFS(Ocorrências!$B:$B,$B11,Ocorrências!$N:$N,Config!$B$4,Ocorrências!$K:$K,"Não",Ocorrências!$E:$E,"Ponto de atenção")+COUNTIFS(Ocorrências!$B:$B,$B11,Ocorrências!$N:$N,Config!$B$4,Ocorrências!$K:$K,"Não",Ocorrências!$E:$E,"Incidente")) | X11: =IF($L11="","",_xlfn.MAXIFS(Avaliação!$M:$M,Avaliação!$B:$B,$A11,Avaliação!$A:$A,Config!$B$4)-_xlfn.MINIFS(Avaliação!$M:$M,Avaliação!$B:$B,$A11,Avaliação!$A:$A,Config!$B$4)) | Y11: =IF($B11="","",IF(OR($V11>0,$W11>0),"BLOQUEIO",IF($L11="","Sem avaliação",IF($N11<-0.3,"Abaixo da expectativa",IF($U11>0,"Calibrar",IF($X11=0,"Nota chapada",IF(IF($T11="",0,$T11)>30,"1:1 atrasada",IF(IF($S11="",99,$S11)>45,"Sem registro","OK")))))))) | AA11: =IFERROR(INDEX(Config!$B$17:$E$20,MATCH(Config!$A$17,Config!$A$17:$A$20,0),MATCH($D11,Config!$B$16:$E$16,0)),0) | AB11: =IFERROR(INDEX(Config!$B$17:$E$20,MATCH(Config!$A$18,Config!$A$17:$A$20,0),MATCH($D11,Config!$B$16:$E$16,0)),0) | AC11: =IFERROR(INDEX(Config!$B$17:$E$20,MATCH(Config!$A$19,Config!$A$17:$A$20,0),MATCH($D11,Config!$B$16:$E$16,0)),0) | AD11: =IFERROR(INDEX(Config!$B$17:$E$20,MATCH(Config!$A$20,Config!$A$17:$A$20,0),MATCH($D11,Config!$B$16:$E$16,0)),0) | AE11: =IFERROR($H11*$AA11,0)+IFERROR($I11*$AB11,0)+IFERROR($J11*$AC11,0)+IFERROR($K11*$AD11,0) | AF11: =IF(ISNUMBER($H11),$AA11,0)+IF(ISNUMBER($I11),$AB11,0)+IF(ISNUMBER($J11),$AC11,0)+IF(ISNUMBER($K11),$AD11,0)
A12: =IF(Colaboradores!$B12="","",Colaboradores!$A12) | B12: =IF(Colaboradores!$B12="","",Colaboradores!$B12) | C12: =IF(Colaboradores!$B12="","",Colaboradores!$F12) | D12: =IF(Colaboradores!$B12="","",Colaboradores!$D12) | E12: =IF(Colaboradores!$B12="","",Colaboradores!$E12) | F12: =IF(Colaboradores!$B12="","",Colaboradores!$O12) | G12: =IF(Colaboradores!$B12="","",Colaboradores!$P12) | H12: =IF($B12="","",IFERROR(AVERAGEIFS(Avaliação!$M:$M,Avaliação!$B:$B,$A12,Avaliação!$A:$A,Config!$B$4,Avaliação!$G:$G,Config!$A$17),"")) | I12: =IF($B12="","",IFERROR(AVERAGEIFS(Avaliação!$M:$M,Avaliação!$B:$B,$A12,Avaliação!$A:$A,Config!$B$4,Avaliação!$G:$G,Config!$A$18),"")) | J12: =IF($B12="","",IFERROR(AVERAGEIFS(Avaliação!$M:$M,Avaliação!$B:$B,$A12,Avaliação!$A:$A,Config!$B$4,Avaliação!$G:$G,Config!$A$19),"")) | K12: =IF($B12="","",IFERROR(AVERAGEIFS(Avaliação!$M:$M,Avaliação!$B:$B,$A12,Avaliação!$A:$A,Config!$B$4,Avaliação!$G:$G,Config!$A$20),"")) | L12: =IF($AF12=0,"",$AE12/$AF12) | M12: =IFERROR(INDEX(Config!$B$25:$B$28,MATCH($E12,Config!$A$25:$A$28,0)),"") | N12: =IF(OR($L12="",$M12=""),"",$L12-$M12) | O12: =IF($L12="","",IF($L12<2.5,"Abaixo",IF($L12<3.5,"Atende",IF($L12<=4.2,"Supera","Referência")))) | P12: =IF($B12="","",COUNTIFS(Ocorrências!$B:$B,$B12,Ocorrências!$N:$N,Config!$B$4)) | Q12: =IF($B12="","",COUNTIFS(Ocorrências!$B:$B,$B12,Ocorrências!$N:$N,Config!$B$4,Ocorrências!$E:$E,"Reconhecimento")+COUNTIFS(Ocorrências!$B:$B,$B12,Ocorrências!$N:$N,Config!$B$4,Ocorrências!$E:$E,"Positiva")) | R12: =IF($B12="","",COUNTIFS(Ocorrências!$B:$B,$B12,Ocorrências!$N:$N,Config!$B$4,Ocorrências!$E:$E,"Ponto de atenção")+COUNTIFS(Ocorrências!$B:$B,$B12,Ocorrências!$N:$N,Config!$B$4,Ocorrências!$E:$E,"Incidente")) | S12: =IF($B12="","",IF(COUNTIF(Ocorrências!$B:$B,$B12)=0,"",TODAY()-_xlfn.MAXIFS(Ocorrências!$A:$A,Ocorrências!$B:$B,$B12))) | T12: =IF($B12="","",IF(COUNTIF('Reuniões 1a1'!$B:$B,$B12)=0,"",TODAY()-_xlfn.MAXIFS('Reuniões 1a1'!$A:$A,'Reuniões 1a1'!$B:$B,$B12))) | U12: =IF($B12="","",COUNTIFS(Avaliação!$B:$B,$A12,Avaliação!$A:$A,Config!$B$4,Avaliação!$K:$K,">=2")) | V12: =IF($B12="","",COUNTIFS(Avaliação!$B:$B,$A12,Avaliação!$A:$A,Config!$B$4,Avaliação!$O:$O,"SEM LASTRO")) | W12: =IF($B12="","",COUNTIFS(Ocorrências!$B:$B,$B12,Ocorrências!$N:$N,Config!$B$4,Ocorrências!$K:$K,"Não",Ocorrências!$E:$E,"Ponto de atenção")+COUNTIFS(Ocorrências!$B:$B,$B12,Ocorrências!$N:$N,Config!$B$4,Ocorrências!$K:$K,"Não",Ocorrências!$E:$E,"Incidente")) | X12: =IF($L12="","",_xlfn.MAXIFS(Avaliação!$M:$M,Avaliação!$B:$B,$A12,Avaliação!$A:$A,Config!$B$4)-_xlfn.MINIFS(Avaliação!$M:$M,Avaliação!$B:$B,$A12,Avaliação!$A:$A,Config!$B$4)) | Y12: =IF($B12="","",IF(OR($V12>0,$W12>0),"BLOQUEIO",IF($L12="","Sem avaliação",IF($N12<-0.3,"Abaixo da expectativa",IF($U12>0,"Calibrar",IF($X12=0,"Nota chapada",IF(IF($T12="",0,$T12)>30,"1:1 atrasada",IF(IF($S12="",99,$S12)>45,"Sem registro","OK")))))))) | AA12: =IFERROR(INDEX(Config!$B$17:$E$20,MATCH(Config!$A$17,Config!$A$17:$A$20,0),MATCH($D12,Config!$B$16:$E$16,0)),0) | AB12: =IFERROR(INDEX(Config!$B$17:$E$20,MATCH(Config!$A$18,Config!$A$17:$A$20,0),MATCH($D12,Config!$B$16:$E$16,0)),0) | AC12: =IFERROR(INDEX(Config!$B$17:$E$20,MATCH(Config!$A$19,Config!$A$17:$A$20,0),MATCH($D12,Config!$B$16:$E$16,0)),0) | AD12: =IFERROR(INDEX(Config!$B$17:$E$20,MATCH(Config!$A$20,Config!$A$17:$A$20,0),MATCH($D12,Config!$B$16:$E$16,0)),0) | AE12: =IFERROR($H12*$AA12,0)+IFERROR($I12*$AB12,0)+IFERROR($J12*$AC12,0)+IFERROR($K12*$AD12,0) | AF12: =IF(ISNUMBER($H12),$AA12,0)+IF(ISNUMBER($I12),$AB12,0)+IF(ISNUMBER($J12),$AC12,0)+IF(ISNUMBER($K12),$AD12,0)
A13: =IF(Colaboradores!$B13="","",Colaboradores!$A13) | B13: =IF(Colaboradores!$B13="","",Colaboradores!$B13) | C13: =IF(Colaboradores!$B13="","",Colaboradores!$F13) | D13: =IF(Colaboradores!$B13="","",Colaboradores!$D13) | E13: =IF(Colaboradores!$B13="","",Colaboradores!$E13) | F13: =IF(Colaboradores!$B13="","",Colaboradores!$O13) | G13: =IF(Colaboradores!$B13="","",Colaboradores!$P13) | H13: =IF($B13="","",IFERROR(AVERAGEIFS(Avaliação!$M:$M,Avaliação!$B:$B,$A13,Avaliação!$A:$A,Config!$B$4,Avaliação!$G:$G,Config!$A$17),"")) | I13: =IF($B13="","",IFERROR(AVERAGEIFS(Avaliação!$M:$M,Avaliação!$B:$B,$A13,Avaliação!$A:$A,Config!$B$4,Avaliação!$G:$G,Config!$A$18),"")) | J13: =IF($B13="","",IFERROR(AVERAGEIFS(Avaliação!$M:$M,Avaliação!$B:$B,$A13,Avaliação!$A:$A,Config!$B$4,Avaliação!$G:$G,Config!$A$19),"")) | K13: =IF($B13="","",IFERROR(AVERAGEIFS(Avaliação!$M:$M,Avaliação!$B:$B,$A13,Avaliação!$A:$A,Config!$B$4,Avaliação!$G:$G,Config!$A$20),"")) | L13: =IF($AF13=0,"",$AE13/$AF13) | M13: =IFERROR(INDEX(Config!$B$25:$B$28,MATCH($E13,Config!$A$25:$A$28,0)),"") | N13: =IF(OR($L13="",$M13=""),"",$L13-$M13) | O13: =IF($L13="","",IF($L13<2.5,"Abaixo",IF($L13<3.5,"Atende",IF($L13<=4.2,"Supera","Referência")))) | P13: =IF($B13="","",COUNTIFS(Ocorrências!$B:$B,$B13,Ocorrências!$N:$N,Config!$B$4)) | Q13: =IF($B13="","",COUNTIFS(Ocorrências!$B:$B,$B13,Ocorrências!$N:$N,Config!$B$4,Ocorrências!$E:$E,"Reconhecimento")+COUNTIFS(Ocorrências!$B:$B,$B13,Ocorrências!$N:$N,Config!$B$4,Ocorrências!$E:$E,"Positiva")) | R13: =IF($B13="","",COUNTIFS(Ocorrências!$B:$B,$B13,Ocorrências!$N:$N,Config!$B$4,Ocorrências!$E:$E,"Ponto de atenção")+COUNTIFS(Ocorrências!$B:$B,$B13,Ocorrências!$N:$N,Config!$B$4,Ocorrências!$E:$E,"Incidente")) | S13: =IF($B13="","",IF(COUNTIF(Ocorrências!$B:$B,$B13)=0,"",TODAY()-_xlfn.MAXIFS(Ocorrências!$A:$A,Ocorrências!$B:$B,$B13))) | T13: =IF($B13="","",IF(COUNTIF('Reuniões 1a1'!$B:$B,$B13)=0,"",TODAY()-_xlfn.MAXIFS('Reuniões 1a1'!$A:$A,'Reuniões 1a1'!$B:$B,$B13))) | U13: =IF($B13="","",COUNTIFS(Avaliação!$B:$B,$A13,Avaliação!$A:$A,Config!$B$4,Avaliação!$K:$K,">=2")) | V13: =IF($B13="","",COUNTIFS(Avaliação!$B:$B,$A13,Avaliação!$A:$A,Config!$B$4,Avaliação!$O:$O,"SEM LASTRO")) | W13: =IF($B13="","",COUNTIFS(Ocorrências!$B:$B,$B13,Ocorrências!$N:$N,Config!$B$4,Ocorrências!$K:$K,"Não",Ocorrências!$E:$E,"Ponto de atenção")+COUNTIFS(Ocorrências!$B:$B,$B13,Ocorrências!$N:$N,Config!$B$4,Ocorrências!$K:$K,"Não",Ocorrências!$E:$E,"Incidente")) | X13: =IF($L13="","",_xlfn.MAXIFS(Avaliação!$M:$M,Avaliação!$B:$B,$A13,Avaliação!$A:$A,Config!$B$4)-_xlfn.MINIFS(Avaliação!$M:$M,Avaliação!$B:$B,$A13,Avaliação!$A:$A,Config!$B$4)) | Y13: =IF($B13="","",IF(OR($V13>0,$W13>0),"BLOQUEIO",IF($L13="","Sem avaliação",IF($N13<-0.3,"Abaixo da expectativa",IF($U13>0,"Calibrar",IF($X13=0,"Nota chapada",IF(IF($T13="",0,$T13)>30,"1:1 atrasada",IF(IF($S13="",99,$S13)>45,"Sem registro","OK")))))))) | AA13: =IFERROR(INDEX(Config!$B$17:$E$20,MATCH(Config!$A$17,Config!$A$17:$A$20,0),MATCH($D13,Config!$B$16:$E$16,0)),0) | AB13: =IFERROR(INDEX(Config!$B$17:$E$20,MATCH(Config!$A$18,Config!$A$17:$A$20,0),MATCH($D13,Config!$B$16:$E$16,0)),0) | AC13: =IFERROR(INDEX(Config!$B$17:$E$20,MATCH(Config!$A$19,Config!$A$17:$A$20,0),MATCH($D13,Config!$B$16:$E$16,0)),0) | AD13: =IFERROR(INDEX(Config!$B$17:$E$20,MATCH(Config!$A$20,Config!$A$17:$A$20,0),MATCH($D13,Config!$B$16:$E$16,0)),0) | AE13: =IFERROR($H13*$AA13,0)+IFERROR($I13*$AB13,0)+IFERROR($J13*$AC13,0)+IFERROR($K13*$AD13,0) | AF13: =IF(ISNUMBER($H13),$AA13,0)+IF(ISNUMBER($I13),$AB13,0)+IF(ISNUMBER($J13),$AC13,0)+IF(ISNUMBER($K13),$AD13,0)
A14: =IF(Colaboradores!$B14="","",Colaboradores!$A14) | B14: =IF(Colaboradores!$B14="","",Colaboradores!$B14) | C14: =IF(Colaboradores!$B14="","",Colaboradores!$F14) | D14: =IF(Colaboradores!$B14="","",Colaboradores!$D14) | E14: =IF(Colaboradores!$B14="","",Colaboradores!$E14) | F14: =IF(Colaboradores!$B14="","",Colaboradores!$O14) | G14: =IF(Colaboradores!$B14="","",Colaboradores!$P14) | H14: =IF($B14="","",IFERROR(AVERAGEIFS(Avaliação!$M:$M,Avaliação!$B:$B,$A14,Avaliação!$A:$A,Config!$B$4,Avaliação!$G:$G,Config!$A$17),"")) | I14: =IF($B14="","",IFERROR(AVERAGEIFS(Avaliação!$M:$M,Avaliação!$B:$B,$A14,Avaliação!$A:$A,Config!$B$4,Avaliação!$G:$G,Config!$A$18),"")) | J14: =IF($B14="","",IFERROR(AVERAGEIFS(Avaliação!$M:$M,Avaliação!$B:$B,$A14,Avaliação!$A:$A,Config!$B$4,Avaliação!$G:$G,Config!$A$19),"")) | K14: =IF($B14="","",IFERROR(AVERAGEIFS(Avaliação!$M:$M,Avaliação!$B:$B,$A14,Avaliação!$A:$A,Config!$B$4,Avaliação!$G:$G,Config!$A$20),"")) | L14: =IF($AF14=0,"",$AE14/$AF14) | M14: =IFERROR(INDEX(Config!$B$25:$B$28,MATCH($E14,Config!$A$25:$A$28,0)),"") | N14: =IF(OR($L14="",$M14=""),"",$L14-$M14) | O14: =IF($L14="","",IF($L14<2.5,"Abaixo",IF($L14<3.5,"Atende",IF($L14<=4.2,"Supera","Referência")))) | P14: =IF($B14="","",COUNTIFS(Ocorrências!$B:$B,$B14,Ocorrências!$N:$N,Config!$B$4)) | Q14: =IF($B14="","",COUNTIFS(Ocorrências!$B:$B,$B14,Ocorrências!$N:$N,Config!$B$4,Ocorrências!$E:$E,"Reconhecimento")+COUNTIFS(Ocorrências!$B:$B,$B14,Ocorrências!$N:$N,Config!$B$4,Ocorrências!$E:$E,"Positiva")) | R14: =IF($B14="","",COUNTIFS(Ocorrências!$B:$B,$B14,Ocorrências!$N:$N,Config!$B$4,Ocorrências!$E:$E,"Ponto de atenção")+COUNTIFS(Ocorrências!$B:$B,$B14,Ocorrências!$N:$N,Config!$B$4,Ocorrências!$E:$E,"Incidente")) | S14: =IF($B14="","",IF(COUNTIF(Ocorrências!$B:$B,$B14)=0,"",TODAY()-_xlfn.MAXIFS(Ocorrências!$A:$A,Ocorrências!$B:$B,$B14))) | T14: =IF($B14="","",IF(COUNTIF('Reuniões 1a1'!$B:$B,$B14)=0,"",TODAY()-_xlfn.MAXIFS('Reuniões 1a1'!$A:$A,'Reuniões 1a1'!$B:$B,$B14))) | U14: =IF($B14="","",COUNTIFS(Avaliação!$B:$B,$A14,Avaliação!$A:$A,Config!$B$4,Avaliação!$K:$K,">=2")) | V14: =IF($B14="","",COUNTIFS(Avaliação!$B:$B,$A14,Avaliação!$A:$A,Config!$B$4,Avaliação!$O:$O,"SEM LASTRO")) | W14: =IF($B14="","",COUNTIFS(Ocorrências!$B:$B,$B14,Ocorrências!$N:$N,Config!$B$4,Ocorrências!$K:$K,"Não",Ocorrências!$E:$E,"Ponto de atenção")+COUNTIFS(Ocorrências!$B:$B,$B14,Ocorrências!$N:$N,Config!$B$4,Ocorrências!$K:$K,"Não",Ocorrências!$E:$E,"Incidente")) | X14: =IF($L14="","",_xlfn.MAXIFS(Avaliação!$M:$M,Avaliação!$B:$B,$A14,Avaliação!$A:$A,Config!$B$4)-_xlfn.MINIFS(Avaliação!$M:$M,Avaliação!$B:$B,$A14,Avaliação!$A:$A,Config!$B$4)) | Y14: =IF($B14="","",IF(OR($V14>0,$W14>0),"BLOQUEIO",IF($L14="","Sem avaliação",IF($N14<-0.3,"Abaixo da expectativa",IF($U14>0,"Calibrar",IF($X14=0,"Nota chapada",IF(IF($T14="",0,$T14)>30,"1:1 atrasada",IF(IF($S14="",99,$S14)>45,"Sem registro","OK")))))))) | AA14: =IFERROR(INDEX(Config!$B$17:$E$20,MATCH(Config!$A$17,Config!$A$17:$A$20,0),MATCH($D14,Config!$B$16:$E$16,0)),0) | AB14: =IFERROR(INDEX(Config!$B$17:$E$20,MATCH(Config!$A$18,Config!$A$17:$A$20,0),MATCH($D14,Config!$B$16:$E$16,0)),0) | AC14: =IFERROR(INDEX(Config!$B$17:$E$20,MATCH(Config!$A$19,Config!$A$17:$A$20,0),MATCH($D14,Config!$B$16:$E$16,0)),0) | AD14: =IFERROR(INDEX(Config!$B$17:$E$20,MATCH(Config!$A$20,Config!$A$17:$A$20,0),MATCH($D14,Config!$B$16:$E$16,0)),0) | AE14: =IFERROR($H14*$AA14,0)+IFERROR($I14*$AB14,0)+IFERROR($J14*$AC14,0)+IFERROR($K14*$AD14,0) | AF14: =IF(ISNUMBER($H14),$AA14,0)+IF(ISNUMBER($I14),$AB14,0)+IF(ISNUMBER($J14),$AC14,0)+IF(ISNUMBER($K14),$AD14,0)
A15: =IF(Colaboradores!$B15="","",Colaboradores!$A15) | B15: =IF(Colaboradores!$B15="","",Colaboradores!$B15) | C15: =IF(Colaboradores!$B15="","",Colaboradores!$F15) | D15: =IF(Colaboradores!$B15="","",Colaboradores!$D15) | E15: =IF(Colaboradores!$B15="","",Colaboradores!$E15) | F15: =IF(Colaboradores!$B15="","",Colaboradores!$O15) | G15: =IF(Colaboradores!$B15="","",Colaboradores!$P15) | H15: =IF($B15="","",IFERROR(AVERAGEIFS(Avaliação!$M:$M,Avaliação!$B:$B,$A15,Avaliação!$A:$A,Config!$B$4,Avaliação!$G:$G,Config!$A$17),"")) | I15: =IF($B15="","",IFERROR(AVERAGEIFS(Avaliação!$M:$M,Avaliação!$B:$B,$A15,Avaliação!$A:$A,Config!$B$4,Avaliação!$G:$G,Config!$A$18),"")) | J15: =IF($B15="","",IFERROR(AVERAGEIFS(Avaliação!$M:$M,Avaliação!$B:$B,$A15,Avaliação!$A:$A,Config!$B$4,Avaliação!$G:$G,Config!$A$19),"")) | K15: =IF($B15="","",IFERROR(AVERAGEIFS(Avaliação!$M:$M,Avaliação!$B:$B,$A15,Avaliação!$A:$A,Config!$B$4,Avaliação!$G:$G,Config!$A$20),"")) | L15: =IF($AF15=0,"",$AE15/$AF15) | M15: =IFERROR(INDEX(Config!$B$25:$B$28,MATCH($E15,Config!$A$25:$A$28,0)),"") | N15: =IF(OR($L15="",$M15=""),"",$L15-$M15) | O15: =IF($L15="","",IF($L15<2.5,"Abaixo",IF($L15<3.5,"Atende",IF($L15<=4.2,"Supera","Referência")))) | P15: =IF($B15="","",COUNTIFS(Ocorrências!$B:$B,$B15,Ocorrências!$N:$N,Config!$B$4)) | Q15: =IF($B15="","",COUNTIFS(Ocorrências!$B:$B,$B15,Ocorrências!$N:$N,Config!$B$4,Ocorrências!$E:$E,"Reconhecimento")+COUNTIFS(Ocorrências!$B:$B,$B15,Ocorrências!$N:$N,Config!$B$4,Ocorrências!$E:$E,"Positiva")) | R15: =IF($B15="","",COUNTIFS(Ocorrências!$B:$B,$B15,Ocorrências!$N:$N,Config!$B$4,Ocorrências!$E:$E,"Ponto de atenção")+COUNTIFS(Ocorrências!$B:$B,$B15,Ocorrências!$N:$N,Config!$B$4,Ocorrências!$E:$E,"Incidente")) | S15: =IF($B15="","",IF(COUNTIF(Ocorrências!$B:$B,$B15)=0,"",TODAY()-_xlfn.MAXIFS(Ocorrências!$A:$A,Ocorrências!$B:$B,$B15))) | T15: =IF($B15="","",IF(COUNTIF('Reuniões 1a1'!$B:$B,$B15)=0,"",TODAY()-_xlfn.MAXIFS('Reuniões 1a1'!$A:$A,'Reuniões 1a1'!$B:$B,$B15))) | U15: =IF($B15="","",COUNTIFS(Avaliação!$B:$B,$A15,Avaliação!$A:$A,Config!$B$4,Avaliação!$K:$K,">=2")) | V15: =IF($B15="","",COUNTIFS(Avaliação!$B:$B,$A15,Avaliação!$A:$A,Config!$B$4,Avaliação!$O:$O,"SEM LASTRO")) | W15: =IF($B15="","",COUNTIFS(Ocorrências!$B:$B,$B15,Ocorrências!$N:$N,Config!$B$4,Ocorrências!$K:$K,"Não",Ocorrências!$E:$E,"Ponto de atenção")+COUNTIFS(Ocorrências!$B:$B,$B15,Ocorrências!$N:$N,Config!$B$4,Ocorrências!$K:$K,"Não",Ocorrências!$E:$E,"Incidente")) | X15: =IF($L15="","",_xlfn.MAXIFS(Avaliação!$M:$M,Avaliação!$B:$B,$A15,Avaliação!$A:$A,Config!$B$4)-_xlfn.MINIFS(Avaliação!$M:$M,Avaliação!$B:$B,$A15,Avaliação!$A:$A,Config!$B$4)) | Y15: =IF($B15="","",IF(OR($V15>0,$W15>0),"BLOQUEIO",IF($L15="","Sem avaliação",IF($N15<-0.3,"Abaixo da expectativa",IF($U15>0,"Calibrar",IF($X15=0,"Nota chapada",IF(IF($T15="",0,$T15)>30,"1:1 atrasada",IF(IF($S15="",99,$S15)>45,"Sem registro","OK")))))))) | AA15: =IFERROR(INDEX(Config!$B$17:$E$20,MATCH(Config!$A$17,Config!$A$17:$A$20,0),MATCH($D15,Config!$B$16:$E$16,0)),0) | AB15: =IFERROR(INDEX(Config!$B$17:$E$20,MATCH(Config!$A$18,Config!$A$17:$A$20,0),MATCH($D15,Config!$B$16:$E$16,0)),0) | AC15: =IFERROR(INDEX(Config!$B$17:$E$20,MATCH(Config!$A$19,Config!$A$17:$A$20,0),MATCH($D15,Config!$B$16:$E$16,0)),0) | AD15: =IFERROR(INDEX(Config!$B$17:$E$20,MATCH(Config!$A$20,Config!$A$17:$A$20,0),MATCH($D15,Config!$B$16:$E$16,0)),0) | AE15: =IFERROR($H15*$AA15,0)+IFERROR($I15*$AB15,0)+IFERROR($J15*$AC15,0)+IFERROR($K15*$AD15,0) | AF15: =IF(ISNUMBER($H15),$AA15,0)+IF(ISNUMBER($I15),$AB15,0)+IF(ISNUMBER($J15),$AC15,0)+IF(ISNUMBER($K15),$AD15,0)
A16: =IF(Colaboradores!$B16="","",Colaboradores!$A16) | B16: =IF(Colaboradores!$B16="","",Colaboradores!$B16) | C16: =IF(Colaboradores!$B16="","",Colaboradores!$F16) | D16: =IF(Colaboradores!$B16="","",Colaboradores!$D16) | E16: =IF(Colaboradores!$B16="","",Colaboradores!$E16) | F16: =IF(Colaboradores!$B16="","",Colaboradores!$O16) | G16: =IF(Colaboradores!$B16="","",Colaboradores!$P16) | H16: =IF($B16="","",IFERROR(AVERAGEIFS(Avaliação!$M:$M,Avaliação!$B:$B,$A16,Avaliação!$A:$A,Config!$B$4,Avaliação!$G:$G,Config!$A$17),"")) | I16: =IF($B16="","",IFERROR(AVERAGEIFS(Avaliação!$M:$M,Avaliação!$B:$B,$A16,Avaliação!$A:$A,Config!$B$4,Avaliação!$G:$G,Config!$A$18),"")) | J16: =IF($B16="","",IFERROR(AVERAGEIFS(Avaliação!$M:$M,Avaliação!$B:$B,$A16,Avaliação!$A:$A,Config!$B$4,Avaliação!$G:$G,Config!$A$19),"")) | K16: =IF($B16="","",IFERROR(AVERAGEIFS(Avaliação!$M:$M,Avaliação!$B:$B,$A16,Avaliação!$A:$A,Config!$B$4,Avaliação!$G:$G,Config!$A$20),"")) | L16: =IF($AF16=0,"",$AE16/$AF16) | M16: =IFERROR(INDEX(Config!$B$25:$B$28,MATCH($E16,Config!$A$25:$A$28,0)),"") | N16: =IF(OR($L16="",$M16=""),"",$L16-$M16) | O16: =IF($L16="","",IF($L16<2.5,"Abaixo",IF($L16<3.5,"Atende",IF($L16<=4.2,"Supera","Referência")))) | P16: =IF($B16="","",COUNTIFS(Ocorrências!$B:$B,$B16,Ocorrências!$N:$N,Config!$B$4)) | Q16: =IF($B16="","",COUNTIFS(Ocorrências!$B:$B,$B16,Ocorrências!$N:$N,Config!$B$4,Ocorrências!$E:$E,"Reconhecimento")+COUNTIFS(Ocorrências!$B:$B,$B16,Ocorrências!$N:$N,Config!$B$4,Ocorrências!$E:$E,"Positiva")) | R16: =IF($B16="","",COUNTIFS(Ocorrências!$B:$B,$B16,Ocorrências!$N:$N,Config!$B$4,Ocorrências!$E:$E,"Ponto de atenção")+COUNTIFS(Ocorrências!$B:$B,$B16,Ocorrências!$N:$N,Config!$B$4,Ocorrências!$E:$E,"Incidente")) | S16: =IF($B16="","",IF(COUNTIF(Ocorrências!$B:$B,$B16)=0,"",TODAY()-_xlfn.MAXIFS(Ocorrências!$A:$A,Ocorrências!$B:$B,$B16))) | T16: =IF($B16="","",IF(COUNTIF('Reuniões 1a1'!$B:$B,$B16)=0,"",TODAY()-_xlfn.MAXIFS('Reuniões 1a1'!$A:$A,'Reuniões 1a1'!$B:$B,$B16))) | U16: =IF($B16="","",COUNTIFS(Avaliação!$B:$B,$A16,Avaliação!$A:$A,Config!$B$4,Avaliação!$K:$K,">=2")) | V16: =IF($B16="","",COUNTIFS(Avaliação!$B:$B,$A16,Avaliação!$A:$A,Config!$B$4,Avaliação!$O:$O,"SEM LASTRO")) | W16: =IF($B16="","",COUNTIFS(Ocorrências!$B:$B,$B16,Ocorrências!$N:$N,Config!$B$4,Ocorrências!$K:$K,"Não",Ocorrências!$E:$E,"Ponto de atenção")+COUNTIFS(Ocorrências!$B:$B,$B16,Ocorrências!$N:$N,Config!$B$4,Ocorrências!$K:$K,"Não",Ocorrências!$E:$E,"Incidente")) | X16: =IF($L16="","",_xlfn.MAXIFS(Avaliação!$M:$M,Avaliação!$B:$B,$A16,Avaliação!$A:$A,Config!$B$4)-_xlfn.MINIFS(Avaliação!$M:$M,Avaliação!$B:$B,$A16,Avaliação!$A:$A,Config!$B$4)) | Y16: =IF($B16="","",IF(OR($V16>0,$W16>0),"BLOQUEIO",IF($L16="","Sem avaliação",IF($N16<-0.3,"Abaixo da expectativa",IF($U16>0,"Calibrar",IF($X16=0,"Nota chapada",IF(IF($T16="",0,$T16)>30,"1:1 atrasada",IF(IF($S16="",99,$S16)>45,"Sem registro","OK")))))))) | AA16: =IFERROR(INDEX(Config!$B$17:$E$20,MATCH(Config!$A$17,Config!$A$17:$A$20,0),MATCH($D16,Config!$B$16:$E$16,0)),0) | AB16: =IFERROR(INDEX(Config!$B$17:$E$20,MATCH(Config!$A$18,Config!$A$17:$A$20,0),MATCH($D16,Config!$B$16:$E$16,0)),0) | AC16: =IFERROR(INDEX(Config!$B$17:$E$20,MATCH(Config!$A$19,Config!$A$17:$A$20,0),MATCH($D16,Config!$B$16:$E$16,0)),0) | AD16: =IFERROR(INDEX(Config!$B$17:$E$20,MATCH(Config!$A$20,Config!$A$17:$A$20,0),MATCH($D16,Config!$B$16:$E$16,0)),0) | AE16: =IFERROR($H16*$AA16,0)+IFERROR($I16*$AB16,0)+IFERROR($J16*$AC16,0)+IFERROR($K16*$AD16,0) | AF16: =IF(ISNUMBER($H16),$AA16,0)+IF(ISNUMBER($I16),$AB16,0)+IF(ISNUMBER($J16),$AC16,0)+IF(ISNUMBER($K16),$AD16,0)
... A64: =IF(Colaboradores!$B64="","",Colaboradores!$A64) | B64: =IF(Colaboradores!$B64="","",Colaboradores!$B64) | C64: =IF(Colaboradores!$B64="","",Colaboradores!$F64) | D64: =IF(Colaboradores!$B64="","",Colaboradores!$D64) | E64: =IF(Colaboradores!$B64="","",Colaboradores!$E64) | F64: =IF(Colaboradores!$B64="","",Colaboradores!$O64) | G64: =IF(Colaboradores!$B64="","",Colaboradores!$P64) | H64: =IF($B64="","",IFERROR(AVERAGEIFS(Avaliação!$M:$M,Avaliação!$B:$B,$A64,Avaliação!$A:$A,Config!$B$4,Avaliação!$G:$G,Config!$A$17),"")) | I64: =IF($B64="","",IFERROR(AVERAGEIFS(Avaliação!$M:$M,Avaliação!$B:$B,$A64,Avaliação!$A:$A,Config!$B$4,Avaliação!$G:$G,Config!$A$18),"")) | J64: =IF($B64="","",IFERROR(AVERAGEIFS(Avaliação!$M:$M,Avaliação!$B:$B,$A64,Avaliação!$A:$A,Config!$B$4,Avaliação!$G:$G,Config!$A$19),"")) | K64: =IF($B64="","",IFERROR(AVERAGEIFS(Avaliação!$M:$M,Avaliação!$B:$B,$A64,Avaliação!$A:$A,Config!$B$4,Avaliação!$G:$G,Config!$A$20),"")) | L64: =IF($AF64=0,"",$AE64/$AF64) | M64: =IFERROR(INDEX(Config!$B$25:$B$28,MATCH($E64,Config!$A$25:$A$28,0)),"") | N64: =IF(OR($L64="",$M64=""),"",$L64-$M64) | O64: =IF($L64="","",IF($L64<2.5,"Abaixo",IF($L64<3.5,"Atende",IF($L64<=4.2,"Supera","Referência")))) | P64: =IF($B64="","",COUNTIFS(Ocorrências!$B:$B,$B64,Ocorrências!$N:$N,Config!$B$4)) | Q64: =IF($B64="","",COUNTIFS(Ocorrências!$B:$B,$B64,Ocorrências!$N:$N,Config!$B$4,Ocorrências!$E:$E,"Reconhecimento")+COUNTIFS(Ocorrências!$B:$B,$B64,Ocorrências!$N:$N,Config!$B$4,Ocorrências!$E:$E,"Positiva")) | R64: =IF($B64="","",COUNTIFS(Ocorrências!$B:$B,$B64,Ocorrências!$N:$N,Config!$B$4,Ocorrências!$E:$E,"Ponto de atenção")+COUNTIFS(Ocorrências!$B:$B,$B64,Ocorrências!$N:$N,Config!$B$4,Ocorrências!$E:$E,"Incidente")) | S64: =IF($B64="","",IF(COUNTIF(Ocorrências!$B:$B,$B64)=0,"",TODAY()-_xlfn.MAXIFS(Ocorrências!$A:$A,Ocorrências!$B:$B,$B64))) | T64: =IF($B64="","",IF(COUNTIF('Reuniões 1a1'!$B:$B,$B64)=0,"",TODAY()-_xlfn.MAXIFS('Reuniões 1a1'!$A:$A,'Reuniões 1a1'!$B:$B,$B64))) | U64: =IF($B64="","",COUNTIFS(Avaliação!$B:$B,$A64,Avaliação!$A:$A,Config!$B$4,Avaliação!$K:$K,">=2")) | V64: =IF($B64="","",COUNTIFS(Avaliação!$B:$B,$A64,Avaliação!$A:$A,Config!$B$4,Avaliação!$O:$O,"SEM LASTRO")) | W64: =IF($B64="","",COUNTIFS(Ocorrências!$B:$B,$B64,Ocorrências!$N:$N,Config!$B$4,Ocorrências!$K:$K,"Não",Ocorrências!$E:$E,"Ponto de atenção")+COUNTIFS(Ocorrências!$B:$B,$B64,Ocorrências!$N:$N,Config!$B$4,Ocorrências!$K:$K,"Não",Ocorrências!$E:$E,"Incidente")) | X64: =IF($L64="","",_xlfn.MAXIFS(Avaliação!$M:$M,Avaliação!$B:$B,$A64,Avaliação!$A:$A,Config!$B$4)-_xlfn.MINIFS(Avaliação!$M:$M,Avaliação!$B:$B,$A64,Avaliação!$A:$A,Config!$B$4)) | Y64: =IF($B64="","",IF(OR($V64>0,$W64>0),"BLOQUEIO",IF($L64="","Sem avaliação",IF($N64<-0.3,"Abaixo da expectativa",IF($U64>0,"Calibrar",IF($X64=0,"Nota chapada",IF(IF($T64="",0,$T64)>30,"1:1 atrasada",IF(IF($S64="",99,$S64)>45,"Sem registro","OK")))))))) | AA64: =IFERROR(INDEX(Config!$B$17:$E$20,MATCH(Config!$A$17,Config!$A$17:$A$20,0),MATCH($D64,Config!$B$16:$E$16,0)),0) | AB64: =IFERROR(INDEX(Config!$B$17:$E$20,MATCH(Config!$A$18,Config!$A$17:$A$20,0),MATCH($D64,Config!$B$16:$E$16,0)),0) | AC64: =IFERROR(INDEX(Config!$B$17:$E$20,MATCH(Config!$A$19,Config!$A$17:$A$20,0),MATCH($D64,Config!$B$16:$E$16,0)),0) | AD64: =IFERROR(INDEX(Config!$B$17:$E$20,MATCH(Config!$A$20,Config!$A$17:$A$20,0),MATCH($D64,Config!$B$16:$E$16,0)),0) | AE64: =IFERROR($H64*$AA64,0)+IFERROR($I64*$AB64,0)+IFERROR($J64*$AC64,0)+IFERROR($K64*$AD64,0) | AF64: =IF(ISNUMBER($H64),$AA64,0)+IF(ISNUMBER($I64),$AB64,0)+IF(ISNUMBER($J64),$AC64,0)+IF(ISNUMBER($K64),$AD64,0)

Sheet Ocorrências
A1: Ocorrências — o registro contínuo
A2: Alvo: 60 segundos por lançamento. Registro mais recente no topo. Meta: pelo menos 1 registro positivo a cada 2 negativos.
A3: Regra de escrita: o FATO não aceita adjetivo. 'Subiu hotfix sem aprovação na sexta 18h' ✔ · 'É descuidado' ✘. O juízo vai em Consequência, e precisa ser defensável a partir do fato ao lado. Nada de saúde, vida pessoal ou motivo de ausência.
A4: Data do fato | B4: Colaborador | C4: Registrado por | D4: Papel do autor | E4: Tipo | F4: Competência | G4: Fato observável (sem adjetivo de personalidade) | H4: Impacto | I4: Consequência observada | J4: Ação tomada pelo gestor | K4: Informado ao colaborador? | L4: Link / evidência | M4: Confidencialidade | N4: Ciclo | O4: Registro válido? | P4: Seq. p/ pauta
A5: 46212 | B5: Ana Ribeiro | C5: Rafael Souza | D5: Líder Técnico | E5: Positiva | F5: Colaboração e review | G5: No PR #812 apontou uma condição de corrida no resgate de cupom antes do merge, com o trecho e a sugestão de UPDATE atômico. | H5: Alto | I5: Evitou um bug de duplicidade de resgate que teria ido para produção no contrato A. | J5: Reconhecido na retro do dia 10/07. | K5: Sim | L5: PR #812 | M5: Squad | N5: =IF($A5="","",YEAR($A5)&"-Q"&ROUNDUP(MONTH($A5)/3,0)) | O5: =IF($A5="","",IF(OR($B5="",$E5="",$F5="",$G5="",$I5="",$K5=""),"Faltam campos","OK")) | P5: =IF(OR($B5="",$B5<>'Pauta 1a1'!$B$4,$N5<>'Pauta 1a1'!$B$5),"",COUNTIFS($B$5:$B5,'Pauta 1a1'!$B$4,$N$5:$N5,'Pauta 1a1'!$B$5))
A6: 46225 | B6: Bruno Tavares | C6: Marcos Lima | D6: GP | E6: Ponto de atenção | F6: Previsibilidade | G6: Card CB-118 ficou 4 dias sem atualização e o bloqueio (falta de credencial de homologação) só foi comunicado na review. | H6: Médio | I6: A sprint fechou com o item em carry over e o PO replanejou a demo com o cliente em cima da hora. | J6: Feedback na 1:1 de 23/07; combinado avisar bloqueio na daily do mesmo dia. | K6: Sim | L6: CB-118 | M6: Squad | N6: =IF($A6="","",YEAR($A6)&"-Q"&ROUNDUP(MONTH($A6)/3,0)) | O6: =IF($A6="","",IF(OR($B6="",$E6="",$F6="",$G6="",$I6="",$K6=""),"Faltam campos","OK")) | P6: =IF(OR($B6="",$B6<>'Pauta 1a1'!$B$4,$N6<>'Pauta 1a1'!$B$5),"",COUNTIFS($B$5:$B6,'Pauta 1a1'!$B$4,$N$5:$N6,'Pauta 1a1'!$B$5))
A7: 46238 | B7: Bruno Tavares | C7: Marcos Lima | D7: GP | E7: Positiva | F7: Comunicação | G7: Na daily de 04/08 avisou no mesmo dia que a integração de pagamento estava fora do ar, com print do erro e a alternativa de mockar. | H7: Médio | I7: O time replanejou a sprint no mesmo dia, sem perda de entrega. | J7: Reconhecido na daily. | K7: Sim | M7: Squad | N7: =IF($A7="","",YEAR($A7)&"-Q"&ROUNDUP(MONTH($A7)/3,0)) | O7: =IF($A7="","",IF(OR($B7="",$E7="",$F7="",$G7="",$I7="",$K7=""),"Faltam campos","OK")) | P7: =IF(OR($B7="",$B7<>'Pauta 1a1'!$B$4,$N7<>'Pauta 1a1'!$B$5),"",COUNTIFS($B$5:$B7,'Pauta 1a1'!$B$4,$N$5:$N7,'Pauta 1a1'!$B$5))
A8: 46246 | B8: Carla Nunes | C8: Marcos Lima | D8: GP | E8: Contexto atenuante | F8: Previsibilidade | G8: Assumiu o on-call do Contrato B por duas semanas cobrindo férias, além dos 50% de alocação no Motor de Cobrança. | H8: Alto | I8: Reduziu em ~40% o tempo disponível para o roadmap no período. | J8: Registrado para a calibração; escopo da sprint 14 reduzido. | K8: Sim | M8: Squad | N8: =IF($A8="","",YEAR($A8)&"-Q"&ROUNDUP(MONTH($A8)/3,0)) | O8: =IF($A8="","",IF(OR($B8="",$E8="",$F8="",$G8="",$I8="",$K8=""),"Faltam campos","OK")) | P8: =IF(OR($B8="",$B8<>'Pauta 1a1'!$B$4,$N8<>'Pauta 1a1'!$B$5),"",COUNTIFS($B$5:$B8,'Pauta 1a1'!$B$4,$N$5:$N8,'Pauta 1a1'!$B$5))
A9: 46253 | B9: Ana Ribeiro | C9: Rafael Souza | D9: Líder Técnico | E9: Ponto de atenção | F9: Qualidade da entrega | G9: PR #857 voltou em 3 rodadas: nas duas primeiras faltava teste do caminho de erro na rota de resgate. | H9: Médio | I9: Atrasou o merge em 2 dias e consumiu 3 rodadas de review do time. | J9: Combinado no 1:1 de 20/08: incluir teste de erro antes de abrir o PR. | K9: Sim | L9: PR #857 | M9: Squad | N9: =IF($A9="","",YEAR($A9)&"-Q"&ROUNDUP(MONTH($A9)/3,0)) | O9: =IF($A9="","",IF(OR($B9="",$E9="",$F9="",$G9="",$I9="",$K9=""),"Faltam campos","OK")) | P9: =IF(OR($B9="",$B9<>'Pauta 1a1'!$B$4,$N9<>'Pauta 1a1'!$B$5),"",COUNTIFS($B$5:$B9,'Pauta 1a1'!$B$4,$N$5:$N9,'Pauta 1a1'!$B$5))
A10: 46259 | B10: Carla Nunes | C10: Rafael Souza | D10: Líder Técnico | E10: Reconhecimento | F10: Desenvolvimento de outros | G10: Escreveu a ADR-07 sobre o advisory lock no cooldown e conduziu a sessão de 40 min com as squads Alfa e Beta. | H10: Alto | I10: Duas squads passaram a usar o mesmo padrão; a discussão não voltou nos refinamentos seguintes. | J10: Levado ao comitê de calibração como evidência de atuação de Especialista. | K10: Sim | L10: ADR-07 | M10: Gestão | N10: =IF($A10="","",YEAR($A10)&"-Q"&ROUNDUP(MONTH($A10)/3,0)) | O10: =IF($A10="","",IF(OR($B10="",$E10="",$F10="",$G10="",$I10="",$K10=""),"Faltam campos","OK")) | P10: =IF(OR($B10="",$B10<>'Pauta 1a1'!$B$4,$N10<>'Pauta 1a1'!$B$5),"",COUNTIFS($B$5:$B10,'Pauta 1a1'!$B$4,$N$5:$N10,'Pauta 1a1'!$B$5))
N11: =IF($A11="","",YEAR($A11)&"-Q"&ROUNDUP(MONTH($A11)/3,0)) | O11: =IF($A11="","",IF(OR($B11="",$E11="",$F11="",$G11="",$I11="",$K11=""),"Faltam campos","OK")) | P11: =IF(OR($B11="",$B11<>'Pauta 1a1'!$B$4,$N11<>'Pauta 1a1'!$B$5),"",COUNTIFS($B$5:$B11,'Pauta 1a1'!$B$4,$N$5:$N11,'Pauta 1a1'!$B$5))
N12: =IF($A12="","",YEAR($A12)&"-Q"&ROUNDUP(MONTH($A12)/3,0)) | O12: =IF($A12="","",IF(OR($B12="",$E12="",$F12="",$G12="",$I12="",$K12=""),"Faltam campos","OK")) | P12: =IF(OR($B12="",$B12<>'Pauta 1a1'!$B$4,$N12<>'Pauta 1a1'!$B$5),"",COUNTIFS($B$5:$B12,'Pauta 1a1'!$B$4,$N$5:$N12,'Pauta 1a1'!$B$5))
N13: =IF($A13="","",YEAR($A13)&"-Q"&ROUNDUP(MONTH($A13)/3,0)) | O13: =IF($A13="","",IF(OR($B13="",$E13="",$F13="",$G13="",$I13="",$K13=""),"Faltam campos","OK")) | P13: =IF(OR($B13="",$B13<>'Pauta 1a1'!$B$4,$N13<>'Pauta 1a1'!$B$5),"",COUNTIFS($B$5:$B13,'Pauta 1a1'!$B$4,$N$5:$N13,'Pauta 1a1'!$B$5))
N14: =IF($A14="","",YEAR($A14)&"-Q"&ROUNDUP(MONTH($A14)/3,0)) | O14: =IF($A14="","",IF(OR($B14="",$E14="",$F14="",$G14="",$I14="",$K14=""),"Faltam campos","OK")) | P14: =IF(OR($B14="",$B14<>'Pauta 1a1'!$B$4,$N14<>'Pauta 1a1'!$B$5),"",COUNTIFS($B$5:$B14,'Pauta 1a1'!$B$4,$N$5:$N14,'Pauta 1a1'!$B$5))
N15: =IF($A15="","",YEAR($A15)&"-Q"&ROUNDUP(MONTH($A15)/3,0)) | O15: =IF($A15="","",IF(OR($B15="",$E15="",$F15="",$G15="",$I15="",$K15=""),"Faltam campos","OK")) | P15: =IF(OR($B15="",$B15<>'Pauta 1a1'!$B$4,$N15<>'Pauta 1a1'!$B$5),"",COUNTIFS($B$5:$B15,'Pauta 1a1'!$B$4,$N$5:$N15,'Pauta 1a1'!$B$5))
N16: =IF($A16="","",YEAR($A16)&"-Q"&ROUNDUP(MONTH($A16)/3,0)) | O16: =IF($A16="","",IF(OR($B16="",$E16="",$F16="",$G16="",$I16="",$K16=""),"Faltam campos","OK")) | P16: =IF(OR($B16="",$B16<>'Pauta 1a1'!$B$4,$N16<>'Pauta 1a1'!$B$5),"",COUNTIFS($B$5:$B16,'Pauta 1a1'!$B$4,$N$5:$N16,'Pauta 1a1'!$B$5))
N17: =IF($A17="","",YEAR($A17)&"-Q"&ROUNDUP(MONTH($A17)/3,0)) | O17: =IF($A17="","",IF(OR($B17="",$E17="",$F17="",$G17="",$I17="",$K17=""),"Faltam campos","OK")) | P17: =IF(OR($B17="",$B17<>'Pauta 1a1'!$B$4,$N17<>'Pauta 1a1'!$B$5),"",COUNTIFS($B$5:$B17,'Pauta 1a1'!$B$4,$N$5:$N17,'Pauta 1a1'!$B$5))
N18: =IF($A18="","",YEAR($A18)&"-Q"&ROUNDUP(MONTH($A18)/3,0)) | O18: =IF($A18="","",IF(OR($B18="",$E18="",$F18="",$G18="",$I18="",$K18=""),"Faltam campos","OK")) | P18: =IF(OR($B18="",$B18<>'Pauta 1a1'!$B$4,$N18<>'Pauta 1a1'!$B$5),"",COUNTIFS($B$5:$B18,'Pauta 1a1'!$B$4,$N$5:$N18,'Pauta 1a1'!$B$5))
N19: =IF($A19="","",YEAR($A19)&"-Q"&ROUNDUP(MONTH($A19)/3,0)) | O19: =IF($A19="","",IF(OR($B19="",$E19="",$F19="",$G19="",$I19="",$K19=""),"Faltam campos","OK")) | P19: =IF(OR($B19="",$B19<>'Pauta 1a1'!$B$4,$N19<>'Pauta 1a1'!$B$5),"",COUNTIFS($B$5:$B19,'Pauta 1a1'!$B$4,$N$5:$N19,'Pauta 1a1'!$B$5))
N20: =IF($A20="","",YEAR($A20)&"-Q"&ROUNDUP(MONTH($A20)/3,0)) | O20: =IF($A20="","",IF(OR($B20="",$E20="",$F20="",$G20="",$I20="",$K20=""),"Faltam campos","OK")) | P20: =IF(OR($B20="",$B20<>'Pauta 1a1'!$B$4,$N20<>'Pauta 1a1'!$B$5),"",COUNTIFS($B$5:$B20,'Pauta 1a1'!$B$4,$N$5:$N20,'Pauta 1a1'!$B$5))
N21: =IF($A21="","",YEAR($A21)&"-Q"&ROUNDUP(MONTH($A21)/3,0)) | O21: =IF($A21="","",IF(OR($B21="",$E21="",$F21="",$G21="",$I21="",$K21=""),"Faltam campos","OK")) | P21: =IF(OR($B21="",$B21<>'Pauta 1a1'!$B$4,$N21<>'Pauta 1a1'!$B$5),"",COUNTIFS($B$5:$B21,'Pauta 1a1'!$B$4,$N$5:$N21,'Pauta 1a1'!$B$5))
N22: =IF($A22="","",YEAR($A22)&"-Q"&ROUNDUP(MONTH($A22)/3,0)) | O22: =IF($A22="","",IF(OR($B22="",$E22="",$F22="",$G22="",$I22="",$K22=""),"Faltam campos","OK")) | P22: =IF(OR($B22="",$B22<>'Pauta 1a1'!$B$4,$N22<>'Pauta 1a1'!$B$5),"",COUNTIFS($B$5:$B22,'Pauta 1a1'!$B$4,$N$5:$N22,'Pauta 1a1'!$B$5))
... N404: =IF($A404="","",YEAR($A404)&"-Q"&ROUNDUP(MONTH($A404)/3,0)) | O404: =IF($A404="","",IF(OR($B404="",$E404="",$F404="",$G404="",$I404="",$K404=""),"Faltam campos","OK")) | P404: =IF(OR($B404="",$B404<>'Pauta 1a1'!$B$4,$N404<>'Pauta 1a1'!$B$5),"",COUNTIFS($B$5:$B404,'Pauta 1a1'!$B$4,$N$5:$N404,'Pauta 1a1'!$B$5))

Sheet Avaliação
