Workbook

Sheet Resumo
A1: Resumo por pessoa
A2: Tudo compilado. Escolha o período abaixo e a tabela inteira se ajusta.
A3: Período de | B3: 46235 | C3: até | D3: 46265 | E3: Deixe um período largo para ver o acumulado, ou aperte para uma semana só.
A5: Colaborador | B5: Squad | C5: Papel | D5: Média GP | E5: Média LT | F5: Entrega | G5: Qualidade | H5: Comunicação | I5: Colaboração | J5: Autonomia | K5: MÉDIA FINAL | L5: Farol | M5: Avaliações | N5: Última avaliação | O5: Ocorrências | P5: Atenção / Críticas | Q5: Último comentário do GP | R5: Último comentário do Líder Técnico
A6: =IF(Cadastro!$A5="","",Cadastro!$A5) | B6: =IF(Cadastro!$A5="","",Cadastro!$B5) | C6: =IF(Cadastro!$A5="","",Cadastro!$C5) | D6: =IF($A6="","",IF(COUNTIFS('Avaliação Semanal'!$B$5:$B$504,$A6,'Avaliação Semanal'!$C$5:$C$504,"GP",'Avaliação Semanal'!$A$5:$A$504,">="&$B$3,'Avaliação Semanal'!$A$5:$A$504,"<="&$D$3,'Avaliação Semanal'!$J$5:$J$504,">0")=0,"",ROUND(AVERAGEIFS('Avaliação Semanal'!$J$5:$J$504,'Avaliação Semanal'!$B$5:$B$504,$A6,'Avaliação Semanal'!$C$5:$C$504,"GP",'Avaliação Semanal'!$A$5:$A$504,">="&$B$3,'Avaliação Semanal'!$A$5:$A$504,"<="&$D$3),2))) | E6: =IF($A6="","",IF(COUNTIFS('Avaliação Semanal'!$B$5:$B$504,$A6,'Avaliação Semanal'!$C$5:$C$504,"Líder Técnico",'Avaliação Semanal'!$A$5:$A$504,">="&$B$3,'Avaliação Semanal'!$A$5:$A$504,"<="&$D$3,'Avaliação Semanal'!$J$5:$J$504,">0")=0,"",ROUND(AVERAGEIFS('Avaliação Semanal'!$J$5:$J$504,'Avaliação Semanal'!$B$5:$B$504,$A6,'Avaliação Semanal'!$C$5:$C$504,"Líder Técnico",'Avaliação Semanal'!$A$5:$A$504,">="&$B$3,'Avaliação Semanal'!$A$5:$A$504,"<="&$D$3),2))) | F6: =IF($A6="","",IF(COUNTIFS('Avaliação Semanal'!$B$5:$B$504,$A6,'Avaliação Semanal'!$A$5:$A$504,">="&$B$3,'Avaliação Semanal'!$A$5:$A$504,"<="&$D$3,'Avaliação Semanal'!$E$5:$E$504,">0")=0,"",ROUND(AVERAGEIFS('Avaliação Semanal'!$E$5:$E$504,'Avaliação Semanal'!$B$5:$B$504,$A6,'Avaliação Semanal'!$A$5:$A$504,">="&$B$3,'Avaliação Semanal'!$A$5:$A$504,"<="&$D$3),2))) | G6: =IF($A6="","",IF(COUNTIFS('Avaliação Semanal'!$B$5:$B$504,$A6,'Avaliação Semanal'!$A$5:$A$504,">="&$B$3,'Avaliação Semanal'!$A$5:$A$504,"<="&$D$3,'Avaliação Semanal'!$F$5:$F$504,">0")=0,"",ROUND(AVERAGEIFS('Avaliação Semanal'!$F$5:$F$504,'Avaliação Semanal'!$B$5:$B$504,$A6,'Avaliação Semanal'!$A$5:$A$504,">="&$B$3,'Avaliação Semanal'!$A$5:$A$504,"<="&$D$3),2))) | H6: =IF($A6="","",IF(COUNTIFS('Avaliação Semanal'!$B$5:$B$504,$A6,'Avaliação Semanal'!$A$5:$A$504,">="&$B$3,'Avaliação Semanal'!$A$5:$A$504,"<="&$D$3,'Avaliação Semanal'!$G$5:$G$504,">0")=0,"",ROUND(AVERAGEIFS('Avaliação Semanal'!$G$5:$G$504,'Avaliação Semanal'!$B$5:$B$504,$A6,'Avaliação Semanal'!$A$5:$A$504,">="&$B$3,'Avaliação Semanal'!$A$5:$A$504,"<="&$D$3),2))) | I6: =IF($A6="","",IF(COUNTIFS('Avaliação Semanal'!$B$5:$B$504,$A6,'Avaliação Semanal'!$A$5:$A$504,">="&$B$3,'Avaliação Semanal'!$A$5:$A$504,"<="&$D$3,'Avaliação Semanal'!$H$5:$H$504,">0")=0,"",ROUND(AVERAGEIFS('Avaliação Semanal'!$H$5:$H$504,'Avaliação Semanal'!$B$5:$B$504,$A6,'Avaliação Semanal'!$A$5:$A$504,">="&$B$3,'Avaliação Semanal'!$A$5:$A$504,"<="&$D$3),2))) | J6: =IF($A6="","",IF(COUNTIFS('Avaliação Semanal'!$B$5:$B$504,$A6,'Avaliação Semanal'!$A$5:$A$504,">="&$B$3,'Avaliação Semanal'!$A$5:$A$504,"<="&$D$3,'Avaliação Semanal'!$I$5:$I$504,">0")=0,"",ROUND(AVERAGEIFS('Avaliação Semanal'!$I$5:$I$504,'Avaliação Semanal'!$B$5:$B$504,$A6,'Avaliação Semanal'!$A$5:$A$504,">="&$B$3,'Avaliação Semanal'!$A$5:$A$504,"<="&$D$3),2))) | K6: =IF(COUNT($F6:$J6)=0,"",ROUND(AVERAGE($F6:$J6),2)) | L6: =IF($K6="","",IF($K6>=Cadastro!$H$5,"Verde",IF($K6>=Cadastro!$H$6,"Atenção","Crítico"))) | M6: =IF($A6="","",COUNTIFS('Avaliação Semanal'!$B$5:$B$504,$A6,'Avaliação Semanal'!$A$5:$A$504,">="&$B$3,'Avaliação Semanal'!$A$5:$A$504,"<="&$D$3,'Avaliação Semanal'!$J$5:$J$504,">0")) | N6: =IF($M6=0,"",_xlfn.MAXIFS('Avaliação Semanal'!$A$5:$A$504,'Avaliação Semanal'!$B$5:$B$504,$A6,'Avaliação Semanal'!$A$5:$A$504,"<="&$D$3)) | O6: =IF($A6="","",COUNTIFS('Ocorrências'!$B$5:$B$204,$A6,'Ocorrências'!$A$5:$A$204,">="&$B$3,'Ocorrências'!$A$5:$A$204,"<="&$D$3)) | P6: =IF($A6="","",COUNTIFS('Ocorrências'!$B$5:$B$204,$A6,'Ocorrências'!$C$5:$C$204,"Ponto de atenção",'Ocorrências'!$A$5:$A$204,">="&$B$3,'Ocorrências'!$A$5:$A$204,"<="&$D$3)+COUNTIFS('Ocorrências'!$B$5:$B$204,$A6,'Ocorrências'!$C$5:$C$204,"Crítica",'Ocorrências'!$A$5:$A$204,">="&$B$3,'Ocorrências'!$A$5:$A$204,"<="&$D$3)) | Q6: =IF($A6="","",IF(COUNTIFS('Avaliação Semanal'!$B$5:$B$504,$A6,'Avaliação Semanal'!$C$5:$C$504,"GP",'Avaliação Semanal'!$A$5:$A$504,">="&$B$3,'Avaliação Semanal'!$A$5:$A$504,"<="&$D$3)=0,"",IFERROR(INDEX('Avaliação Semanal'!$L$5:$L$504,MATCH($A6&"|GP|"&TEXT(_xlfn.MAXIFS('Avaliação Semanal'!$A$5:$A$504,'Avaliação Semanal'!$B$5:$B$504,$A6,'Avaliação Semanal'!$C$5:$C$504,"GP",'Avaliação Semanal'!$A$5:$A$504,"<="&$D$3),"00000"),'Avaliação Semanal'!$M$5:$M$504,0)),""))) | R6: =IF($A6="","",IF(COUNTIFS('Avaliação Semanal'!$B$5:$B$504,$A6,'Avaliação Semanal'!$C$5:$C$504,"Líder Técnico",'Avaliação Semanal'!$A$5:$A$504,">="&$B$3,'Avaliação Semanal'!$A$5:$A$504,"<="&$D$3)=0,"",IFERROR(INDEX('Avaliação Semanal'!$L$5:$L$504,MATCH($A6&"|Líder Técnico|"&TEXT(_xlfn.MAXIFS('Avaliação Semanal'!$A$5:$A$504,'Avaliação Semanal'!$B$5:$B$504,$A6,'Avaliação Semanal'!$C$5:$C$504,"Líder Técnico",'Avaliação Semanal'!$A$5:$A$504,"<="&$D$3),"00000"),'Avaliação Semanal'!$M$5:$M$504,0)),"")))
A7: =IF(Cadastro!$A6="","",Cadastro!$A6) | B7: =IF(Cadastro!$A6="","",Cadastro!$B6) | C7: =IF(Cadastro!$A6="","",Cadastro!$C6) | D7: =IF($A7="","",IF(COUNTIFS('Avaliação Semanal'!$B$5:$B$504,$A7,'Avaliação Semanal'!$C$5:$C$504,"GP",'Avaliação Semanal'!$A$5:$A$504,">="&$B$3,'Avaliação Semanal'!$A$5:$A$504,"<="&$D$3,'Avaliação Semanal'!$J$5:$J$504,">0")=0,"",ROUND(AVERAGEIFS('Avaliação Semanal'!$J$5:$J$504,'Avaliação Semanal'!$B$5:$B$504,$A7,'Avaliação Semanal'!$C$5:$C$504,"GP",'Avaliação Semanal'!$A$5:$A$504,">="&$B$3,'Avaliação Semanal'!$A$5:$A$504,"<="&$D$3),2))) | E7: =IF($A7="","",IF(COUNTIFS('Avaliação Semanal'!$B$5:$B$504,$A7,'Avaliação Semanal'!$C$5:$C$504,"Líder Técnico",'Avaliação Semanal'!$A$5:$A$504,">="&$B$3,'Avaliação Semanal'!$A$5:$A$504,"<="&$D$3,'Avaliação Semanal'!$J$5:$J$504,">0")=0,"",ROUND(AVERAGEIFS('Avaliação Semanal'!$J$5:$J$504,'Avaliação Semanal'!$B$5:$B$504,$A7,'Avaliação Semanal'!$C$5:$C$504,"Líder Técnico",'Avaliação Semanal'!$A$5:$A$504,">="&$B$3,'Avaliação Semanal'!$A$5:$A$504,"<="&$D$3),2))) | F7: =IF($A7="","",IF(COUNTIFS('Avaliação Semanal'!$B$5:$B$504,$A7,'Avaliação Semanal'!$A$5:$A$504,">="&$B$3,'Avaliação Semanal'!$A$5:$A$504,"<="&$D$3,'Avaliação Semanal'!$E$5:$E$504,">0")=0,"",ROUND(AVERAGEIFS('Avaliação Semanal'!$E$5:$E$504,'Avaliação Semanal'!$B$5:$B$504,$A7,'Avaliação Semanal'!$A$5:$A$504,">="&$B$3,'Avaliação Semanal'!$A$5:$A$504,"<="&$D$3),2))) | G7: =IF($A7="","",IF(COUNTIFS('Avaliação Semanal'!$B$5:$B$504,$A7,'Avaliação Semanal'!$A$5:$A$504,">="&$B$3,'Avaliação Semanal'!$A$5:$A$504,"<="&$D$3,'Avaliação Semanal'!$F$5:$F$504,">0")=0,"",ROUND(AVERAGEIFS('Avaliação Semanal'!$F$5:$F$504,'Avaliação Semanal'!$B$5:$B$504,$A7,'Avaliação Semanal'!$A$5:$A$504,">="&$B$3,'Avaliação Semanal'!$A$5:$A$504,"<="&$D$3),2))) | H7: =IF($A7="","",IF(COUNTIFS('Avaliação Semanal'!$B$5:$B$504,$A7,'Avaliação Semanal'!$A$5:$A$504,">="&$B$3,'Avaliação Semanal'!$A$5:$A$504,"<="&$D$3,'Avaliação Semanal'!$G$5:$G$504,">0")=0,"",ROUND(AVERAGEIFS('Avaliação Semanal'!$G$5:$G$504,'Avaliação Semanal'!$B$5:$B$504,$A7,'Avaliação Semanal'!$A$5:$A$504,">="&$B$3,'Avaliação Semanal'!$A$5:$A$504,"<="&$D$3),2))) | I7: =IF($A7="","",IF(COUNTIFS('Avaliação Semanal'!$B$5:$B$504,$A7,'Avaliação Semanal'!$A$5:$A$504,">="&$B$3,'Avaliação Semanal'!$A$5:$A$504,"<="&$D$3,'Avaliação Semanal'!$H$5:$H$504,">0")=0,"",ROUND(AVERAGEIFS('Avaliação Semanal'!$H$5:$H$504,'Avaliação Semanal'!$B$5:$B$504,$A7,'Avaliação Semanal'!$A$5:$A$504,">="&$B$3,'Avaliação Semanal'!$A$5:$A$504,"<="&$D$3),2))) | J7: =IF($A7="","",IF(COUNTIFS('Avaliação Semanal'!$B$5:$B$504,$A7,'Avaliação Semanal'!$A$5:$A$504,">="&$B$3,'Avaliação Semanal'!$A$5:$A$504,"<="&$D$3,'Avaliação Semanal'!$I$5:$I$504,">0")=0,"",ROUND(AVERAGEIFS('Avaliação Semanal'!$I$5:$I$504,'Avaliação Semanal'!$B$5:$B$504,$A7,'Avaliação Semanal'!$A$5:$A$504,">="&$B$3,'Avaliação Semanal'!$A$5:$A$504,"<="&$D$3),2))) | K7: =IF(COUNT($F7:$J7)=0,"",ROUND(AVERAGE($F7:$J7),2)) | L7: =IF($K7="","",IF($K7>=Cadastro!$H$5,"Verde",IF($K7>=Cadastro!$H$6,"Atenção","Crítico"))) | M7: =IF($A7="","",COUNTIFS('Avaliação Semanal'!$B$5:$B$504,$A7,'Avaliação Semanal'!$A$5:$A$504,">="&$B$3,'Avaliação Semanal'!$A$5:$A$504,"<="&$D$3,'Avaliação Semanal'!$J$5:$J$504,">0")) | N7: =IF($M7=0,"",_xlfn.MAXIFS('Avaliação Semanal'!$A$5:$A$504,'Avaliação Semanal'!$B$5:$B$504,$A7,'Avaliação Semanal'!$A$5:$A$504,"<="&$D$3)) | O7: =IF($A7="","",COUNTIFS('Ocorrências'!$B$5:$B$204,$A7,'Ocorrências'!$A$5:$A$204,">="&$B$3,'Ocorrências'!$A$5:$A$204,"<="&$D$3)) | P7: =IF($A7="","",COUNTIFS('Ocorrências'!$B$5:$B$204,$A7,'Ocorrências'!$C$5:$C$204,"Ponto de atenção",'Ocorrências'!$A$5:$A$204,">="&$B$3,'Ocorrências'!$A$5:$A$204,"<="&$D$3)+COUNTIFS('Ocorrências'!$B$5:$B$204,$A7,'Ocorrências'!$C$5:$C$204,"Crítica",'Ocorrências'!$A$5:$A$204,">="&$B$3,'Ocorrências'!$A$5:$A$204,"<="&$D$3)) | Q7: =IF($A7="","",IF(COUNTIFS('Avaliação Semanal'!$B$5:$B$504,$A7,'Avaliação Semanal'!$C$5:$C$504,"GP",'Avaliação Semanal'!$A$5:$A$504,">="&$B$3,'Avaliação Semanal'!$A$5:$A$504,"<="&$D$3)=0,"",IFERROR(INDEX('Avaliação Semanal'!$L$5:$L$504,MATCH($A7&"|GP|"&TEXT(_xlfn.MAXIFS('Avaliação Semanal'!$A$5:$A$504,'Avaliação Semanal'!$B$5:$B$504,$A7,'Avaliação Semanal'!$C$5:$C$504,"GP",'Avaliação Semanal'!$A$5:$A$504,"<="&$D$3),"00000"),'Avaliação Semanal'!$M$5:$M$504,0)),""))) | R7: =IF($A7="","",IF(COUNTIFS('Avaliação Semanal'!$B$5:$B$504,$A7,'Avaliação Semanal'!$C$5:$C$504,"Líder Técnico",'Avaliação Semanal'!$A$5:$A$504,">="&$B$3,'Avaliação Semanal'!$A$5:$A$504,"<="&$D$3)=0,"",IFERROR(INDEX('Avaliação Semanal'!$L$5:$L$504,MATCH($A7&"|Líder Técnico|"&TEXT(_xlfn.MAXIFS('Avaliação Semanal'!$A$5:$A$504,'Avaliação Semanal'!$B$5:$B$504,$A7,'Avaliação Semanal'!$C$5:$C$504,"Líder Técnico",'Avaliação Semanal'!$A$5:$A$504,"<="&$D$3),"00000"),'Avaliação Semanal'!$M$5:$M$504,0)),"")))
A8: =IF(Cadastro!$A7="","",Cadastro!$A7) | B8: =IF(Cadastro!$A7="","",Cadastro!$B7) | C8: =IF(Cadastro!$A7="","",Cadastro!$C7) | D8: =IF($A8="","",IF(COUNTIFS('Avaliação Semanal'!$B$5:$B$504,$A8,'Avaliação Semanal'!$C$5:$C$504,"GP",'Avaliação Semanal'!$A$5:$A$504,">="&$B$3,'Avaliação Semanal'!$A$5:$A$504,"<="&$D$3,'Avaliação Semanal'!$J$5:$J$504,">0")=0,"",ROUND(AVERAGEIFS('Avaliação Semanal'!$J$5:$J$504,'Avaliação Semanal'!$B$5:$B$504,$A8,'Avaliação Semanal'!$C$5:$C$504,"GP",'Avaliação Semanal'!$A$5:$A$504,">="&$B$3,'Avaliação Semanal'!$A$5:$A$504,"<="&$D$3),2))) | E8: =IF($A8="","",IF(COUNTIFS('Avaliação Semanal'!$B$5:$B$504,$A8,'Avaliação Semanal'!$C$5:$C$504,"Líder Técnico",'Avaliação Semanal'!$A$5:$A$504,">="&$B$3,'Avaliação Semanal'!$A$5:$A$504,"<="&$D$3,'Avaliação Semanal'!$J$5:$J$504,">0")=0,"",ROUND(AVERAGEIFS('Avaliação Semanal'!$J$5:$J$504,'Avaliação Semanal'!$B$5:$B$504,$A8,'Avaliação Semanal'!$C$5:$C$504,"Líder Técnico",'Avaliação Semanal'!$A$5:$A$504,">="&$B$3,'Avaliação Semanal'!$A$5:$A$504,"<="&$D$3),2))) | F8: =IF($A8="","",IF(COUNTIFS('Avaliação Semanal'!$B$5:$B$504,$A8,'Avaliação Semanal'!$A$5:$A$504,">="&$B$3,'Avaliação Semanal'!$A$5:$A$504,"<="&$D$3,'Avaliação Semanal'!$E$5:$E$504,">0")=0,"",ROUND(AVERAGEIFS('Avaliação Semanal'!$E$5:$E$504,'Avaliação Semanal'!$B$5:$B$504,$A8,'Avaliação Semanal'!$A$5:$A$504,">="&$B$3,'Avaliação Semanal'!$A$5:$A$504,"<="&$D$3),2))) | G8: =IF($A8="","",IF(COUNTIFS('Avaliação Semanal'!$B$5:$B$504,$A8,'Avaliação Semanal'!$A$5:$A$504,">="&$B$3,'Avaliação Semanal'!$A$5:$A$504,"<="&$D$3,'Avaliação Semanal'!$F$5:$F$504,">0")=0,"",ROUND(AVERAGEIFS('Avaliação Semanal'!$F$5:$F$504,'Avaliação Semanal'!$B$5:$B$504,$A8,'Avaliação Semanal'!$A$5:$A$504,">="&$B$3,'Avaliação Semanal'!$A$5:$A$504,"<="&$D$3),2))) | H8: =IF($A8="","",IF(COUNTIFS('Avaliação Semanal'!$B$5:$B$504,$A8,'Avaliação Semanal'!$A$5:$A$504,">="&$B$3,'Avaliação Semanal'!$A$5:$A$504,"<="&$D$3,'Avaliação Semanal'!$G$5:$G$504,">0")=0,"",ROUND(AVERAGEIFS('Avaliação Semanal'!$G$5:$G$504,'Avaliação Semanal'!$B$5:$B$504,$A8,'Avaliação Semanal'!$A$5:$A$504,">="&$B$3,'Avaliação Semanal'!$A$5:$A$504,"<="&$D$3),2))) | I8: =IF($A8="","",IF(COUNTIFS('Avaliação Semanal'!$B$5:$B$504,$A8,'Avaliação Semanal'!$A$5:$A$504,">="&$B$3,'Avaliação Semanal'!$A$5:$A$504,"<="&$D$3,'Avaliação Semanal'!$H$5:$H$504,">0")=0,"",ROUND(AVERAGEIFS('Avaliação Semanal'!$H$5:$H$504,'Avaliação Semanal'!$B$5:$B$504,$A8,'Avaliação Semanal'!$A$5:$A$504,">="&$B$3,'Avaliação Semanal'!$A$5:$A$504,"<="&$D$3),2))) | J8: =IF($A8="","",IF(COUNTIFS('Avaliação Semanal'!$B$5:$B$504,$A8,'Avaliação Semanal'!$A$5:$A$504,">="&$B$3,'Avaliação Semanal'!$A$5:$A$504,"<="&$D$3,'Avaliação Semanal'!$I$5:$I$504,">0")=0,"",ROUND(AVERAGEIFS('Avaliação Semanal'!$I$5:$I$504,'Avaliação Semanal'!$B$5:$B$504,$A8,'Avaliação Semanal'!$A$5:$A$504,">="&$B$3,'Avaliação Semanal'!$A$5:$A$504,"<="&$D$3),2))) | K8: =IF(COUNT($F8:$J8)=0,"",ROUND(AVERAGE($F8:$J8),2)) | L8: =IF($K8="","",IF($K8>=Cadastro!$H$5,"Verde",IF($K8>=Cadastro!$H$6,"Atenção","Crítico"))) | M8: =IF($A8="","",COUNTIFS('Avaliação Semanal'!$B$5:$B$504,$A8,'Avaliação Semanal'!$A$5:$A$504,">="&$B$3,'Avaliação Semanal'!$A$5:$A$504,"<="&$D$3,'Avaliação Semanal'!$J$5:$J$504,">0")) | N8: =IF($M8=0,"",_xlfn.MAXIFS('Avaliação Semanal'!$A$5:$A$504,'Avaliação Semanal'!$B$5:$B$504,$A8,'Avaliação Semanal'!$A$5:$A$504,"<="&$D$3)) | O8: =IF($A8="","",COUNTIFS('Ocorrências'!$B$5:$B$204,$A8,'Ocorrências'!$A$5:$A$204,">="&$B$3,'Ocorrências'!$A$5:$A$204,"<="&$D$3)) | P8: =IF($A8="","",COUNTIFS('Ocorrências'!$B$5:$B$204,$A8,'Ocorrências'!$C$5:$C$204,"Ponto de atenção",'Ocorrências'!$A$5:$A$204,">="&$B$3,'Ocorrências'!$A$5:$A$204,"<="&$D$3)+COUNTIFS('Ocorrências'!$B$5:$B$204,$A8,'Ocorrências'!$C$5:$C$204,"Crítica",'Ocorrências'!$A$5:$A$204,">="&$B$3,'Ocorrências'!$A$5:$A$204,"<="&$D$3)) | Q8: =IF($A8="","",IF(COUNTIFS('Avaliação Semanal'!$B$5:$B$504,$A8,'Avaliação Semanal'!$C$5:$C$504,"GP",'Avaliação Semanal'!$A$5:$A$504,">="&$B$3,'Avaliação Semanal'!$A$5:$A$504,"<="&$D$3)=0,"",IFERROR(INDEX('Avaliação Semanal'!$L$5:$L$504,MATCH($A8&"|GP|"&TEXT(_xlfn.MAXIFS('Avaliação Semanal'!$A$5:$A$504,'Avaliação Semanal'!$B$5:$B$504,$A8,'Avaliação Semanal'!$C$5:$C$504,"GP",'Avaliação Semanal'!$A$5:$A$504,"<="&$D$3),"00000"),'Avaliação Semanal'!$M$5:$M$504,0)),""))) | R8: =IF($A8="","",IF(COUNTIFS('Avaliação Semanal'!$B$5:$B$504,$A8,'Avaliação Semanal'!$C$5:$C$504,"Líder Técnico",'Avaliação Semanal'!$A$5:$A$504,">="&$B$3,'Avaliação Semanal'!$A$5:$A$504,"<="&$D$3)=0,"",IFERROR(INDEX('Avaliação Semanal'!$L$5:$L$504,MATCH($A8&"|Líder Técnico|"&TEXT(_xlfn.MAXIFS('Avaliação Semanal'!$A$5:$A$504,'Avaliação Semanal'!$B$5:$B$504,$A8,'Avaliação Semanal'!$C$5:$C$504,"Líder Técnico",'Avaliação Semanal'!$A$5:$A$504,"<="&$D$3),"00000"),'Avaliação Semanal'!$M$5:$M$504,0)),"")))
A9: =IF(Cadastro!$A8="","",Cadastro!$A8) | B9: =IF(Cadastro!$A8="","",Cadastro!$B8) | C9: =IF(Cadastro!$A8="","",Cadastro!$C8) | D9: =IF($A9="","",IF(COUNTIFS('Avaliação Semanal'!$B$5:$B$504,$A9,'Avaliação Semanal'!$C$5:$C$504,"GP",'Avaliação Semanal'!$A$5:$A$504,">="&$B$3,'Avaliação Semanal'!$A$5:$A$504,"<="&$D$3,'Avaliação Semanal'!$J$5:$J$504,">0")=0,"",ROUND(AVERAGEIFS('Avaliação Semanal'!$J$5:$J$504,'Avaliação Semanal'!$B$5:$B$504,$A9,'Avaliação Semanal'!$C$5:$C$504,"GP",'Avaliação Semanal'!$A$5:$A$504,">="&$B$3,'Avaliação Semanal'!$A$5:$A$504,"<="&$D$3),2))) | E9: =IF($A9="","",IF(COUNTIFS('Avaliação Semanal'!$B$5:$B$504,$A9,'Avaliação Semanal'!$C$5:$C$504,"Líder Técnico",'Avaliação Semanal'!$A$5:$A$504,">="&$B$3,'Avaliação Semanal'!$A$5:$A$504,"<="&$D$3,'Avaliação Semanal'!$J$5:$J$504,">0")=0,"",ROUND(AVERAGEIFS('Avaliação Semanal'!$J$5:$J$504,'Avaliação Semanal'!$B$5:$B$504,$A9,'Avaliação Semanal'!$C$5:$C$504,"Líder Técnico",'Avaliação Semanal'!$A$5:$A$504,">="&$B$3,'Avaliação Semanal'!$A$5:$A$504,"<="&$D$3),2))) | F9: =IF($A9="","",IF(COUNTIFS('Avaliação Semanal'!$B$5:$B$504,$A9,'Avaliação Semanal'!$A$5:$A$504,">="&$B$3,'Avaliação Semanal'!$A$5:$A$504,"<="&$D$3,'Avaliação Semanal'!$E$5:$E$504,">0")=0,"",ROUND(AVERAGEIFS('Avaliação Semanal'!$E$5:$E$504,'Avaliação Semanal'!$B$5:$B$504,$A9,'Avaliação Semanal'!$A$5:$A$504,">="&$B$3,'Avaliação Semanal'!$A$5:$A$504,"<="&$D$3),2))) | G9: =IF($A9="","",IF(COUNTIFS('Avaliação Semanal'!$B$5:$B$504,$A9,'Avaliação Semanal'!$A$5:$A$504,">="&$B$3,'Avaliação Semanal'!$A$5:$A$504,"<="&$D$3,'Avaliação Semanal'!$F$5:$F$504,">0")=0,"",ROUND(AVERAGEIFS('Avaliação Semanal'!$F$5:$F$504,'Avaliação Semanal'!$B$5:$B$504,$A9,'Avaliação Semanal'!$A$5:$A$504,">="&$B$3,'Avaliação Semanal'!$A$5:$A$504,"<="&$D$3),2))) | H9: =IF($A9="","",IF(COUNTIFS('Avaliação Semanal'!$B$5:$B$504,$A9,'Avaliação Semanal'!$A$5:$A$504,">="&$B$3,'Avaliação Semanal'!$A$5:$A$504,"<="&$D$3,'Avaliação Semanal'!$G$5:$G$504,">0")=0,"",ROUND(AVERAGEIFS('Avaliação Semanal'!$G$5:$G$504,'Avaliação Semanal'!$B$5:$B$504,$A9,'Avaliação Semanal'!$A$5:$A$504,">="&$B$3,'Avaliação Semanal'!$A$5:$A$504,"<="&$D$3),2))) | I9: =IF($A9="","",IF(COUNTIFS('Avaliação Semanal'!$B$5:$B$504,$A9,'Avaliação Semanal'!$A$5:$A$504,">="&$B$3,'Avaliação Semanal'!$A$5:$A$504,"<="&$D$3,'Avaliação Semanal'!$H$5:$H$504,">0")=0,"",ROUND(AVERAGEIFS('Avaliação Semanal'!$H$5:$H$504,'Avaliação Semanal'!$B$5:$B$504,$A9,'Avaliação Semanal'!$A$5:$A$504,">="&$B$3,'Avaliação Semanal'!$A$5:$A$504,"<="&$D$3),2))) | J9: =IF($A9="","",IF(COUNTIFS('Avaliação Semanal'!$B$5:$B$504,$A9,'Avaliação Semanal'!$A$5:$A$504,">="&$B$3,'Avaliação Semanal'!$A$5:$A$504,"<="&$D$3,'Avaliação Semanal'!$I$5:$I$504,">0")=0,"",ROUND(AVERAGEIFS('Avaliação Semanal'!$I$5:$I$504,'Avaliação Semanal'!$B$5:$B$504,$A9,'Avaliação Semanal'!$A$5:$A$504,">="&$B$3,'Avaliação Semanal'!$A$5:$A$504,"<="&$D$3),2))) | K9: =IF(COUNT($F9:$J9)=0,"",ROUND(AVERAGE($F9:$J9),2)) | L9: =IF($K9="","",IF($K9>=Cadastro!$H$5,"Verde",IF($K9>=Cadastro!$H$6,"Atenção","Crítico"))) | M9: =IF($A9="","",COUNTIFS('Avaliação Semanal'!$B$5:$B$504,$A9,'Avaliação Semanal'!$A$5:$A$504,">="&$B$3,'Avaliação Semanal'!$A$5:$A$504,"<="&$D$3,'Avaliação Semanal'!$J$5:$J$504,">0")) | N9: =IF($M9=0,"",_xlfn.MAXIFS('Avaliação Semanal'!$A$5:$A$504,'Avaliação Semanal'!$B$5:$B$504,$A9,'Avaliação Semanal'!$A$5:$A$504,"<="&$D$3)) | O9: =IF($A9="","",COUNTIFS('Ocorrências'!$B$5:$B$204,$A9,'Ocorrências'!$A$5:$A$204,">="&$B$3,'Ocorrências'!$A$5:$A$204,"<="&$D$3)) | P9: =IF($A9="","",COUNTIFS('Ocorrências'!$B$5:$B$204,$A9,'Ocorrências'!$C$5:$C$204,"Ponto de atenção",'Ocorrências'!$A$5:$A$204,">="&$B$3,'Ocorrências'!$A$5:$A$204,"<="&$D$3)+COUNTIFS('Ocorrências'!$B$5:$B$204,$A9,'Ocorrências'!$C$5:$C$204,"Crítica",'Ocorrências'!$A$5:$A$204,">="&$B$3,'Ocorrências'!$A$5:$A$204,"<="&$D$3)) | Q9: =IF($A9="","",IF(COUNTIFS('Avaliação Semanal'!$B$5:$B$504,$A9,'Avaliação Semanal'!$C$5:$C$504,"GP",'Avaliação Semanal'!$A$5:$A$504,">="&$B$3,'Avaliação Semanal'!$A$5:$A$504,"<="&$D$3)=0,"",IFERROR(INDEX('Avaliação Semanal'!$L$5:$L$504,MATCH($A9&"|GP|"&TEXT(_xlfn.MAXIFS('Avaliação Semanal'!$A$5:$A$504,'Avaliação Semanal'!$B$5:$B$504,$A9,'Avaliação Semanal'!$C$5:$C$504,"GP",'Avaliação Semanal'!$A$5:$A$504,"<="&$D$3),"00000"),'Avaliação Semanal'!$M$5:$M$504,0)),""))) | R9: =IF($A9="","",IF(COUNTIFS('Avaliação Semanal'!$B$5:$B$504,$A9,'Avaliação Semanal'!$C$5:$C$504,"Líder Técnico",'Avaliação Semanal'!$A$5:$A$504,">="&$B$3,'Avaliação Semanal'!$A$5:$A$504,"<="&$D$3)=0,"",IFERROR(INDEX('Avaliação Semanal'!$L$5:$L$504,MATCH($A9&"|Líder Técnico|"&TEXT(_xlfn.MAXIFS('Avaliação Semanal'!$A$5:$A$504,'Avaliação Semanal'!$B$5:$B$504,$A9,'Avaliação Semanal'!$C$5:$C$504,"Líder Técnico",'Avaliação Semanal'!$A$5:$A$504,"<="&$D$3),"00000"),'Avaliação Semanal'!$M$5:$M$504,0)),"")))
A10: =IF(Cadastro!$A9="","",Cadastro!$A9) | B10: =IF(Cadastro!$A9="","",Cadastro!$B9) | C10: =IF(Cadastro!$A9="","",Cadastro!$C9) | D10: =IF($A10="","",IF(COUNTIFS('Avaliação Semanal'!$B$5:$B$504,$A10,'Avaliação Semanal'!$C$5:$C$504,"GP",'Avaliação Semanal'!$A$5:$A$504,">="&$B$3,'Avaliação Semanal'!$A$5:$A$504,"<="&$D$3,'Avaliação Semanal'!$J$5:$J$504,">0")=0,"",ROUND(AVERAGEIFS('Avaliação Semanal'!$J$5:$J$504,'Avaliação Semanal'!$B$5:$B$504,$A10,'Avaliação Semanal'!$C$5:$C$504,"GP",'Avaliação Semanal'!$A$5:$A$504,">="&$B$3,'Avaliação Semanal'!$A$5:$A$504,"<="&$D$3),2))) | E10: =IF($A10="","",IF(COUNTIFS('Avaliação Semanal'!$B$5:$B$504,$A10,'Avaliação Semanal'!$C$5:$C$504,"Líder Técnico",'Avaliação Semanal'!$A$5:$A$504,">="&$B$3,'Avaliação Semanal'!$A$5:$A$504,"<="&$D$3,'Avaliação Semanal'!$J$5:$J$504,">0")=0,"",ROUND(AVERAGEIFS('Avaliação Semanal'!$J$5:$J$504,'Avaliação Semanal'!$B$5:$B$504,$A10,'Avaliação Semanal'!$C$5:$C$504,"Líder Técnico",'Avaliação Semanal'!$A$5:$A$504,">="&$B$3,'Avaliação Semanal'!$A$5:$A$504,"<="&$D$3),2))) | F10: =IF($A10="","",IF(COUNTIFS('Avaliação Semanal'!$B$5:$B$504,$A10,'Avaliação Semanal'!$A$5:$A$504,">="&$B$3,'Avaliação Semanal'!$A$5:$A$504,"<="&$D$3,'Avaliação Semanal'!$E$5:$E$504,">0")=0,"",ROUND(AVERAGEIFS('Avaliação Semanal'!$E$5:$E$504,'Avaliação Semanal'!$B$5:$B$504,$A10,'Avaliação Semanal'!$A$5:$A$504,">="&$B$3,'Avaliação Semanal'!$A$5:$A$504,"<="&$D$3),2))) | G10: =IF($A10="","",IF(COUNTIFS('Avaliação Semanal'!$B$5:$B$504,$A10,'Avaliação Semanal'!$A$5:$A$504,">="&$B$3,'Avaliação Semanal'!$A$5:$A$504,"<="&$D$3,'Avaliação Semanal'!$F$5:$F$504,">0")=0,"",ROUND(AVERAGEIFS('Avaliação Semanal'!$F$5:$F$504,'Avaliação Semanal'!$B$5:$B$504,$A10,'Avaliação Semanal'!$A$5:$A$504,">="&$B$3,'Avaliação Semanal'!$A$5:$A$504,"<="&$D$3),2))) | H10: =IF($A10="","",IF(COUNTIFS('Avaliação Semanal'!$B$5:$B$504,$A10,'Avaliação Semanal'!$A$5:$A$504,">="&$B$3,'Avaliação Semanal'!$A$5:$A$504,"<="&$D$3,'Avaliação Semanal'!$G$5:$G$504,">0")=0,"",ROUND(AVERAGEIFS('Avaliação Semanal'!$G$5:$G$504,'Avaliação Semanal'!$B$5:$B$504,$A10,'Avaliação Semanal'!$A$5:$A$504,">="&$B$3,'Avaliação Semanal'!$A$5:$A$504,"<="&$D$3),2))) | I10: =IF($A10="","",IF(COUNTIFS('Avaliação Semanal'!$B$5:$B$504,$A10,'Avaliação Semanal'!$A$5:$A$504,">="&$B$3,'Avaliação Semanal'!$A$5:$A$504,"<="&$D$3,'Avaliação Semanal'!$H$5:$H$504,">0")=0,"",ROUND(AVERAGEIFS('Avaliação Semanal'!$H$5:$H$504,'Avaliação Semanal'!$B$5:$B$504,$A10,'Avaliação Semanal'!$A$5:$A$504,">="&$B$3,'Avaliação Semanal'!$A$5:$A$504,"<="&$D$3),2))) | J10: =IF($A10="","",IF(COUNTIFS('Avaliação Semanal'!$B$5:$B$504,$A10,'Avaliação Semanal'!$A$5:$A$504,">="&$B$3,'Avaliação Semanal'!$A$5:$A$504,"<="&$D$3,'Avaliação Semanal'!$I$5:$I$504,">0")=0,"",ROUND(AVERAGEIFS('Avaliação Semanal'!$I$5:$I$504,'Avaliação Semanal'!$B$5:$B$504,$A10,'Avaliação Semanal'!$A$5:$A$504,">="&$B$3,'Avaliação Semanal'!$A$5:$A$504,"<="&$D$3),2))) | K10: =IF(COUNT($F10:$J10)=0,"",ROUND(AVERAGE($F10:$J10),2)) | L10: =IF($K10="","",IF($K10>=Cadastro!$H$5,"Verde",IF($K10>=Cadastro!$H$6,"Atenção","Crítico"))) | M10: =IF($A10="","",COUNTIFS('Avaliação Semanal'!$B$5:$B$504,$A10,'Avaliação Semanal'!$A$5:$A$504,">="&$B$3,'Avaliação Semanal'!$A$5:$A$504,"<="&$D$3,'Avaliação Semanal'!$J$5:$J$504,">0")) | N10: =IF($M10=0,"",_xlfn.MAXIFS('Avaliação Semanal'!$A$5:$A$504,'Avaliação Semanal'!$B$5:$B$504,$A10,'Avaliação Semanal'!$A$5:$A$504,"<="&$D$3)) | O10: =IF($A10="","",COUNTIFS('Ocorrências'!$B$5:$B$204,$A10,'Ocorrências'!$A$5:$A$204,">="&$B$3,'Ocorrências'!$A$5:$A$204,"<="&$D$3)) | P10: =IF($A10="","",COUNTIFS('Ocorrências'!$B$5:$B$204,$A10,'Ocorrências'!$C$5:$C$204,"Ponto de atenção",'Ocorrências'!$A$5:$A$204,">="&$B$3,'Ocorrências'!$A$5:$A$204,"<="&$D$3)+COUNTIFS('Ocorrências'!$B$5:$B$204,$A10,'Ocorrências'!$C$5:$C$204,"Crítica",'Ocorrências'!$A$5:$A$204,">="&$B$3,'Ocorrências'!$A$5:$A$204,"<="&$D$3)) | Q10: =IF($A10="","",IF(COUNTIFS('Avaliação Semanal'!$B$5:$B$504,$A10,'Avaliação Semanal'!$C$5:$C$504,"GP",'Avaliação Semanal'!$A$5:$A$504,">="&$B$3,'Avaliação Semanal'!$A$5:$A$504,"<="&$D$3)=0,"",IFERROR(INDEX('Avaliação Semanal'!$L$5:$L$504,MATCH($A10&"|GP|"&TEXT(_xlfn.MAXIFS('Avaliação Semanal'!$A$5:$A$504,'Avaliação Semanal'!$B$5:$B$504,$A10,'Avaliação Semanal'!$C$5:$C$504,"GP",'Avaliação Semanal'!$A$5:$A$504,"<="&$D$3),"00000"),'Avaliação Semanal'!$M$5:$M$504,0)),""))) | R10: =IF($A10="","",IF(COUNTIFS('Avaliação Semanal'!$B$5:$B$504,$A10,'Avaliação Semanal'!$C$5:$C$504,"Líder Técnico",'Avaliação Semanal'!$A$5:$A$504,">="&$B$3,'Avaliação Semanal'!$A$5:$A$504,"<="&$D$3)=0,"",IFERROR(INDEX('Avaliação Semanal'!$L$5:$L$504,MATCH($A10&"|Líder Técnico|"&TEXT(_xlfn.MAXIFS('Avaliação Semanal'!$A$5:$A$504,'Avaliação Semanal'!$B$5:$B$504,$A10,'Avaliação Semanal'!$C$5:$C$504,"Líder Técnico",'Avaliação Semanal'!$A$5:$A$504,"<="&$D$3),"00000"),'Avaliação Semanal'!$M$5:$M$504,0)),"")))
A11: =IF(Cadastro!$A10="","",Cadastro!$A10) | B11: =IF(Cadastro!$A10="","",Cadastro!$B10) | C11: =IF(Cadastro!$A10="","",Cadastro!$C10) | D11: =IF($A11="","",IF(COUNTIFS('Avaliação Semanal'!$B$5:$B$504,$A11,'Avaliação Semanal'!$C$5:$C$504,"GP",'Avaliação Semanal'!$A$5:$A$504,">="&$B$3,'Avaliação Semanal'!$A$5:$A$504,"<="&$D$3,'Avaliação Semanal'!$J$5:$J$504,">0")=0,"",ROUND(AVERAGEIFS('Avaliação Semanal'!$J$5:$J$504,'Avaliação Semanal'!$B$5:$B$504,$A11,'Avaliação Semanal'!$C$5:$C$504,"GP",'Avaliação Semanal'!$A$5:$A$504,">="&$B$3,'Avaliação Semanal'!$A$5:$A$504,"<="&$D$3),2))) | E11: =IF($A11="","",IF(COUNTIFS('Avaliação Semanal'!$B$5:$B$504,$A11,'Avaliação Semanal'!$C$5:$C$504,"Líder Técnico",'Avaliação Semanal'!$A$5:$A$504,">="&$B$3,'Avaliação Semanal'!$A$5:$A$504,"<="&$D$3,'Avaliação Semanal'!$J$5:$J$504,">0")=0,"",ROUND(AVERAGEIFS('Avaliação Semanal'!$J$5:$J$504,'Avaliação Semanal'!$B$5:$B$504,$A11,'Avaliação Semanal'!$C$5:$C$504,"Líder Técnico",'Avaliação Semanal'!$A$5:$A$504,">="&$B$3,'Avaliação Semanal'!$A$5:$A$504,"<="&$D$3),2))) | F11: =IF($A11="","",IF(COUNTIFS('Avaliação Semanal'!$B$5:$B$504,$A11,'Avaliação Semanal'!$A$5:$A$504,">="&$B$3,'Avaliação Semanal'!$A$5:$A$504,"<="&$D$3,'Avaliação Semanal'!$E$5:$E$504,">0")=0,"",ROUND(AVERAGEIFS('Avaliação Semanal'!$E$5:$E$504,'Avaliação Semanal'!$B$5:$B$504,$A11,'Avaliação Semanal'!$A$5:$A$504,">="&$B$3,'Avaliação Semanal'!$A$5:$A$504,"<="&$D$3),2))) | G11: =IF($A11="","",IF(COUNTIFS('Avaliação Semanal'!$B$5:$B$504,$A11,'Avaliação Semanal'!$A$5:$A$504,">="&$B$3,'Avaliação Semanal'!$A$5:$A$504,"<="&$D$3,'Avaliação Semanal'!$F$5:$F$504,">0")=0,"",ROUND(AVERAGEIFS('Avaliação Semanal'!$F$5:$F$504,'Avaliação Semanal'!$B$5:$B$504,$A11,'Avaliação Semanal'!$A$5:$A$504,">="&$B$3,'Avaliação Semanal'!$A$5:$A$504,"<="&$D$3),2))) | H11: =IF($A11="","",IF(COUNTIFS('Avaliação Semanal'!$B$5:$B$504,$A11,'Avaliação Semanal'!$A$5:$A$504,">="&$B$3,'Avaliação Semanal'!$A$5:$A$504,"<="&$D$3,'Avaliação Semanal'!$G$5:$G$504,">0")=0,"",ROUND(AVERAGEIFS('Avaliação Semanal'!$G$5:$G$504,'Avaliação Semanal'!$B$5:$B$504,$A11,'Avaliação Semanal'!$A$5:$A$504,">="&$B$3,'Avaliação Semanal'!$A$5:$A$504,"<="&$D$3),2))) | I11: =IF($A11="","",IF(COUNTIFS('Avaliação Semanal'!$B$5:$B$504,$A11,'Avaliação Semanal'!$A$5:$A$504,">="&$B$3,'Avaliação Semanal'!$A$5:$A$504,"<="&$D$3,'Avaliação Semanal'!$H$5:$H$504,">0")=0,"",ROUND(AVERAGEIFS('Avaliação Semanal'!$H$5:$H$504,'Avaliação Semanal'!$B$5:$B$504,$A11,'Avaliação Semanal'!$A$5:$A$504,">="&$B$3,'Avaliação Semanal'!$A$5:$A$504,"<="&$D$3),2))) | J11: =IF($A11="","",IF(COUNTIFS('Avaliação Semanal'!$B$5:$B$504,$A11,'Avaliação Semanal'!$A$5:$A$504,">="&$B$3,'Avaliação Semanal'!$A$5:$A$504,"<="&$D$3,'Avaliação Semanal'!$I$5:$I$504,">0")=0,"",ROUND(AVERAGEIFS('Avaliação Semanal'!$I$5:$I$504,'Avaliação Semanal'!$B$5:$B$504,$A11,'Avaliação Semanal'!$A$5:$A$504,">="&$B$3,'Avaliação Semanal'!$A$5:$A$504,"<="&$D$3),2))) | K11: =IF(COUNT($F11:$J11)=0,"",ROUND(AVERAGE($F11:$J11),2)) | L11: =IF($K11="","",IF($K11>=Cadastro!$H$5,"Verde",IF($K11>=Cadastro!$H$6,"Atenção","Crítico"))) | M11: =IF($A11="","",COUNTIFS('Avaliação Semanal'!$B$5:$B$504,$A11,'Avaliação Semanal'!$A$5:$A$504,">="&$B$3,'Avaliação Semanal'!$A$5:$A$504,"<="&$D$3,'Avaliação Semanal'!$J$5:$J$504,">0")) | N11: =IF($M11=0,"",_xlfn.MAXIFS('Avaliação Semanal'!$A$5:$A$504,'Avaliação Semanal'!$B$5:$B$504,$A11,'Avaliação Semanal'!$A$5:$A$504,"<="&$D$3)) | O11: =IF($A11="","",COUNTIFS('Ocorrências'!$B$5:$B$204,$A11,'Ocorrências'!$A$5:$A$204,">="&$B$3,'Ocorrências'!$A$5:$A$204,"<="&$D$3)) | P11: =IF($A11="","",COUNTIFS('Ocorrências'!$B$5:$B$204,$A11,'Ocorrências'!$C$5:$C$204,"Ponto de atenção",'Ocorrências'!$A$5:$A$204,">="&$B$3,'Ocorrências'!$A$5:$A$204,"<="&$D$3)+COUNTIFS('Ocorrências'!$B$5:$B$204,$A11,'Ocorrências'!$C$5:$C$204,"Crítica",'Ocorrências'!$A$5:$A$204,">="&$B$3,'Ocorrências'!$A$5:$A$204,"<="&$D$3)) | Q11: =IF($A11="","",IF(COUNTIFS('Avaliação Semanal'!$B$5:$B$504,$A11,'Avaliação Semanal'!$C$5:$C$504,"GP",'Avaliação Semanal'!$A$5:$A$504,">="&$B$3,'Avaliação Semanal'!$A$5:$A$504,"<="&$D$3)=0,"",IFERROR(INDEX('Avaliação Semanal'!$L$5:$L$504,MATCH($A11&"|GP|"&TEXT(_xlfn.MAXIFS('Avaliação Semanal'!$A$5:$A$504,'Avaliação Semanal'!$B$5:$B$504,$A11,'Avaliação Semanal'!$C$5:$C$504,"GP",'Avaliação Semanal'!$A$5:$A$504,"<="&$D$3),"00000"),'Avaliação Semanal'!$M$5:$M$504,0)),""))) | R11: =IF($A11="","",IF(COUNTIFS('Avaliação Semanal'!$B$5:$B$504,$A11,'Avaliação Semanal'!$C$5:$C$504,"Líder Técnico",'Avaliação Semanal'!$A$5:$A$504,">="&$B$3,'Avaliação Semanal'!$A$5:$A$504,"<="&$D$3)=0,"",IFERROR(INDEX('Avaliação Semanal'!$L$5:$L$504,MATCH($A11&"|Líder Técnico|"&TEXT(_xlfn.MAXIFS('Avaliação Semanal'!$A$5:$A$504,'Avaliação Semanal'!$B$5:$B$504,$A11,'Avaliação Semanal'!$C$5:$C$504,"Líder Técnico",'Avaliação Semanal'!$A$5:$A$504,"<="&$D$3),"00000"),'Avaliação Semanal'!$M$5:$M$504,0)),"")))
A12: =IF(Cadastro!$A11="","",Cadastro!$A11) | B12: =IF(Cadastro!$A11="","",Cadastro!$B11) | C12: =IF(Cadastro!$A11="","",Cadastro!$C11) | D12: =IF($A12="","",IF(COUNTIFS('Avaliação Semanal'!$B$5:$B$504,$A12,'Avaliação Semanal'!$C$5:$C$504,"GP",'Avaliação Semanal'!$A$5:$A$504,">="&$B$3,'Avaliação Semanal'!$A$5:$A$504,"<="&$D$3,'Avaliação Semanal'!$J$5:$J$504,">0")=0,"",ROUND(AVERAGEIFS('Avaliação Semanal'!$J$5:$J$504,'Avaliação Semanal'!$B$5:$B$504,$A12,'Avaliação Semanal'!$C$5:$C$504,"GP",'Avaliação Semanal'!$A$5:$A$504,">="&$B$3,'Avaliação Semanal'!$A$5:$A$504,"<="&$D$3),2))) | E12: =IF($A12="","",IF(COUNTIFS('Avaliação Semanal'!$B$5:$B$504,$A12,'Avaliação Semanal'!$C$5:$C$504,"Líder Técnico",'Avaliação Semanal'!$A$5:$A$504,">="&$B$3,'Avaliação Semanal'!$A$5:$A$504,"<="&$D$3,'Avaliação Semanal'!$J$5:$J$504,">0")=0,"",ROUND(AVERAGEIFS('Avaliação Semanal'!$J$5:$J$504,'Avaliação Semanal'!$B$5:$B$504,$A12,'Avaliação Semanal'!$C$5:$C$504,"Líder Técnico",'Avaliação Semanal'!$A$5:$A$504,">="&$B$3,'Avaliação Semanal'!$A$5:$A$504,"<="&$D$3),2))) | F12: =IF($A12="","",IF(COUNTIFS('Avaliação Semanal'!$B$5:$B$504,$A12,'Avaliação Semanal'!$A$5:$A$504,">="&$B$3,'Avaliação Semanal'!$A$5:$A$504,"<="&$D$3,'Avaliação Semanal'!$E$5:$E$504,">0")=0,"",ROUND(AVERAGEIFS('Avaliação Semanal'!$E$5:$E$504,'Avaliação Semanal'!$B$5:$B$504,$A12,'Avaliação Semanal'!$A$5:$A$504,">="&$B$3,'Avaliação Semanal'!$A$5:$A$504,"<="&$D$3),2))) | G12: =IF($A12="","",IF(COUNTIFS('Avaliação Semanal'!$B$5:$B$504,$A12,'Avaliação Semanal'!$A$5:$A$504,">="&$B$3,'Avaliação Semanal'!$A$5:$A$504,"<="&$D$3,'Avaliação Semanal'!$F$5:$F$504,">0")=0,"",ROUND(AVERAGEIFS('Avaliação Semanal'!$F$5:$F$504,'Avaliação Semanal'!$B$5:$B$504,$A12,'Avaliação Semanal'!$A$5:$A$504,">="&$B$3,'Avaliação Semanal'!$A$5:$A$504,"<="&$D$3),2))) | H12: =IF($A12="","",IF(COUNTIFS('Avaliação Semanal'!$B$5:$B$504,$A12,'Avaliação Semanal'!$A$5:$A$504,">="&$B$3,'Avaliação Semanal'!$A$5:$A$504,"<="&$D$3,'Avaliação Semanal'!$G$5:$G$504,">0")=0,"",ROUND(AVERAGEIFS('Avaliação Semanal'!$G$5:$G$504,'Avaliação Semanal'!$B$5:$B$504,$A12,'Avaliação Semanal'!$A$5:$A$504,">="&$B$3,'Avaliação Semanal'!$A$5:$A$504,"<="&$D$3),2))) | I12: =IF($A12="","",IF(COUNTIFS('Avaliação Semanal'!$B$5:$B$504,$A12,'Avaliação Semanal'!$A$5:$A$504,">="&$B$3,'Avaliação Semanal'!$A$5:$A$504,"<="&$D$3,'Avaliação Semanal'!$H$5:$H$504,">0")=0,"",ROUND(AVERAGEIFS('Avaliação Semanal'!$H$5:$H$504,'Avaliação Semanal'!$B$5:$B$504,$A12,'Avaliação Semanal'!$A$5:$A$504,">="&$B$3,'Avaliação Semanal'!$A$5:$A$504,"<="&$D$3),2))) | J12: =IF($A12="","",IF(COUNTIFS('Avaliação Semanal'!$B$5:$B$504,$A12,'Avaliação Semanal'!$A$5:$A$504,">="&$B$3,'Avaliação Semanal'!$A$5:$A$504,"<="&$D$3,'Avaliação Semanal'!$I$5:$I$504,">0")=0,"",ROUND(AVERAGEIFS('Avaliação Semanal'!$I$5:$I$504,'Avaliação Semanal'!$B$5:$B$504,$A12,'Avaliação Semanal'!$A$5:$A$504,">="&$B$3,'Avaliação Semanal'!$A$5:$A$504,"<="&$D$3),2))) | K12: =IF(COUNT($F12:$J12)=0,"",ROUND(AVERAGE($F12:$J12),2)) | L12: =IF($K12="","",IF($K12>=Cadastro!$H$5,"Verde",IF($K12>=Cadastro!$H$6,"Atenção","Crítico"))) | M12: =IF($A12="","",COUNTIFS('Avaliação Semanal'!$B$5:$B$504,$A12,'Avaliação Semanal'!$A$5:$A$504,">="&$B$3,'Avaliação Semanal'!$A$5:$A$504,"<="&$D$3,'Avaliação Semanal'!$J$5:$J$504,">0")) | N12: =IF($M12=0,"",_xlfn.MAXIFS('Avaliação Semanal'!$A$5:$A$504,'Avaliação Semanal'!$B$5:$B$504,$A12,'Avaliação Semanal'!$A$5:$A$504,"<="&$D$3)) | O12: =IF($A12="","",COUNTIFS('Ocorrências'!$B$5:$B$204,$A12,'Ocorrências'!$A$5:$A$204,">="&$B$3,'Ocorrências'!$A$5:$A$204,"<="&$D$3)) | P12: =IF($A12="","",COUNTIFS('Ocorrências'!$B$5:$B$204,$A12,'Ocorrências'!$C$5:$C$204,"Ponto de atenção",'Ocorrências'!$A$5:$A$204,">="&$B$3,'Ocorrências'!$A$5:$A$204,"<="&$D$3)+COUNTIFS('Ocorrências'!$B$5:$B$204,$A12,'Ocorrências'!$C$5:$C$204,"Crítica",'Ocorrências'!$A$5:$A$204,">="&$B$3,'Ocorrências'!$A$5:$A$204,"<="&$D$3)) | Q12: =IF($A12="","",IF(COUNTIFS('Avaliação Semanal'!$B$5:$B$504,$A12,'Avaliação Semanal'!$C$5:$C$504,"GP",'Avaliação Semanal'!$A$5:$A$504,">="&$B$3,'Avaliação Semanal'!$A$5:$A$504,"<="&$D$3)=0,"",IFERROR(INDEX('Avaliação Semanal'!$L$5:$L$504,MATCH($A12&"|GP|"&TEXT(_xlfn.MAXIFS('Avaliação Semanal'!$A$5:$A$504,'Avaliação Semanal'!$B$5:$B$504,$A12,'Avaliação Semanal'!$C$5:$C$504,"GP",'Avaliação Semanal'!$A$5:$A$504,"<="&$D$3),"00000"),'Avaliação Semanal'!$M$5:$M$504,0)),""))) | R12: =IF($A12="","",IF(COUNTIFS('Avaliação Semanal'!$B$5:$B$504,$A12,'Avaliação Semanal'!$C$5:$C$504,"Líder Técnico",'Avaliação Semanal'!$A$5:$A$504,">="&$B$3,'Avaliação Semanal'!$A$5:$A$504,"<="&$D$3)=0,"",IFERROR(INDEX('Avaliação Semanal'!$L$5:$L$504,MATCH($A12&"|Líder Técnico|"&TEXT(_xlfn.MAXIFS('Avaliação Semanal'!$A$5:$A$504,'Avaliação Semanal'!$B$5:$B$504,$A12,'Avaliação Semanal'!$C$5:$C$504,"Líder Técnico",'Avaliação Semanal'!$A$5:$A$504,"<="&$D$3),"00000"),'Avaliação Semanal'!$M$5:$M$504,0)),"")))
A13: =IF(Cadastro!$A12="","",Cadastro!$A12) | B13: =IF(Cadastro!$A12="","",Cadastro!$B12) | C13: =IF(Cadastro!$A12="","",Cadastro!$C12) | D13: =IF($A13="","",IF(COUNTIFS('Avaliação Semanal'!$B$5:$B$504,$A13,'Avaliação Semanal'!$C$5:$C$504,"GP",'Avaliação Semanal'!$A$5:$A$504,">="&$B$3,'Avaliação Semanal'!$A$5:$A$504,"<="&$D$3,'Avaliação Semanal'!$J$5:$J$504,">0")=0,"",ROUND(AVERAGEIFS('Avaliação Semanal'!$J$5:$J$504,'Avaliação Semanal'!$B$5:$B$504,$A13,'Avaliação Semanal'!$C$5:$C$504,"GP",'Avaliação Semanal'!$A$5:$A$504,">="&$B$3,'Avaliação Semanal'!$A$5:$A$504,"<="&$D$3),2))) | E13: =IF($A13="","",IF(COUNTIFS('Avaliação Semanal'!$B$5:$B$504,$A13,'Avaliação Semanal'!$C$5:$C$504,"Líder Técnico",'Avaliação Semanal'!$A$5:$A$504,">="&$B$3,'Avaliação Semanal'!$A$5:$A$504,"<="&$D$3,'Avaliação Semanal'!$J$5:$J$504,">0")=0,"",ROUND(AVERAGEIFS('Avaliação Semanal'!$J$5:$J$504,'Avaliação Semanal'!$B$5:$B$504,$A13,'Avaliação Semanal'!$C$5:$C$504,"Líder Técnico",'Avaliação Semanal'!$A$5:$A$504,">="&$B$3,'Avaliação Semanal'!$A$5:$A$504,"<="&$D$3),2))) | F13: =IF($A13="","",IF(COUNTIFS('Avaliação Semanal'!$B$5:$B$504,$A13,'Avaliação Semanal'!$A$5:$A$504,">="&$B$3,'Avaliação Semanal'!$A$5:$A$504,"<="&$D$3,'Avaliação Semanal'!$E$5:$E$504,">0")=0,"",ROUND(AVERAGEIFS('Avaliação Semanal'!$E$5:$E$504,'Avaliação Semanal'!$B$5:$B$504,$A13,'Avaliação Semanal'!$A$5:$A$504,">="&$B$3,'Avaliação Semanal'!$A$5:$A$504,"<="&$D$3),2))) | G13: =IF($A13="","",IF(COUNTIFS('Avaliação Semanal'!$B$5:$B$504,$A13,'Avaliação Semanal'!$A$5:$A$504,">="&$B$3,'Avaliação Semanal'!$A$5:$A$504,"<="&$D$3,'Avaliação Semanal'!$F$5:$F$504,">0")=0,"",ROUND(AVERAGEIFS('Avaliação Semanal'!$F$5:$F$504,'Avaliação Semanal'!$B$5:$B$504,$A13,'Avaliação Semanal'!$A$5:$A$504,">="&$B$3,'Avaliação Semanal'!$A$5:$A$504,"<="&$D$3),2))) | H13: =IF($A13="","",IF(COUNTIFS('Avaliação Semanal'!$B$5:$B$504,$A13,'Avaliação Semanal'!$A$5:$A$504,">="&$B$3,'Avaliação Semanal'!$A$5:$A$504,"<="&$D$3,'Avaliação Semanal'!$G$5:$G$504,">0")=0,"",ROUND(AVERAGEIFS('Avaliação Semanal'!$G$5:$G$504,'Avaliação Semanal'!$B$5:$B$504,$A13,'Avaliação Semanal'!$A$5:$A$504,">="&$B$3,'Avaliação Semanal'!$A$5:$A$504,"<="&$D$3),2))) | I13: =IF($A13="","",IF(COUNTIFS('Avaliação Semanal'!$B$5:$B$504,$A13,'Avaliação Semanal'!$A$5:$A$504,">="&$B$3,'Avaliação Semanal'!$A$5:$A$504,"<="&$D$3,'Avaliação Semanal'!$H$5:$H$504,">0")=0,"",ROUND(AVERAGEIFS('Avaliação Semanal'!$H$5:$H$504,'Avaliação Semanal'!$B$5:$B$504,$A13,'Avaliação Semanal'!$A$5:$A$504,">="&$B$3,'Avaliação Semanal'!$A$5:$A$504,"<="&$D$3),2))) | J13: =IF($A13="","",IF(COUNTIFS('Avaliação Semanal'!$B$5:$B$504,$A13,'Avaliação Semanal'!$A$5:$A$504,">="&$B$3,'Avaliação Semanal'!$A$5:$A$504,"<="&$D$3,'Avaliação Semanal'!$I$5:$I$504,">0")=0,"",ROUND(AVERAGEIFS('Avaliação Semanal'!$I$5:$I$504,'Avaliação Semanal'!$B$5:$B$504,$A13,'Avaliação Semanal'!$A$5:$A$504,">="&$B$3,'Avaliação Semanal'!$A$5:$A$504,"<="&$D$3),2))) | K13: =IF(COUNT($F13:$J13)=0,"",ROUND(AVERAGE($F13:$J13),2)) | L13: =IF($K13="","",IF($K13>=Cadastro!$H$5,"Verde",IF($K13>=Cadastro!$H$6,"Atenção","Crítico"))) | M13: =IF($A13="","",COUNTIFS('Avaliação Semanal'!$B$5:$B$504,$A13,'Avaliação Semanal'!$A$5:$A$504,">="&$B$3,'Avaliação Semanal'!$A$5:$A$504,"<="&$D$3,'Avaliação Semanal'!$J$5:$J$504,">0")) | N13: =IF($M13=0,"",_xlfn.MAXIFS('Avaliação Semanal'!$A$5:$A$504,'Avaliação Semanal'!$B$5:$B$504,$A13,'Avaliação Semanal'!$A$5:$A$504,"<="&$D$3)) | O13: =IF($A13="","",COUNTIFS('Ocorrências'!$B$5:$B$204,$A13,'Ocorrências'!$A$5:$A$204,">="&$B$3,'Ocorrências'!$A$5:$A$204,"<="&$D$3)) | P13: =IF($A13="","",COUNTIFS('Ocorrências'!$B$5:$B$204,$A13,'Ocorrências'!$C$5:$C$204,"Ponto de atenção",'Ocorrências'!$A$5:$A$204,">="&$B$3,'Ocorrências'!$A$5:$A$204,"<="&$D$3)+COUNTIFS('Ocorrências'!$B$5:$B$204,$A13,'Ocorrências'!$C$5:$C$204,"Crítica",'Ocorrências'!$A$5:$A$204,">="&$B$3,'Ocorrências'!$A$5:$A$204,"<="&$D$3)) | Q13: =IF($A13="","",IF(COUNTIFS('Avaliação Semanal'!$B$5:$B$504,$A13,'Avaliação Semanal'!$C$5:$C$504,"GP",'Avaliação Semanal'!$A$5:$A$504,">="&$B$3,'Avaliação Semanal'!$A$5:$A$504,"<="&$D$3)=0,"",IFERROR(INDEX('Avaliação Semanal'!$L$5:$L$504,MATCH($A13&"|GP|"&TEXT(_xlfn.MAXIFS('Avaliação Semanal'!$A$5:$A$504,'Avaliação Semanal'!$B$5:$B$504,$A13,'Avaliação Semanal'!$C$5:$C$504,"GP",'Avaliação Semanal'!$A$5:$A$504,"<="&$D$3),"00000"),'Avaliação Semanal'!$M$5:$M$504,0)),""))) | R13: =IF($A13="","",IF(COUNTIFS('Avaliação Semanal'!$B$5:$B$504,$A13,'Avaliação Semanal'!$C$5:$C$504,"Líder Técnico",'Avaliação Semanal'!$A$5:$A$504,">="&$B$3,'Avaliação Semanal'!$A$5:$A$504,"<="&$D$3)=0,"",IFERROR(INDEX('Avaliação Semanal'!$L$5:$L$504,MATCH($A13&"|Líder Técnico|"&TEXT(_xlfn.MAXIFS('Avaliação Semanal'!$A$5:$A$504,'Avaliação Semanal'!$B$5:$B$504,$A13,'Avaliação Semanal'!$C$5:$C$504,"Líder Técnico",'Avaliação Semanal'!$A$5:$A$504,"<="&$D$3),"00000"),'Avaliação Semanal'!$M$5:$M$504,0)),"")))
A14: =IF(Cadastro!$A13="","",Cadastro!$A13) | B14: =IF(Cadastro!$A13="","",Cadastro!$B13) | C14: =IF(Cadastro!$A13="","",Cadastro!$C13) | D14: =IF($A14="","",IF(COUNTIFS('Avaliação Semanal'!$B$5:$B$504,$A14,'Avaliação Semanal'!$C$5:$C$504,"GP",'Avaliação Semanal'!$A$5:$A$504,">="&$B$3,'Avaliação Semanal'!$A$5:$A$504,"<="&$D$3,'Avaliação Semanal'!$J$5:$J$504,">0")=0,"",ROUND(AVERAGEIFS('Avaliação Semanal'!$J$5:$J$504,'Avaliação Semanal'!$B$5:$B$504,$A14,'Avaliação Semanal'!$C$5:$C$504,"GP",'Avaliação Semanal'!$A$5:$A$504,">="&$B$3,'Avaliação Semanal'!$A$5:$A$504,"<="&$D$3),2))) | E14: =IF($A14="","",IF(COUNTIFS('Avaliação Semanal'!$B$5:$B$504,$A14,'Avaliação Semanal'!$C$5:$C$504,"Líder Técnico",'Avaliação Semanal'!$A$5:$A$504,">="&$B$3,'Avaliação Semanal'!$A$5:$A$504,"<="&$D$3,'Avaliação Semanal'!$J$5:$J$504,">0")=0,"",ROUND(AVERAGEIFS('Avaliação Semanal'!$J$5:$J$504,'Avaliação Semanal'!$B$5:$B$504,$A14,'Avaliação Semanal'!$C$5:$C$504,"Líder Técnico",'Avaliação Semanal'!$A$5:$A$504,">="&$B$3,'Avaliação Semanal'!$A$5:$A$504,"<="&$D$3),2))) | F14: =IF($A14="","",IF(COUNTIFS('Avaliação Semanal'!$B$5:$B$504,$A14,'Avaliação Semanal'!$A$5:$A$504,">="&$B$3,'Avaliação Semanal'!$A$5:$A$504,"<="&$D$3,'Avaliação Semanal'!$E$5:$E$504,">0")=0,"",ROUND(AVERAGEIFS('Avaliação Semanal'!$E$5:$E$504,'Avaliação Semanal'!$B$5:$B$504,$A14,'Avaliação Semanal'!$A$5:$A$504,">="&$B$3,'Avaliação Semanal'!$A$5:$A$504,"<="&$D$3),2))) | G14: =IF($A14="","",IF(COUNTIFS('Avaliação Semanal'!$B$5:$B$504,$A14,'Avaliação Semanal'!$A$5:$A$504,">="&$B$3,'Avaliação Semanal'!$A$5:$A$504,"<="&$D$3,'Avaliação Semanal'!$F$5:$F$504,">0")=0,"",ROUND(AVERAGEIFS('Avaliação Semanal'!$F$5:$F$504,'Avaliação Semanal'!$B$5:$B$504,$A14,'Avaliação Semanal'!$A$5:$A$504,">="&$B$3,'Avaliação Semanal'!$A$5:$A$504,"<="&$D$3),2))) | H14: =IF($A14="","",IF(COUNTIFS('Avaliação Semanal'!$B$5:$B$504,$A14,'Avaliação Semanal'!$A$5:$A$504,">="&$B$3,'Avaliação Semanal'!$A$5:$A$504,"<="&$D$3,'Avaliação Semanal'!$G$5:$G$504,">0")=0,"",ROUND(AVERAGEIFS('Avaliação Semanal'!$G$5:$G$504,'Avaliação Semanal'!$B$5:$B$504,$A14,'Avaliação Semanal'!$A$5:$A$504,">="&$B$3,'Avaliação Semanal'!$A$5:$A$504,"<="&$D$3),2))) | I14: =IF($A14="","",IF(COUNTIFS('Avaliação Semanal'!$B$5:$B$504,$A14,'Avaliação Semanal'!$A$5:$A$504,">="&$B$3,'Avaliação Semanal'!$A$5:$A$504,"<="&$D$3,'Avaliação Semanal'!$H$5:$H$504,">0")=0,"",ROUND(AVERAGEIFS('Avaliação Semanal'!$H$5:$H$504,'Avaliação Semanal'!$B$5:$B$504,$A14,'Avaliação Semanal'!$A$5:$A$504,">="&$B$3,'Avaliação Semanal'!$A$5:$A$504,"<="&$D$3),2))) | J14: =IF($A14="","",IF(COUNTIFS('Avaliação Semanal'!$B$5:$B$504,$A14,'Avaliação Semanal'!$A$5:$A$504,">="&$B$3,'Avaliação Semanal'!$A$5:$A$504,"<="&$D$3,'Avaliação Semanal'!$I$5:$I$504,">0")=0,"",ROUND(AVERAGEIFS('Avaliação Semanal'!$I$5:$I$504,'Avaliação Semanal'!$B$5:$B$504,$A14,'Avaliação Semanal'!$A$5:$A$504,">="&$B$3,'Avaliação Semanal'!$A$5:$A$504,"<="&$D$3),2))) | K14: =IF(COUNT($F14:$J14)=0,"",ROUND(AVERAGE($F14:$J14),2)) | L14: =IF($K14="","",IF($K14>=Cadastro!$H$5,"Verde",IF($K14>=Cadastro!$H$6,"Atenção","Crítico"))) | M14: =IF($A14="","",COUNTIFS('Avaliação Semanal'!$B$5:$B$504,$A14,'Avaliação Semanal'!$A$5:$A$504,">="&$B$3,'Avaliação Semanal'!$A$5:$A$504,"<="&$D$3,'Avaliação Semanal'!$J$5:$J$504,">0")) | N14: =IF($M14=0,"",_xlfn.MAXIFS('Avaliação Semanal'!$A$5:$A$504,'Avaliação Semanal'!$B$5:$B$504,$A14,'Avaliação Semanal'!$A$5:$A$504,"<="&$D$3)) | O14: =IF($A14="","",COUNTIFS('Ocorrências'!$B$5:$B$204,$A14,'Ocorrências'!$A$5:$A$204,">="&$B$3,'Ocorrências'!$A$5:$A$204,"<="&$D$3)) | P14: =IF($A14="","",COUNTIFS('Ocorrências'!$B$5:$B$204,$A14,'Ocorrências'!$C$5:$C$204,"Ponto de atenção",'Ocorrências'!$A$5:$A$204,">="&$B$3,'Ocorrências'!$A$5:$A$204,"<="&$D$3)+COUNTIFS('Ocorrências'!$B$5:$B$204,$A14,'Ocorrências'!$C$5:$C$204,"Crítica",'Ocorrências'!$A$5:$A$204,">="&$B$3,'Ocorrências'!$A$5:$A$204,"<="&$D$3)) | Q14: =IF($A14="","",IF(COUNTIFS('Avaliação Semanal'!$B$5:$B$504,$A14,'Avaliação Semanal'!$C$5:$C$504,"GP",'Avaliação Semanal'!$A$5:$A$504,">="&$B$3,'Avaliação Semanal'!$A$5:$A$504,"<="&$D$3)=0,"",IFERROR(INDEX('Avaliação Semanal'!$L$5:$L$504,MATCH($A14&"|GP|"&TEXT(_xlfn.MAXIFS('Avaliação Semanal'!$A$5:$A$504,'Avaliação Semanal'!$B$5:$B$504,$A14,'Avaliação Semanal'!$C$5:$C$504,"GP",'Avaliação Semanal'!$A$5:$A$504,"<="&$D$3),"00000"),'Avaliação Semanal'!$M$5:$M$504,0)),""))) | R14: =IF($A14="","",IF(COUNTIFS('Avaliação Semanal'!$B$5:$B$504,$A14,'Avaliação Semanal'!$C$5:$C$504,"Líder Técnico",'Avaliação Semanal'!$A$5:$A$504,">="&$B$3,'Avaliação Semanal'!$A$5:$A$504,"<="&$D$3)=0,"",IFERROR(INDEX('Avaliação Semanal'!$L$5:$L$504,MATCH($A14&"|Líder Técnico|"&TEXT(_xlfn.MAXIFS('Avaliação Semanal'!$A$5:$A$504,'Avaliação Semanal'!$B$5:$B$504,$A14,'Avaliação Semanal'!$C$5:$C$504,"Líder Técnico",'Avaliação Semanal'!$A$5:$A$504,"<="&$D$3),"00000"),'Avaliação Semanal'!$M$5:$M$504,0)),"")))
A15: =IF(Cadastro!$A14="","",Cadastro!$A14) | B15: =IF(Cadastro!$A14="","",Cadastro!$B14) | C15: =IF(Cadastro!$A14="","",Cadastro!$C14) | D15: =IF($A15="","",IF(COUNTIFS('Avaliação Semanal'!$B$5:$B$504,$A15,'Avaliação Semanal'!$C$5:$C$504,"GP",'Avaliação Semanal'!$A$5:$A$504,">="&$B$3,'Avaliação Semanal'!$A$5:$A$504,"<="&$D$3,'Avaliação Semanal'!$J$5:$J$504,">0")=0,"",ROUND(AVERAGEIFS('Avaliação Semanal'!$J$5:$J$504,'Avaliação Semanal'!$B$5:$B$504,$A15,'Avaliação Semanal'!$C$5:$C$504,"GP",'Avaliação Semanal'!$A$5:$A$504,">="&$B$3,'Avaliação Semanal'!$A$5:$A$504,"<="&$D$3),2))) | E15: =IF($A15="","",IF(COUNTIFS('Avaliação Semanal'!$B$5:$B$504,$A15,'Avaliação Semanal'!$C$5:$C$504,"Líder Técnico",'Avaliação Semanal'!$A$5:$A$504,">="&$B$3,'Avaliação Semanal'!$A$5:$A$504,"<="&$D$3,'Avaliação Semanal'!$J$5:$J$504,">0")=0,"",ROUND(AVERAGEIFS('Avaliação Semanal'!$J$5:$J$504,'Avaliação Semanal'!$B$5:$B$504,$A15,'Avaliação Semanal'!$C$5:$C$504,"Líder Técnico",'Avaliação Semanal'!$A$5:$A$504,">="&$B$3,'Avaliação Semanal'!$A$5:$A$504,"<="&$D$3),2))) | F15: =IF($A15="","",IF(COUNTIFS('Avaliação Semanal'!$B$5:$B$504,$A15,'Avaliação Semanal'!$A$5:$A$504,">="&$B$3,'Avaliação Semanal'!$A$5:$A$504,"<="&$D$3,'Avaliação Semanal'!$E$5:$E$504,">0")=0,"",ROUND(AVERAGEIFS('Avaliação Semanal'!$E$5:$E$504,'Avaliação Semanal'!$B$5:$B$504,$A15,'Avaliação Semanal'!$A$5:$A$504,">="&$B$3,'Avaliação Semanal'!$A$5:$A$504,"<="&$D$3),2))) | G15: =IF($A15="","",IF(COUNTIFS('Avaliação Semanal'!$B$5:$B$504,$A15,'Avaliação Semanal'!$A$5:$A$504,">="&$B$3,'Avaliação Semanal'!$A$5:$A$504,"<="&$D$3,'Avaliação Semanal'!$F$5:$F$504,">0")=0,"",ROUND(AVERAGEIFS('Avaliação Semanal'!$F$5:$F$504,'Avaliação Semanal'!$B$5:$B$504,$A15,'Avaliação Semanal'!$A$5:$A$504,">="&$B$3,'Avaliação Semanal'!$A$5:$A$504,"<="&$D$3),2))) | H15: =IF($A15="","",IF(COUNTIFS('Avaliação Semanal'!$B$5:$B$504,$A15,'Avaliação Semanal'!$A$5:$A$504,">="&$B$3,'Avaliação Semanal'!$A$5:$A$504,"<="&$D$3,'Avaliação Semanal'!$G$5:$G$504,">0")=0,"",ROUND(AVERAGEIFS('Avaliação Semanal'!$G$5:$G$504,'Avaliação Semanal'!$B$5:$B$504,$A15,'Avaliação Semanal'!$A$5:$A$504,">="&$B$3,'Avaliação Semanal'!$A$5:$A$504,"<="&$D$3),2))) | I15: =IF($A15="","",IF(COUNTIFS('Avaliação Semanal'!$B$5:$B$504,$A15,'Avaliação Semanal'!$A$5:$A$504,">="&$B$3,'Avaliação Semanal'!$A$5:$A$504,"<="&$D$3,'Avaliação Semanal'!$H$5:$H$504,">0")=0,"",ROUND(AVERAGEIFS('Avaliação Semanal'!$H$5:$H$504,'Avaliação Semanal'!$B$5:$B$504,$A15,'Avaliação Semanal'!$A$5:$A$504,">="&$B$3,'Avaliação Semanal'!$A$5:$A$504,"<="&$D$3),2))) | J15: =IF($A15="","",IF(COUNTIFS('Avaliação Semanal'!$B$5:$B$504,$A15,'Avaliação Semanal'!$A$5:$A$504,">="&$B$3,'Avaliação Semanal'!$A$5:$A$504,"<="&$D$3,'Avaliação Semanal'!$I$5:$I$504,">0")=0,"",ROUND(AVERAGEIFS('Avaliação Semanal'!$I$5:$I$504,'Avaliação Semanal'!$B$5:$B$504,$A15,'Avaliação Semanal'!$A$5:$A$504,">="&$B$3,'Avaliação Semanal'!$A$5:$A$504,"<="&$D$3),2))) | K15: =IF(COUNT($F15:$J15)=0,"",ROUND(AVERAGE($F15:$J15),2)) | L15: =IF($K15="","",IF($K15>=Cadastro!$H$5,"Verde",IF($K15>=Cadastro!$H$6,"Atenção","Crítico"))) | M15: =IF($A15="","",COUNTIFS('Avaliação Semanal'!$B$5:$B$504,$A15,'Avaliação Semanal'!$A$5:$A$504,">="&$B$3,'Avaliação Semanal'!$A$5:$A$504,"<="&$D$3,'Avaliação Semanal'!$J$5:$J$504,">0")) | N15: =IF($M15=0,"",_xlfn.MAXIFS('Avaliação Semanal'!$A$5:$A$504,'Avaliação Semanal'!$B$5:$B$504,$A15,'Avaliação Semanal'!$A$5:$A$504,"<="&$D$3)) | O15: =IF($A15="","",COUNTIFS('Ocorrências'!$B$5:$B$204,$A15,'Ocorrências'!$A$5:$A$204,">="&$B$3,'Ocorrências'!$A$5:$A$204,"<="&$D$3)) | P15: =IF($A15="","",COUNTIFS('Ocorrências'!$B$5:$B$204,$A15,'Ocorrências'!$C$5:$C$204,"Ponto de atenção",'Ocorrências'!$A$5:$A$204,">="&$B$3,'Ocorrências'!$A$5:$A$204,"<="&$D$3)+COUNTIFS('Ocorrências'!$B$5:$B$204,$A15,'Ocorrências'!$C$5:$C$204,"Crítica",'Ocorrências'!$A$5:$A$204,">="&$B$3,'Ocorrências'!$A$5:$A$204,"<="&$D$3)) | Q15: =IF($A15="","",IF(COUNTIFS('Avaliação Semanal'!$B$5:$B$504,$A15,'Avaliação Semanal'!$C$5:$C$504,"GP",'Avaliação Semanal'!$A$5:$A$504,">="&$B$3,'Avaliação Semanal'!$A$5:$A$504,"<="&$D$3)=0,"",IFERROR(INDEX('Avaliação Semanal'!$L$5:$L$504,MATCH($A15&"|GP|"&TEXT(_xlfn.MAXIFS('Avaliação Semanal'!$A$5:$A$504,'Avaliação Semanal'!$B$5:$B$504,$A15,'Avaliação Semanal'!$C$5:$C$504,"GP",'Avaliação Semanal'!$A$5:$A$504,"<="&$D$3),"00000"),'Avaliação Semanal'!$M$5:$M$504,0)),""))) | R15: =IF($A15="","",IF(COUNTIFS('Avaliação Semanal'!$B$5:$B$504,$A15,'Avaliação Semanal'!$C$5:$C$504,"Líder Técnico",'Avaliação Semanal'!$A$5:$A$504,">="&$B$3,'Avaliação Semanal'!$A$5:$A$504,"<="&$D$3)=0,"",IFERROR(INDEX('Avaliação Semanal'!$L$5:$L$504,MATCH($A15&"|Líder Técnico|"&TEXT(_xlfn.MAXIFS('Avaliação Semanal'!$A$5:$A$504,'Avaliação Semanal'!$B$5:$B$504,$A15,'Avaliação Semanal'!$C$5:$C$504,"Líder Técnico",'Avaliação Semanal'!$A$5:$A$504,"<="&$D$3),"00000"),'Avaliação Semanal'!$M$5:$M$504,0)),"")))
A16: =IF(Cadastro!$A15="","",Cadastro!$A15) | B16: =IF(Cadastro!$A15="","",Cadastro!$B15) | C16: =IF(Cadastro!$A15="","",Cadastro!$C15) | D16: =IF($A16="","",IF(COUNTIFS('Avaliação Semanal'!$B$5:$B$504,$A16,'Avaliação Semanal'!$C$5:$C$504,"GP",'Avaliação Semanal'!$A$5:$A$504,">="&$B$3,'Avaliação Semanal'!$A$5:$A$504,"<="&$D$3,'Avaliação Semanal'!$J$5:$J$504,">0")=0,"",ROUND(AVERAGEIFS('Avaliação Semanal'!$J$5:$J$504,'Avaliação Semanal'!$B$5:$B$504,$A16,'Avaliação Semanal'!$C$5:$C$504,"GP",'Avaliação Semanal'!$A$5:$A$504,">="&$B$3,'Avaliação Semanal'!$A$5:$A$504,"<="&$D$3),2))) | E16: =IF($A16="","",IF(COUNTIFS('Avaliação Semanal'!$B$5:$B$504,$A16,'Avaliação Semanal'!$C$5:$C$504,"Líder Técnico",'Avaliação Semanal'!$A$5:$A$504,">="&$B$3,'Avaliação Semanal'!$A$5:$A$504,"<="&$D$3,'Avaliação Semanal'!$J$5:$J$504,">0")=0,"",ROUND(AVERAGEIFS('Avaliação Semanal'!$J$5:$J$504,'Avaliação Semanal'!$B$5:$B$504,$A16,'Avaliação Semanal'!$C$5:$C$504,"Líder Técnico",'Avaliação Semanal'!$A$5:$A$504,">="&$B$3,'Avaliação Semanal'!$A$5:$A$504,"<="&$D$3),2))) | F16: =IF($A16="","",IF(COUNTIFS('Avaliação Semanal'!$B$5:$B$504,$A16,'Avaliação Semanal'!$A$5:$A$504,">="&$B$3,'Avaliação Semanal'!$A$5:$A$504,"<="&$D$3,'Avaliação Semanal'!$E$5:$E$504,">0")=0,"",ROUND(AVERAGEIFS('Avaliação Semanal'!$E$5:$E$504,'Avaliação Semanal'!$B$5:$B$504,$A16,'Avaliação Semanal'!$A$5:$A$504,">="&$B$3,'Avaliação Semanal'!$A$5:$A$504,"<="&$D$3),2))) | G16: =IF($A16="","",IF(COUNTIFS('Avaliação Semanal'!$B$5:$B$504,$A16,'Avaliação Semanal'!$A$5:$A$504,">="&$B$3,'Avaliação Semanal'!$A$5:$A$504,"<="&$D$3,'Avaliação Semanal'!$F$5:$F$504,">0")=0,"",ROUND(AVERAGEIFS('Avaliação Semanal'!$F$5:$F$504,'Avaliação Semanal'!$B$5:$B$504,$A16,'Avaliação Semanal'!$A$5:$A$504,">="&$B$3,'Avaliação Semanal'!$A$5:$A$504,"<="&$D$3),2))) | H16: =IF($A16="","",IF(COUNTIFS('Avaliação Semanal'!$B$5:$B$504,$A16,'Avaliação Semanal'!$A$5:$A$504,">="&$B$3,'Avaliação Semanal'!$A$5:$A$504,"<="&$D$3,'Avaliação Semanal'!$G$5:$G$504,">0")=0,"",ROUND(AVERAGEIFS('Avaliação Semanal'!$G$5:$G$504,'Avaliação Semanal'!$B$5:$B$504,$A16,'Avaliação Semanal'!$A$5:$A$504,">="&$B$3,'Avaliação Semanal'!$A$5:$A$504,"<="&$D$3),2))) | I16: =IF($A16="","",IF(COUNTIFS('Avaliação Semanal'!$B$5:$B$504,$A16,'Avaliação Semanal'!$A$5:$A$504,">="&$B$3,'Avaliação Semanal'!$A$5:$A$504,"<="&$D$3,'Avaliação Semanal'!$H$5:$H$504,">0")=0,"",ROUND(AVERAGEIFS('Avaliação Semanal'!$H$5:$H$504,'Avaliação Semanal'!$B$5:$B$504,$A16,'Avaliação Semanal'!$A$5:$A$504,">="&$B$3,'Avaliação Semanal'!$A$5:$A$504,"<="&$D$3),2))) | J16: =IF($A16="","",IF(COUNTIFS('Avaliação Semanal'!$B$5:$B$504,$A16,'Avaliação Semanal'!$A$5:$A$504,">="&$B$3,'Avaliação Semanal'!$A$5:$A$504,"<="&$D$3,'Avaliação Semanal'!$I$5:$I$504,">0")=0,"",ROUND(AVERAGEIFS('Avaliação Semanal'!$I$5:$I$504,'Avaliação Semanal'!$B$5:$B$504,$A16,'Avaliação Semanal'!$A$5:$A$504,">="&$B$3,'Avaliação Semanal'!$A$5:$A$504,"<="&$D$3),2))) | K16: =IF(COUNT($F16:$J16)=0,"",ROUND(AVERAGE($F16:$J16),2)) | L16: =IF($K16="","",IF($K16>=Cadastro!$H$5,"Verde",IF($K16>=Cadastro!$H$6,"Atenção","Crítico"))) | M16: =IF($A16="","",COUNTIFS('Avaliação Semanal'!$B$5:$B$504,$A16,'Avaliação Semanal'!$A$5:$A$504,">="&$B$3,'Avaliação Semanal'!$A$5:$A$504,"<="&$D$3,'Avaliação Semanal'!$J$5:$J$504,">0")) | N16: =IF($M16=0,"",_xlfn.MAXIFS('Avaliação Semanal'!$A$5:$A$504,'Avaliação Semanal'!$B$5:$B$504,$A16,'Avaliação Semanal'!$A$5:$A$504,"<="&$D$3)) | O16: =IF($A16="","",COUNTIFS('Ocorrências'!$B$5:$B$204,$A16,'Ocorrências'!$A$5:$A$204,">="&$B$3,'Ocorrências'!$A$5:$A$204,"<="&$D$3)) | P16: =IF($A16="","",COUNTIFS('Ocorrências'!$B$5:$B$204,$A16,'Ocorrências'!$C$5:$C$204,"Ponto de atenção",'Ocorrências'!$A$5:$A$204,">="&$B$3,'Ocorrências'!$A$5:$A$204,"<="&$D$3)+COUNTIFS('Ocorrências'!$B$5:$B$204,$A16,'Ocorrências'!$C$5:$C$204,"Crítica",'Ocorrências'!$A$5:$A$204,">="&$B$3,'Ocorrências'!$A$5:$A$204,"<="&$D$3)) | Q16: =IF($A16="","",IF(COUNTIFS('Avaliação Semanal'!$B$5:$B$504,$A16,'Avaliação Semanal'!$C$5:$C$504,"GP",'Avaliação Semanal'!$A$5:$A$504,">="&$B$3,'Avaliação Semanal'!$A$5:$A$504,"<="&$D$3)=0,"",IFERROR(INDEX('Avaliação Semanal'!$L$5:$L$504,MATCH($A16&"|GP|"&TEXT(_xlfn.MAXIFS('Avaliação Semanal'!$A$5:$A$504,'Avaliação Semanal'!$B$5:$B$504,$A16,'Avaliação Semanal'!$C$5:$C$504,"GP",'Avaliação Semanal'!$A$5:$A$504,"<="&$D$3),"00000"),'Avaliação Semanal'!$M$5:$M$504,0)),""))) | R16: =IF($A16="","",IF(COUNTIFS('Avaliação Semanal'!$B$5:$B$504,$A16,'Avaliação Semanal'!$C$5:$C$504,"Líder Técnico",'Avaliação Semanal'!$A$5:$A$504,">="&$B$3,'Avaliação Semanal'!$A$5:$A$504,"<="&$D$3)=0,"",IFERROR(INDEX('Avaliação Semanal'!$L$5:$L$504,MATCH($A16&"|Líder Técnico|"&TEXT(_xlfn.MAXIFS('Avaliação Semanal'!$A$5:$A$504,'Avaliação Semanal'!$B$5:$B$504,$A16,'Avaliação Semanal'!$C$5:$C$504,"Líder Técnico",'Avaliação Semanal'!$A$5:$A$504,"<="&$D$3),"00000"),'Avaliação Semanal'!$M$5:$M$504,0)),"")))
A17: =IF(Cadastro!$A16="","",Cadastro!$A16) | B17: =IF(Cadastro!$A16="","",Cadastro!$B16) | C17: =IF(Cadastro!$A16="","",Cadastro!$C16) | D17: =IF($A17="","",IF(COUNTIFS('Avaliação Semanal'!$B$5:$B$504,$A17,'Avaliação Semanal'!$C$5:$C$504,"GP",'Avaliação Semanal'!$A$5:$A$504,">="&$B$3,'Avaliação Semanal'!$A$5:$A$504,"<="&$D$3,'Avaliação Semanal'!$J$5:$J$504,">0")=0,"",ROUND(AVERAGEIFS('Avaliação Semanal'!$J$5:$J$504,'Avaliação Semanal'!$B$5:$B$504,$A17,'Avaliação Semanal'!$C$5:$C$504,"GP",'Avaliação Semanal'!$A$5:$A$504,">="&$B$3,'Avaliação Semanal'!$A$5:$A$504,"<="&$D$3),2))) | E17: =IF($A17="","",IF(COUNTIFS('Avaliação Semanal'!$B$5:$B$504,$A17,'Avaliação Semanal'!$C$5:$C$504,"Líder Técnico",'Avaliação Semanal'!$A$5:$A$504,">="&$B$3,'Avaliação Semanal'!$A$5:$A$504,"<="&$D$3,'Avaliação Semanal'!$J$5:$J$504,">0")=0,"",ROUND(AVERAGEIFS('Avaliação Semanal'!$J$5:$J$504,'Avaliação Semanal'!$B$5:$B$504,$A17,'Avaliação Semanal'!$C$5:$C$504,"Líder Técnico",'Avaliação Semanal'!$A$5:$A$504,">="&$B$3,'Avaliação Semanal'!$A$5:$A$504,"<="&$D$3),2))) | F17: =IF($A17="","",IF(COUNTIFS('Avaliação Semanal'!$B$5:$B$504,$A17,'Avaliação Semanal'!$A$5:$A$504,">="&$B$3,'Avaliação Semanal'!$A$5:$A$504,"<="&$D$3,'Avaliação Semanal'!$E$5:$E$504,">0")=0,"",ROUND(AVERAGEIFS('Avaliação Semanal'!$E$5:$E$504,'Avaliação Semanal'!$B$5:$B$504,$A17,'Avaliação Semanal'!$A$5:$A$504,">="&$B$3,'Avaliação Semanal'!$A$5:$A$504,"<="&$D$3),2))) | G17: =IF($A17="","",IF(COUNTIFS('Avaliação Semanal'!$B$5:$B$504,$A17,'Avaliação Semanal'!$A$5:$A$504,">="&$B$3,'Avaliação Semanal'!$A$5:$A$504,"<="&$D$3,'Avaliação Semanal'!$F$5:$F$504,">0")=0,"",ROUND(AVERAGEIFS('Avaliação Semanal'!$F$5:$F$504,'Avaliação Semanal'!$B$5:$B$504,$A17,'Avaliação Semanal'!$A$5:$A$504,">="&$B$3,'Avaliação Semanal'!$A$5:$A$504,"<="&$D$3),2))) | H17: =IF($A17="","",IF(COUNTIFS('Avaliação Semanal'!$B$5:$B$504,$A17,'Avaliação Semanal'!$A$5:$A$504,">="&$B$3,'Avaliação Semanal'!$A$5:$A$504,"<="&$D$3,'Avaliação Semanal'!$G$5:$G$504,">0")=0,"",ROUND(AVERAGEIFS('Avaliação Semanal'!$G$5:$G$504,'Avaliação Semanal'!$B$5:$B$504,$A17,'Avaliação Semanal'!$A$5:$A$504,">="&$B$3,'Avaliação Semanal'!$A$5:$A$504,"<="&$D$3),2))) | I17: =IF($A17="","",IF(COUNTIFS('Avaliação Semanal'!$B$5:$B$504,$A17,'Avaliação Semanal'!$A$5:$A$504,">="&$B$3,'Avaliação Semanal'!$A$5:$A$504,"<="&$D$3,'Avaliação Semanal'!$H$5:$H$504,">0")=0,"",ROUND(AVERAGEIFS('Avaliação Semanal'!$H$5:$H$504,'Avaliação Semanal'!$B$5:$B$504,$A17,'Avaliação Semanal'!$A$5:$A$504,">="&$B$3,'Avaliação Semanal'!$A$5:$A$504,"<="&$D$3),2))) | J17: =IF($A17="","",IF(COUNTIFS('Avaliação Semanal'!$B$5:$B$504,$A17,'Avaliação Semanal'!$A$5:$A$504,">="&$B$3,'Avaliação Semanal'!$A$5:$A$504,"<="&$D$3,'Avaliação Semanal'!$I$5:$I$504,">0")=0,"",ROUND(AVERAGEIFS('Avaliação Semanal'!$I$5:$I$504,'Avaliação Semanal'!$B$5:$B$504,$A17,'Avaliação Semanal'!$A$5:$A$504,">="&$B$3,'Avaliação Semanal'!$A$5:$A$504,"<="&$D$3),2))) | K17: =IF(COUNT($F17:$J17)=0,"",ROUND(AVERAGE($F17:$J17),2)) | L17: =IF($K17="","",IF($K17>=Cadastro!$H$5,"Verde",IF($K17>=Cadastro!$H$6,"Atenção","Crítico"))) | M17: =IF($A17="","",COUNTIFS('Avaliação Semanal'!$B$5:$B$504,$A17,'Avaliação Semanal'!$A$5:$A$504,">="&$B$3,'Avaliação Semanal'!$A$5:$A$504,"<="&$D$3,'Avaliação Semanal'!$J$5:$J$504,">0")) | N17: =IF($M17=0,"",_xlfn.MAXIFS('Avaliação Semanal'!$A$5:$A$504,'Avaliação Semanal'!$B$5:$B$504,$A17,'Avaliação Semanal'!$A$5:$A$504,"<="&$D$3)) | O17: =IF($A17="","",COUNTIFS('Ocorrências'!$B$5:$B$204,$A17,'Ocorrências'!$A$5:$A$204,">="&$B$3,'Ocorrências'!$A$5:$A$204,"<="&$D$3)) | P17: =IF($A17="","",COUNTIFS('Ocorrências'!$B$5:$B$204,$A17,'Ocorrências'!$C$5:$C$204,"Ponto de atenção",'Ocorrências'!$A$5:$A$204,">="&$B$3,'Ocorrências'!$A$5:$A$204,"<="&$D$3)+COUNTIFS('Ocorrências'!$B$5:$B$204,$A17,'Ocorrências'!$C$5:$C$204,"Crítica",'Ocorrências'!$A$5:$A$204,">="&$B$3,'Ocorrências'!$A$5:$A$204,"<="&$D$3)) | Q17: =IF($A17="","",IF(COUNTIFS('Avaliação Semanal'!$B$5:$B$504,$A17,'Avaliação Semanal'!$C$5:$C$504,"GP",'Avaliação Semanal'!$A$5:$A$504,">="&$B$3,'Avaliação Semanal'!$A$5:$A$504,"<="&$D$3)=0,"",IFERROR(INDEX('Avaliação Semanal'!$L$5:$L$504,MATCH($A17&"|GP|"&TEXT(_xlfn.MAXIFS('Avaliação Semanal'!$A$5:$A$504,'Avaliação Semanal'!$B$5:$B$504,$A17,'Avaliação Semanal'!$C$5:$C$504,"GP",'Avaliação Semanal'!$A$5:$A$504,"<="&$D$3),"00000"),'Avaliação Semanal'!$M$5:$M$504,0)),""))) | R17: =IF($A17="","",IF(COUNTIFS('Avaliação Semanal'!$B$5:$B$504,$A17,'Avaliação Semanal'!$C$5:$C$504,"Líder Técnico",'Avaliação Semanal'!$A$5:$A$504,">="&$B$3,'Avaliação Semanal'!$A$5:$A$504,"<="&$D$3)=0,"",IFERROR(INDEX('Avaliação Semanal'!$L$5:$L$504,MATCH($A17&"|Líder Técnico|"&TEXT(_xlfn.MAXIFS('Avaliação Semanal'!$A$5:$A$504,'Avaliação Semanal'!$B$5:$B$504,$A17,'Avaliação Semanal'!$C$5:$C$504,"Líder Técnico",'Avaliação Semanal'!$A$5:$A$504,"<="&$D$3),"00000"),'Avaliação Semanal'!$M$5:$M$504,0)),"")))
