Workbook

Sheet Instruções
A1: Avaliação de Desempenho por Squad — GP + Líder Técnico + Gestor de Pessoas
A2: Versão 3 · construída com as visões de RH, Gerência de Projetos, Liderança Técnica e Gestão de Pessoas, e revisada por um revisor de qualidade e um revisor técnico
A4: O QUE ESTA PLANILHA É
B5: O registro contínuo é o produto; a nota é subproduto. Se só uma aba sobreviver, que seja 'Ocorrências'. Uma nota sem ocorrência vinculada não é avaliação, é impressão.
A6: RITMO DE USO
A7: Quando acontecer — 45 segundos | B7: Lance a ocorrência: bloco rápido, colunas A a J, um único campo de texto. Meta: 2 a 4 por pessoa por mês, com ao menos 1 positiva a cada 2 registros.
A8: Sexta — 15 min pela squad | B8: Abra o 'Painel'. Leia a primeira linha vermelha: de quem você não sabe nada. Não avalie nada.
A9: Fim do ciclo — 20 min por pessoa | B9: Preencha 'Avaliação'. Você não escreve do zero: lê o que já foi acumulado.
A10: Antes da devolutiva | B10: Calibração GP × LT só nos itens divergentes. Depois, a 1:1 com a aba '1a1' impressa.
A11: QUEM AVALIA O QUÊ
A12: Líder Técnico decide | B12: Qualidade da entrega · Domínio técnico · Design de solução.
A13: GP decide | B13: Previsibilidade.
A14: Compartilhado | B14: Comunicação e colaboração · Autonomia e ownership. Quem não tem evidência deixa em branco — em branco é resposta legítima e melhor que chute.
A15: AS NOVE REGRAS DURAS
A16: Regra 1 | B16: 3 é 'atende plenamente PARA A SENIORIDADE'. Não é nota ruim. Um Júnior 3 e um Sênior 3 são comportamentos diferentes.
A17: Regra 2 | B17: Nota 1, 2 ou 5 exige ocorrência vinculada no ciclo. Sem lastro, a célula acusa e o ciclo não fecha.
A18: Regra 3 | B18: Nunca a média entre avaliadores — nem GP × LT, nem GP × GP em quem tem dois contratos. A divergência é a informação.
A19: Regra 4 | B19: Ocorrência negativa nunca conversada com a pessoa NÃO entra no ciclo e não viaja no handover.
A20: Regra 5 | B20: 'Fato observável' não aceita adjetivo de personalidade. O juízo vai em 'Consequência', e tem de ser defensável a partir do fato ao lado.
A21: Regra 6 | B21: Comparação e ranking usam SEMPRE o gap contra a expectativa da senioridade. Nunca a nota bruta, nunca entre squads.
A22: Regra 7 | B22: Sem curva forçada. Distribuição imposta em squad de 6 pessoas é matematicamente absurda.
A23: Regra 8 | B23: Conduta, assédio, denúncia e saúde NÃO entram aqui, em nenhuma aba. Registre 'encaminhado ao RH em <data>' e a apuração corre em processo próprio.
A24: Regra 9 | B24: Nota 3 ou mais COM ocorrência negativa não conversada acende 'Nota sustentada por omissão' — endereçado ao gestor do GP, nunca à pessoa avaliada.
A25: DUAS COISAS QUE ESTA PLANILHA NÃO FAZ, E VOCÊ PRECISA SABER
B26: 1) A obrigatoriedade é DETECTIVA, não preventiva. Ninguém é impedido de salvar uma ocorrência incompleta — validação de dados não torna campo obrigatório, célula em branco nunca dispara validação. O que o modelo garante é que a linha incompleta NÃO CONTA: não entra no lastro, não viaja no handover, e acende alerta.
B27: 2) Ocorrência antiga não se esconde sozinha. Use o filtro na coluna 'Exibição' (Ativa / Histórico / Arquivada). Erro tratado não se cobra três vezes — mas quem esconde é o filtro, não a fórmula.
A28: LGPD — LEIA ANTES DE ESCREVER
B29: Não registre dado sensível: saúde, diagnóstico, religião, orientação sexual, filiação sindical, origem racial, vida familiar. Ausência registra o FATO, nunca o motivo.
B30: A pessoa pode pedir acesso ao que se registrou sobre ela. Regra prática: não escreva nada que você não sustentaria lendo em voz alta para ela.
B31: Arquivo único no drive corporativo, com coautoria. Nunca anexo de e-mail, nunca cópia local. Senha de planilha do Excel não é controle de acesso — por isso retenção, caso de promoção e registro privado do gestor vivem em ARQUIVO SEPARADO, não aqui.
A32: LEGENDA
A33: Fundo amarelo, texto azul | B33: Célula que você preenche.
A34: Fundo cinza | B34: Célula calculada. Não digite por cima — você quebra o Painel.
B35: As abas 'Pessoas', 'Alocações' e 'Config' são cadastro: ajuste no começo e não mexa no dia a dia. No dia a dia você convive com quatro abas: Painel, Ocorrências, Avaliação e 1a1.
A36: LIMITE HONESTO
B37: Excel não tem controle de acesso por linha nem trilha de auditoria. Use isto para provar o modelo em 2 ou 3 ciclos. Se funcionar, migre para um sistema.
B38: As expectativas por senioridade e os pesos por eixo são premissa desta versão, não benchmark de mercado. Calibre ao fim do primeiro ciclo real e registre quem confirmou, na aba Config.

Sheet Painel
A1: Painel do gestor — o que abrir na segunda de manhã
A2: ="Ciclo "&Config!$B$4&" · comparação sempre por GAP contra a expectativa da senioridade — nunca por nota bruta, nunca entre squads."
A3: =IF(SUM(Pessoas!$O$5:$O$64)=0,"Todas as pessoas têm registro neste ciclo.","Sem nenhum registro neste ciclo: "&IFERROR(INDEX(Pessoas!$B$5:$B$64,MATCH(1,Pessoas!$P$5:$P$64,0)),"")&IFERROR(", "&INDEX(Pessoas!$B$5:$B$64,MATCH(2,Pessoas!$P$5:$P$64,0)),"")&IFERROR(", "&INDEX(Pessoas!$B$5:$B$64,MATCH(3,Pessoas!$P$5:$P$64,0)),"")&IF(SUM(Pessoas!$O$5:$O$64)>3,", …","")&" ("&SUM(Pessoas!$O$5:$O$64)&" de "&COUNTIF(Pessoas!$I$5:$I$64,"Ativo")&")")
A4: ="Ocorrências registradas: "&COUNTIF('Ocorrências'!$A$5:$A$604,">0")&" de 600 linhas disponíveis"
A6: ID | B6: Pessoa | C6: Senioridade | D6: Papel considerado | E6: Multi | F6: Eixo A | G6: Eixo B | H6: Eixo C | I6: Eixo D | J6: Nota ponderada | K6: Expectativa | L6: Gap | M6: Faixa | N6: Ocorr. | O6: Positivas | P6: Negativas | Q6: Neg. não comunic. | R6: Dias desde 1:1 | S6: Diverg. 2+ | T6: Sem lastro | U6: Nota s/ omissão | V6: Sinal | W6: num | X6: den
A7: =IF(Pessoas!$B5="","",Pessoas!$A5) | B7: =IF(Pessoas!$B5="","",Pessoas!$B5) | C7: =IF(Pessoas!$B5="","",Pessoas!$D5) | D7: =IF(Pessoas!$B5="","",Pessoas!$L5) | E7: =IF(Pessoas!$B5="","",Pessoas!$M5) | F7: =IF($B7="","",IFERROR(AVERAGEIFS('Avaliação'!$P$5:$P$404,'Avaliação'!$Z$5:$Z$404,$A7&"|"&Config!$B$7&"|"&Config!$A$22),"")) | G7: =IF($B7="","",IFERROR(AVERAGEIFS('Avaliação'!$P$5:$P$404,'Avaliação'!$Z$5:$Z$404,$A7&"|"&Config!$B$7&"|"&Config!$A$23),"")) | H7: =IF($B7="","",IFERROR(AVERAGEIFS('Avaliação'!$P$5:$P$404,'Avaliação'!$Z$5:$Z$404,$A7&"|"&Config!$B$7&"|"&Config!$A$24),"")) | I7: =IF($B7="","",IFERROR(AVERAGEIFS('Avaliação'!$P$5:$P$404,'Avaliação'!$Z$5:$Z$404,$A7&"|"&Config!$B$7&"|"&Config!$A$25),"")) | J7: =IF($X7=0,"",$W7/$X7) | K7: =IFERROR(INDEX(Config!$B$30:$B$33,MATCH($C7,Config!$A$30:$A$33,0)),"") | L7: =IF(OR($J7="",$K7=""),"",$J7-$K7) | M7: =IF($J7="","",IF($J7<2.5,"Abaixo",IF($J7<3.5,"Atende",IF($J7<=4.2,"Supera","Referência")))) | N7: =IF($B7="","",COUNTIFS('Ocorrências'!$U$5:$U$604,$A7&"|"&Config!$B$7)) | O7: =IF($B7="","",COUNTIFS('Ocorrências'!$U$5:$U$604,$A7&"|"&Config!$B$7,'Ocorrências'!$F$5:$F$604,"Reconhecimento")+COUNTIFS('Ocorrências'!$U$5:$U$604,$A7&"|"&Config!$B$7,'Ocorrências'!$F$5:$F$604,"Positiva")) | P7: =IF($B7="","",COUNTIFS('Ocorrências'!$U$5:$U$604,$A7&"|"&Config!$B$7,'Ocorrências'!$F$5:$F$604,"Ponto de atenção")+COUNTIFS('Ocorrências'!$U$5:$U$604,$A7&"|"&Config!$B$7,'Ocorrências'!$F$5:$F$604,"Incidente")) | Q7: =IF($B7="","",COUNTIFS('Ocorrências'!$U$5:$U$604,$A7&"|"&Config!$B$7,'Ocorrências'!$F$5:$F$604,"Ponto de atenção",'Ocorrências'!$L$5:$L$604,"Não")+COUNTIFS('Ocorrências'!$U$5:$U$604,$A7&"|"&Config!$B$7,'Ocorrências'!$F$5:$F$604,"Incidente",'Ocorrências'!$L$5:$L$604,"Não")) | R7: =IF($B7="","",IF(INDEX(Pessoas!$J$5:$J$64,MATCH($A7,Pessoas!$A$5:$A$64,0))="","nunca",Config!$B$6-INDEX(Pessoas!$J$5:$J$64,MATCH($A7,Pessoas!$A$5:$A$64,0)))) | S7: =IF($B7="","",COUNTIFS('Avaliação'!$Y$5:$Y$404,$A7&"|"&Config!$B$7,'Avaliação'!$N$5:$N$404,">=2")) | T7: =IF($B7="","",COUNTIFS('Avaliação'!$Y$5:$Y$404,$A7&"|"&Config!$B$7,'Avaliação'!$V$5:$V$404,"SEM LASTRO")) | U7: =IF($B7="","",IF(AND($Q7>0,COUNTIFS('Avaliação'!$Y$5:$Y$404,$A7&"|"&Config!$B$7,'Avaliação'!$P$5:$P$404,">=3")>0),$Q7,0)) | V7: =IF($B7="","",IF($U7>0,"Nota sustentada por omissão",IF($T7>0,"Nota sem lastro",IF($J7="","Sem avaliação no ciclo",IF($S7>0,"Calibrar divergência",IF($L7<-0.3,"Abaixo da expectativa",IF($Q7>0,"Negativa não conversada",IF(OR($R7="nunca",$R7>30),"1:1 atrasada","OK")))))))) | W7: =IF(ISNUMBER($F7),$F7*Config!$B$22,0)+IF(ISNUMBER($G7),$G7*Config!$B$23,0)+IF(ISNUMBER($H7),$H7*Config!$B$24,0)+IF(ISNUMBER($I7),$I7*Config!$B$25,0) | X7: =IF(ISNUMBER($F7),Config!$B$22,0)+IF(ISNUMBER($G7),Config!$B$23,0)+IF(ISNUMBER($H7),Config!$B$24,0)+IF(ISNUMBER($I7),Config!$B$25,0)
A8: =IF(Pessoas!$B6="","",Pessoas!$A6) | B8: =IF(Pessoas!$B6="","",Pessoas!$B6) | C8: =IF(Pessoas!$B6="","",Pessoas!$D6) | D8: =IF(Pessoas!$B6="","",Pessoas!$L6) | E8: =IF(Pessoas!$B6="","",Pessoas!$M6) | F8: =IF($B8="","",IFERROR(AVERAGEIFS('Avaliação'!$P$5:$P$404,'Avaliação'!$Z$5:$Z$404,$A8&"|"&Config!$B$7&"|"&Config!$A$22),"")) | G8: =IF($B8="","",IFERROR(AVERAGEIFS('Avaliação'!$P$5:$P$404,'Avaliação'!$Z$5:$Z$404,$A8&"|"&Config!$B$7&"|"&Config!$A$23),"")) | H8: =IF($B8="","",IFERROR(AVERAGEIFS('Avaliação'!$P$5:$P$404,'Avaliação'!$Z$5:$Z$404,$A8&"|"&Config!$B$7&"|"&Config!$A$24),"")) | I8: =IF($B8="","",IFERROR(AVERAGEIFS('Avaliação'!$P$5:$P$404,'Avaliação'!$Z$5:$Z$404,$A8&"|"&Config!$B$7&"|"&Config!$A$25),"")) | J8: =IF($X8=0,"",$W8/$X8) | K8: =IFERROR(INDEX(Config!$B$30:$B$33,MATCH($C8,Config!$A$30:$A$33,0)),"") | L8: =IF(OR($J8="",$K8=""),"",$J8-$K8) | M8: =IF($J8="","",IF($J8<2.5,"Abaixo",IF($J8<3.5,"Atende",IF($J8<=4.2,"Supera","Referência")))) | N8: =IF($B8="","",COUNTIFS('Ocorrências'!$U$5:$U$604,$A8&"|"&Config!$B$7)) | O8: =IF($B8="","",COUNTIFS('Ocorrências'!$U$5:$U$604,$A8&"|"&Config!$B$7,'Ocorrências'!$F$5:$F$604,"Reconhecimento")+COUNTIFS('Ocorrências'!$U$5:$U$604,$A8&"|"&Config!$B$7,'Ocorrências'!$F$5:$F$604,"Positiva")) | P8: =IF($B8="","",COUNTIFS('Ocorrências'!$U$5:$U$604,$A8&"|"&Config!$B$7,'Ocorrências'!$F$5:$F$604,"Ponto de atenção")+COUNTIFS('Ocorrências'!$U$5:$U$604,$A8&"|"&Config!$B$7,'Ocorrências'!$F$5:$F$604,"Incidente")) | Q8: =IF($B8="","",COUNTIFS('Ocorrências'!$U$5:$U$604,$A8&"|"&Config!$B$7,'Ocorrências'!$F$5:$F$604,"Ponto de atenção",'Ocorrências'!$L$5:$L$604,"Não")+COUNTIFS('Ocorrências'!$U$5:$U$604,$A8&"|"&Config!$B$7,'Ocorrências'!$F$5:$F$604,"Incidente",'Ocorrências'!$L$5:$L$604,"Não")) | R8: =IF($B8="","",IF(INDEX(Pessoas!$J$5:$J$64,MATCH($A8,Pessoas!$A$5:$A$64,0))="","nunca",Config!$B$6-INDEX(Pessoas!$J$5:$J$64,MATCH($A8,Pessoas!$A$5:$A$64,0)))) | S8: =IF($B8="","",COUNTIFS('Avaliação'!$Y$5:$Y$404,$A8&"|"&Config!$B$7,'Avaliação'!$N$5:$N$404,">=2")) | T8: =IF($B8="","",COUNTIFS('Avaliação'!$Y$5:$Y$404,$A8&"|"&Config!$B$7,'Avaliação'!$V$5:$V$404,"SEM LASTRO")) | U8: =IF($B8="","",IF(AND($Q8>0,COUNTIFS('Avaliação'!$Y$5:$Y$404,$A8&"|"&Config!$B$7,'Avaliação'!$P$5:$P$404,">=3")>0),$Q8,0)) | V8: =IF($B8="","",IF($U8>0,"Nota sustentada por omissão",IF($T8>0,"Nota sem lastro",IF($J8="","Sem avaliação no ciclo",IF($S8>0,"Calibrar divergência",IF($L8<-0.3,"Abaixo da expectativa",IF($Q8>0,"Negativa não conversada",IF(OR($R8="nunca",$R8>30),"1:1 atrasada","OK")))))))) | W8: =IF(ISNUMBER($F8),$F8*Config!$B$22,0)+IF(ISNUMBER($G8),$G8*Config!$B$23,0)+IF(ISNUMBER($H8),$H8*Config!$B$24,0)+IF(ISNUMBER($I8),$I8*Config!$B$25,0) | X8: =IF(ISNUMBER($F8),Config!$B$22,0)+IF(ISNUMBER($G8),Config!$B$23,0)+IF(ISNUMBER($H8),Config!$B$24,0)+IF(ISNUMBER($I8),Config!$B$25,0)
A9: =IF(Pessoas!$B7="","",Pessoas!$A7) | B9: =IF(Pessoas!$B7="","",Pessoas!$B7) | C9: =IF(Pessoas!$B7="","",Pessoas!$D7) | D9: =IF(Pessoas!$B7="","",Pessoas!$L7) | E9: =IF(Pessoas!$B7="","",Pessoas!$M7) | F9: =IF($B9="","",IFERROR(AVERAGEIFS('Avaliação'!$P$5:$P$404,'Avaliação'!$Z$5:$Z$404,$A9&"|"&Config!$B$7&"|"&Config!$A$22),"")) | G9: =IF($B9="","",IFERROR(AVERAGEIFS('Avaliação'!$P$5:$P$404,'Avaliação'!$Z$5:$Z$404,$A9&"|"&Config!$B$7&"|"&Config!$A$23),"")) | H9: =IF($B9="","",IFERROR(AVERAGEIFS('Avaliação'!$P$5:$P$404,'Avaliação'!$Z$5:$Z$404,$A9&"|"&Config!$B$7&"|"&Config!$A$24),"")) | I9: =IF($B9="","",IFERROR(AVERAGEIFS('Avaliação'!$P$5:$P$404,'Avaliação'!$Z$5:$Z$404,$A9&"|"&Config!$B$7&"|"&Config!$A$25),"")) | J9: =IF($X9=0,"",$W9/$X9) | K9: =IFERROR(INDEX(Config!$B$30:$B$33,MATCH($C9,Config!$A$30:$A$33,0)),"") | L9: =IF(OR($J9="",$K9=""),"",$J9-$K9) | M9: =IF($J9="","",IF($J9<2.5,"Abaixo",IF($J9<3.5,"Atende",IF($J9<=4.2,"Supera","Referência")))) | N9: =IF($B9="","",COUNTIFS('Ocorrências'!$U$5:$U$604,$A9&"|"&Config!$B$7)) | O9: =IF($B9="","",COUNTIFS('Ocorrências'!$U$5:$U$604,$A9&"|"&Config!$B$7,'Ocorrências'!$F$5:$F$604,"Reconhecimento")+COUNTIFS('Ocorrências'!$U$5:$U$604,$A9&"|"&Config!$B$7,'Ocorrências'!$F$5:$F$604,"Positiva")) | P9: =IF($B9="","",COUNTIFS('Ocorrências'!$U$5:$U$604,$A9&"|"&Config!$B$7,'Ocorrências'!$F$5:$F$604,"Ponto de atenção")+COUNTIFS('Ocorrências'!$U$5:$U$604,$A9&"|"&Config!$B$7,'Ocorrências'!$F$5:$F$604,"Incidente")) | Q9: =IF($B9="","",COUNTIFS('Ocorrências'!$U$5:$U$604,$A9&"|"&Config!$B$7,'Ocorrências'!$F$5:$F$604,"Ponto de atenção",'Ocorrências'!$L$5:$L$604,"Não")+COUNTIFS('Ocorrências'!$U$5:$U$604,$A9&"|"&Config!$B$7,'Ocorrências'!$F$5:$F$604,"Incidente",'Ocorrências'!$L$5:$L$604,"Não")) | R9: =IF($B9="","",IF(INDEX(Pessoas!$J$5:$J$64,MATCH($A9,Pessoas!$A$5:$A$64,0))="","nunca",Config!$B$6-INDEX(Pessoas!$J$5:$J$64,MATCH($A9,Pessoas!$A$5:$A$64,0)))) | S9: =IF($B9="","",COUNTIFS('Avaliação'!$Y$5:$Y$404,$A9&"|"&Config!$B$7,'Avaliação'!$N$5:$N$404,">=2")) | T9: =IF($B9="","",COUNTIFS('Avaliação'!$Y$5:$Y$404,$A9&"|"&Config!$B$7,'Avaliação'!$V$5:$V$404,"SEM LASTRO")) | U9: =IF($B9="","",IF(AND($Q9>0,COUNTIFS('Avaliação'!$Y$5:$Y$404,$A9&"|"&Config!$B$7,'Avaliação'!$P$5:$P$404,">=3")>0),$Q9,0)) | V9: =IF($B9="","",IF($U9>0,"Nota sustentada por omissão",IF($T9>0,"Nota sem lastro",IF($J9="","Sem avaliação no ciclo",IF($S9>0,"Calibrar divergência",IF($L9<-0.3,"Abaixo da expectativa",IF($Q9>0,"Negativa não conversada",IF(OR($R9="nunca",$R9>30),"1:1 atrasada","OK")))))))) | W9: =IF(ISNUMBER($F9),$F9*Config!$B$22,0)+IF(ISNUMBER($G9),$G9*Config!$B$23,0)+IF(ISNUMBER($H9),$H9*Config!$B$24,0)+IF(ISNUMBER($I9),$I9*Config!$B$25,0) | X9: =IF(ISNUMBER($F9),Config!$B$22,0)+IF(ISNUMBER($G9),Config!$B$23,0)+IF(ISNUMBER($H9),Config!$B$24,0)+IF(ISNUMBER($I9),Config!$B$25,0)
A10: =IF(Pessoas!$B8="","",Pessoas!$A8) | B10: =IF(Pessoas!$B8="","",Pessoas!$B8) | C10: =IF(Pessoas!$B8="","",Pessoas!$D8) | D10: =IF(Pessoas!$B8="","",Pessoas!$L8) | E10: =IF(Pessoas!$B8="","",Pessoas!$M8) | F10: =IF($B10="","",IFERROR(AVERAGEIFS('Avaliação'!$P$5:$P$404,'Avaliação'!$Z$5:$Z$404,$A10&"|"&Config!$B$7&"|"&Config!$A$22),"")) | G10: =IF($B10="","",IFERROR(AVERAGEIFS('Avaliação'!$P$5:$P$404,'Avaliação'!$Z$5:$Z$404,$A10&"|"&Config!$B$7&"|"&Config!$A$23),"")) | H10: =IF($B10="","",IFERROR(AVERAGEIFS('Avaliação'!$P$5:$P$404,'Avaliação'!$Z$5:$Z$404,$A10&"|"&Config!$B$7&"|"&Config!$A$24),"")) | I10: =IF($B10="","",IFERROR(AVERAGEIFS('Avaliação'!$P$5:$P$404,'Avaliação'!$Z$5:$Z$404,$A10&"|"&Config!$B$7&"|"&Config!$A$25),"")) | J10: =IF($X10=0,"",$W10/$X10) | K10: =IFERROR(INDEX(Config!$B$30:$B$33,MATCH($C10,Config!$A$30:$A$33,0)),"") | L10: =IF(OR($J10="",$K10=""),"",$J10-$K10) | M10: =IF($J10="","",IF($J10<2.5,"Abaixo",IF($J10<3.5,"Atende",IF($J10<=4.2,"Supera","Referência")))) | N10: =IF($B10="","",COUNTIFS('Ocorrências'!$U$5:$U$604,$A10&"|"&Config!$B$7)) | O10: =IF($B10="","",COUNTIFS('Ocorrências'!$U$5:$U$604,$A10&"|"&Config!$B$7,'Ocorrências'!$F$5:$F$604,"Reconhecimento")+COUNTIFS('Ocorrências'!$U$5:$U$604,$A10&"|"&Config!$B$7,'Ocorrências'!$F$5:$F$604,"Positiva")) | P10: =IF($B10="","",COUNTIFS('Ocorrências'!$U$5:$U$604,$A10&"|"&Config!$B$7,'Ocorrências'!$F$5:$F$604,"Ponto de atenção")+COUNTIFS('Ocorrências'!$U$5:$U$604,$A10&"|"&Config!$B$7,'Ocorrências'!$F$5:$F$604,"Incidente")) | Q10: =IF($B10="","",COUNTIFS('Ocorrências'!$U$5:$U$604,$A10&"|"&Config!$B$7,'Ocorrências'!$F$5:$F$604,"Ponto de atenção",'Ocorrências'!$L$5:$L$604,"Não")+COUNTIFS('Ocorrências'!$U$5:$U$604,$A10&"|"&Config!$B$7,'Ocorrências'!$F$5:$F$604,"Incidente",'Ocorrências'!$L$5:$L$604,"Não")) | R10: =IF($B10="","",IF(INDEX(Pessoas!$J$5:$J$64,MATCH($A10,Pessoas!$A$5:$A$64,0))="","nunca",Config!$B$6-INDEX(Pessoas!$J$5:$J$64,MATCH($A10,Pessoas!$A$5:$A$64,0)))) | S10: =IF($B10="","",COUNTIFS('Avaliação'!$Y$5:$Y$404,$A10&"|"&Config!$B$7,'Avaliação'!$N$5:$N$404,">=2")) | T10: =IF($B10="","",COUNTIFS('Avaliação'!$Y$5:$Y$404,$A10&"|"&Config!$B$7,'Avaliação'!$V$5:$V$404,"SEM LASTRO")) | U10: =IF($B10="","",IF(AND($Q10>0,COUNTIFS('Avaliação'!$Y$5:$Y$404,$A10&"|"&Config!$B$7,'Avaliação'!$P$5:$P$404,">=3")>0),$Q10,0)) | V10: =IF($B10="","",IF($U10>0,"Nota sustentada por omissão",IF($T10>0,"Nota sem lastro",IF($J10="","Sem avaliação no ciclo",IF($S10>0,"Calibrar divergência",IF($L10<-0.3,"Abaixo da expectativa",IF($Q10>0,"Negativa não conversada",IF(OR($R10="nunca",$R10>30),"1:1 atrasada","OK")))))))) | W10: =IF(ISNUMBER($F10),$F10*Config!$B$22,0)+IF(ISNUMBER($G10),$G10*Config!$B$23,0)+IF(ISNUMBER($H10),$H10*Config!$B$24,0)+IF(ISNUMBER($I10),$I10*Config!$B$25,0) | X10: =IF(ISNUMBER($F10),Config!$B$22,0)+IF(ISNUMBER($G10),Config!$B$23,0)+IF(ISNUMBER($H10),Config!$B$24,0)+IF(ISNUMBER($I10),Config!$B$25,0)
A11: =IF(Pessoas!$B9="","",Pessoas!$A9) | B11: =IF(Pessoas!$B9="","",Pessoas!$B9) | C11: =IF(Pessoas!$B9="","",Pessoas!$D9) | D11: =IF(Pessoas!$B9="","",Pessoas!$L9) | E11: =IF(Pessoas!$B9="","",Pessoas!$M9) | F11: =IF($B11="","",IFERROR(AVERAGEIFS('Avaliação'!$P$5:$P$404,'Avaliação'!$Z$5:$Z$404,$A11&"|"&Config!$B$7&"|"&Config!$A$22),"")) | G11: =IF($B11="","",IFERROR(AVERAGEIFS('Avaliação'!$P$5:$P$404,'Avaliação'!$Z$5:$Z$404,$A11&"|"&Config!$B$7&"|"&Config!$A$23),"")) | H11: =IF($B11="","",IFERROR(AVERAGEIFS('Avaliação'!$P$5:$P$404,'Avaliação'!$Z$5:$Z$404,$A11&"|"&Config!$B$7&"|"&Config!$A$24),"")) | I11: =IF($B11="","",IFERROR(AVERAGEIFS('Avaliação'!$P$5:$P$404,'Avaliação'!$Z$5:$Z$404,$A11&"|"&Config!$B$7&"|"&Config!$A$25),"")) | J11: =IF($X11=0,"",$W11/$X11) | K11: =IFERROR(INDEX(Config!$B$30:$B$33,MATCH($C11,Config!$A$30:$A$33,0)),"") | L11: =IF(OR($J11="",$K11=""),"",$J11-$K11) | M11: =IF($J11="","",IF($J11<2.5,"Abaixo",IF($J11<3.5,"Atende",IF($J11<=4.2,"Supera","Referência")))) | N11: =IF($B11="","",COUNTIFS('Ocorrências'!$U$5:$U$604,$A11&"|"&Config!$B$7)) | O11: =IF($B11="","",COUNTIFS('Ocorrências'!$U$5:$U$604,$A11&"|"&Config!$B$7,'Ocorrências'!$F$5:$F$604,"Reconhecimento")+COUNTIFS('Ocorrências'!$U$5:$U$604,$A11&"|"&Config!$B$7,'Ocorrências'!$F$5:$F$604,"Positiva")) | P11: =IF($B11="","",COUNTIFS('Ocorrências'!$U$5:$U$604,$A11&"|"&Config!$B$7,'Ocorrências'!$F$5:$F$604,"Ponto de atenção")+COUNTIFS('Ocorrências'!$U$5:$U$604,$A11&"|"&Config!$B$7,'Ocorrências'!$F$5:$F$604,"Incidente")) | Q11: =IF($B11="","",COUNTIFS('Ocorrências'!$U$5:$U$604,$A11&"|"&Config!$B$7,'Ocorrências'!$F$5:$F$604,"Ponto de atenção",'Ocorrências'!$L$5:$L$604,"Não")+COUNTIFS('Ocorrências'!$U$5:$U$604,$A11&"|"&Config!$B$7,'Ocorrências'!$F$5:$F$604,"Incidente",'Ocorrências'!$L$5:$L$604,"Não")) | R11: =IF($B11="","",IF(INDEX(Pessoas!$J$5:$J$64,MATCH($A11,Pessoas!$A$5:$A$64,0))="","nunca",Config!$B$6-INDEX(Pessoas!$J$5:$J$64,MATCH($A11,Pessoas!$A$5:$A$64,0)))) | S11: =IF($B11="","",COUNTIFS('Avaliação'!$Y$5:$Y$404,$A11&"|"&Config!$B$7,'Avaliação'!$N$5:$N$404,">=2")) | T11: =IF($B11="","",COUNTIFS('Avaliação'!$Y$5:$Y$404,$A11&"|"&Config!$B$7,'Avaliação'!$V$5:$V$404,"SEM LASTRO")) | U11: =IF($B11="","",IF(AND($Q11>0,COUNTIFS('Avaliação'!$Y$5:$Y$404,$A11&"|"&Config!$B$7,'Avaliação'!$P$5:$P$404,">=3")>0),$Q11,0)) | V11: =IF($B11="","",IF($U11>0,"Nota sustentada por omissão",IF($T11>0,"Nota sem lastro",IF($J11="","Sem avaliação no ciclo",IF($S11>0,"Calibrar divergência",IF($L11<-0.3,"Abaixo da expectativa",IF($Q11>0,"Negativa não conversada",IF(OR($R11="nunca",$R11>30),"1:1 atrasada","OK")))))))) | W11: =IF(ISNUMBER($F11),$F11*Config!$B$22,0)+IF(ISNUMBER($G11),$G11*Config!$B$23,0)+IF(ISNUMBER($H11),$H11*Config!$B$24,0)+IF(ISNUMBER($I11),$I11*Config!$B$25,0) | X11: =IF(ISNUMBER($F11),Config!$B$22,0)+IF(ISNUMBER($G11),Config!$B$23,0)+IF(ISNUMBER($H11),Config!$B$24,0)+IF(ISNUMBER($I11),Config!$B$25,0)
A12: =IF(Pessoas!$B10="","",Pessoas!$A10) | B12: =IF(Pessoas!$B10="","",Pessoas!$B10) | C12: =IF(Pessoas!$B10="","",Pessoas!$D10) | D12: =IF(Pessoas!$B10="","",Pessoas!$L10) | E12: =IF(Pessoas!$B10="","",Pessoas!$M10) | F12: =IF($B12="","",IFERROR(AVERAGEIFS('Avaliação'!$P$5:$P$404,'Avaliação'!$Z$5:$Z$404,$A12&"|"&Config!$B$7&"|"&Config!$A$22),"")) | G12: =IF($B12="","",IFERROR(AVERAGEIFS('Avaliação'!$P$5:$P$404,'Avaliação'!$Z$5:$Z$404,$A12&"|"&Config!$B$7&"|"&Config!$A$23),"")) | H12: =IF($B12="","",IFERROR(AVERAGEIFS('Avaliação'!$P$5:$P$404,'Avaliação'!$Z$5:$Z$404,$A12&"|"&Config!$B$7&"|"&Config!$A$24),"")) | I12: =IF($B12="","",IFERROR(AVERAGEIFS('Avaliação'!$P$5:$P$404,'Avaliação'!$Z$5:$Z$404,$A12&"|"&Config!$B$7&"|"&Config!$A$25),"")) | J12: =IF($X12=0,"",$W12/$X12) | K12: =IFERROR(INDEX(Config!$B$30:$B$33,MATCH($C12,Config!$A$30:$A$33,0)),"") | L12: =IF(OR($J12="",$K12=""),"",$J12-$K12) | M12: =IF($J12="","",IF($J12<2.5,"Abaixo",IF($J12<3.5,"Atende",IF($J12<=4.2,"Supera","Referência")))) | N12: =IF($B12="","",COUNTIFS('Ocorrências'!$U$5:$U$604,$A12&"|"&Config!$B$7)) | O12: =IF($B12="","",COUNTIFS('Ocorrências'!$U$5:$U$604,$A12&"|"&Config!$B$7,'Ocorrências'!$F$5:$F$604,"Reconhecimento")+COUNTIFS('Ocorrências'!$U$5:$U$604,$A12&"|"&Config!$B$7,'Ocorrências'!$F$5:$F$604,"Positiva")) | P12: =IF($B12="","",COUNTIFS('Ocorrências'!$U$5:$U$604,$A12&"|"&Config!$B$7,'Ocorrências'!$F$5:$F$604,"Ponto de atenção")+COUNTIFS('Ocorrências'!$U$5:$U$604,$A12&"|"&Config!$B$7,'Ocorrências'!$F$5:$F$604,"Incidente")) | Q12: =IF($B12="","",COUNTIFS('Ocorrências'!$U$5:$U$604,$A12&"|"&Config!$B$7,'Ocorrências'!$F$5:$F$604,"Ponto de atenção",'Ocorrências'!$L$5:$L$604,"Não")+COUNTIFS('Ocorrências'!$U$5:$U$604,$A12&"|"&Config!$B$7,'Ocorrências'!$F$5:$F$604,"Incidente",'Ocorrências'!$L$5:$L$604,"Não")) | R12: =IF($B12="","",IF(INDEX(Pessoas!$J$5:$J$64,MATCH($A12,Pessoas!$A$5:$A$64,0))="","nunca",Config!$B$6-INDEX(Pessoas!$J$5:$J$64,MATCH($A12,Pessoas!$A$5:$A$64,0)))) | S12: =IF($B12="","",COUNTIFS('Avaliação'!$Y$5:$Y$404,$A12&"|"&Config!$B$7,'Avaliação'!$N$5:$N$404,">=2")) | T12: =IF($B12="","",COUNTIFS('Avaliação'!$Y$5:$Y$404,$A12&"|"&Config!$B$7,'Avaliação'!$V$5:$V$404,"SEM LASTRO")) | U12: =IF($B12="","",IF(AND($Q12>0,COUNTIFS('Avaliação'!$Y$5:$Y$404,$A12&"|"&Config!$B$7,'Avaliação'!$P$5:$P$404,">=3")>0),$Q12,0)) | V12: =IF($B12="","",IF($U12>0,"Nota sustentada por omissão",IF($T12>0,"Nota sem lastro",IF($J12="","Sem avaliação no ciclo",IF($S12>0,"Calibrar divergência",IF($L12<-0.3,"Abaixo da expectativa",IF($Q12>0,"Negativa não conversada",IF(OR($R12="nunca",$R12>30),"1:1 atrasada","OK")))))))) | W12: =IF(ISNUMBER($F12),$F12*Config!$B$22,0)+IF(ISNUMBER($G12),$G12*Config!$B$23,0)+IF(ISNUMBER($H12),$H12*Config!$B$24,0)+IF(ISNUMBER($I12),$I12*Config!$B$25,0) | X12: =IF(ISNUMBER($F12),Config!$B$22,0)+IF(ISNUMBER($G12),Config!$B$23,0)+IF(ISNUMBER($H12),Config!$B$24,0)+IF(ISNUMBER($I12),Config!$B$25,0)
A13: =IF(Pessoas!$B11="","",Pessoas!$A11) | B13: =IF(Pessoas!$B11="","",Pessoas!$B11) | C13: =IF(Pessoas!$B11="","",Pessoas!$D11) | D13: =IF(Pessoas!$B11="","",Pessoas!$L11) | E13: =IF(Pessoas!$B11="","",Pessoas!$M11) | F13: =IF($B13="","",IFERROR(AVERAGEIFS('Avaliação'!$P$5:$P$404,'Avaliação'!$Z$5:$Z$404,$A13&"|"&Config!$B$7&"|"&Config!$A$22),"")) | G13: =IF($B13="","",IFERROR(AVERAGEIFS('Avaliação'!$P$5:$P$404,'Avaliação'!$Z$5:$Z$404,$A13&"|"&Config!$B$7&"|"&Config!$A$23),"")) | H13: =IF($B13="","",IFERROR(AVERAGEIFS('Avaliação'!$P$5:$P$404,'Avaliação'!$Z$5:$Z$404,$A13&"|"&Config!$B$7&"|"&Config!$A$24),"")) | I13: =IF($B13="","",IFERROR(AVERAGEIFS('Avaliação'!$P$5:$P$404,'Avaliação'!$Z$5:$Z$404,$A13&"|"&Config!$B$7&"|"&Config!$A$25),"")) | J13: =IF($X13=0,"",$W13/$X13) | K13: =IFERROR(INDEX(Config!$B$30:$B$33,MATCH($C13,Config!$A$30:$A$33,0)),"") | L13: =IF(OR($J13="",$K13=""),"",$J13-$K13) | M13: =IF($J13="","",IF($J13<2.5,"Abaixo",IF($J13<3.5,"Atende",IF($J13<=4.2,"Supera","Referência")))) | N13: =IF($B13="","",COUNTIFS('Ocorrências'!$U$5:$U$604,$A13&"|"&Config!$B$7)) | O13: =IF($B13="","",COUNTIFS('Ocorrências'!$U$5:$U$604,$A13&"|"&Config!$B$7,'Ocorrências'!$F$5:$F$604,"Reconhecimento")+COUNTIFS('Ocorrências'!$U$5:$U$604,$A13&"|"&Config!$B$7,'Ocorrências'!$F$5:$F$604,"Positiva")) | P13: =IF($B13="","",COUNTIFS('Ocorrências'!$U$5:$U$604,$A13&"|"&Config!$B$7,'Ocorrências'!$F$5:$F$604,"Ponto de atenção")+COUNTIFS('Ocorrências'!$U$5:$U$604,$A13&"|"&Config!$B$7,'Ocorrências'!$F$5:$F$604,"Incidente")) | Q13: =IF($B13="","",COUNTIFS('Ocorrências'!$U$5:$U$604,$A13&"|"&Config!$B$7,'Ocorrências'!$F$5:$F$604,"Ponto de atenção",'Ocorrências'!$L$5:$L$604,"Não")+COUNTIFS('Ocorrências'!$U$5:$U$604,$A13&"|"&Config!$B$7,'Ocorrências'!$F$5:$F$604,"Incidente",'Ocorrências'!$L$5:$L$604,"Não")) | R13: =IF($B13="","",IF(INDEX(Pessoas!$J$5:$J$64,MATCH($A13,Pessoas!$A$5:$A$64,0))="","nunca",Config!$B$6-INDEX(Pessoas!$J$5:$J$64,MATCH($A13,Pessoas!$A$5:$A$64,0)))) | S13: =IF($B13="","",COUNTIFS('Avaliação'!$Y$5:$Y$404,$A13&"|"&Config!$B$7,'Avaliação'!$N$5:$N$404,">=2")) | T13: =IF($B13="","",COUNTIFS('Avaliação'!$Y$5:$Y$404,$A13&"|"&Config!$B$7,'Avaliação'!$V$5:$V$404,"SEM LASTRO")) | U13: =IF($B13="","",IF(AND($Q13>0,COUNTIFS('Avaliação'!$Y$5:$Y$404,$A13&"|"&Config!$B$7,'Avaliação'!$P$5:$P$404,">=3")>0),$Q13,0)) | V13: =IF($B13="","",IF($U13>0,"Nota sustentada por omissão",IF($T13>0,"Nota sem lastro",IF($J13="","Sem avaliação no ciclo",IF($S13>0,"Calibrar divergência",IF($L13<-0.3,"Abaixo da expectativa",IF($Q13>0,"Negativa não conversada",IF(OR($R13="nunca",$R13>30),"1:1 atrasada","OK")))))))) | W13: =IF(ISNUMBER($F13),$F13*Config!$B$22,0)+IF(ISNUMBER($G13),$G13*Config!$B$23,0)+IF(ISNUMBER($H13),$H13*Config!$B$24,0)+IF(ISNUMBER($I13),$I13*Config!$B$25,0) | X13: =IF(ISNUMBER($F13),Config!$B$22,0)+IF(ISNUMBER($G13),Config!$B$23,0)+IF(ISNUMBER($H13),Config!$B$24,0)+IF(ISNUMBER($I13),Config!$B$25,0)
A14: =IF(Pessoas!$B12="","",Pessoas!$A12) | B14: =IF(Pessoas!$B12="","",Pessoas!$B12) | C14: =IF(Pessoas!$B12="","",Pessoas!$D12) | D14: =IF(Pessoas!$B12="","",Pessoas!$L12) | E14: =IF(Pessoas!$B12="","",Pessoas!$M12) | F14: =IF($B14="","",IFERROR(AVERAGEIFS('Avaliação'!$P$5:$P$404,'Avaliação'!$Z$5:$Z$404,$A14&"|"&Config!$B$7&"|"&Config!$A$22),"")) | G14: =IF($B14="","",IFERROR(AVERAGEIFS('Avaliação'!$P$5:$P$404,'Avaliação'!$Z$5:$Z$404,$A14&"|"&Config!$B$7&"|"&Config!$A$23),"")) | H14: =IF($B14="","",IFERROR(AVERAGEIFS('Avaliação'!$P$5:$P$404,'Avaliação'!$Z$5:$Z$404,$A14&"|"&Config!$B$7&"|"&Config!$A$24),"")) | I14: =IF($B14="","",IFERROR(AVERAGEIFS('Avaliação'!$P$5:$P$404,'Avaliação'!$Z$5:$Z$404,$A14&"|"&Config!$B$7&"|"&Config!$A$25),"")) | J14: =IF($X14=0,"",$W14/$X14) | K14: =IFERROR(INDEX(Config!$B$30:$B$33,MATCH($C14,Config!$A$30:$A$33,0)),"") | L14: =IF(OR($J14="",$K14=""),"",$J14-$K14) | M14: =IF($J14="","",IF($J14<2.5,"Abaixo",IF($J14<3.5,"Atende",IF($J14<=4.2,"Supera","Referência")))) | N14: =IF($B14="","",COUNTIFS('Ocorrências'!$U$5:$U$604,$A14&"|"&Config!$B$7)) | O14: =IF($B14="","",COUNTIFS('Ocorrências'!$U$5:$U$604,$A14&"|"&Config!$B$7,'Ocorrências'!$F$5:$F$604,"Reconhecimento")+COUNTIFS('Ocorrências'!$U$5:$U$604,$A14&"|"&Config!$B$7,'Ocorrências'!$F$5:$F$604,"Positiva")) | P14: =IF($B14="","",COUNTIFS('Ocorrências'!$U$5:$U$604,$A14&"|"&Config!$B$7,'Ocorrências'!$F$5:$F$604,"Ponto de atenção")+COUNTIFS('Ocorrências'!$U$5:$U$604,$A14&"|"&Config!$B$7,'Ocorrências'!$F$5:$F$604,"Incidente")) | Q14: =IF($B14="","",COUNTIFS('Ocorrências'!$U$5:$U$604,$A14&"|"&Config!$B$7,'Ocorrências'!$F$5:$F$604,"Ponto de atenção",'Ocorrências'!$L$5:$L$604,"Não")+COUNTIFS('Ocorrências'!$U$5:$U$604,$A14&"|"&Config!$B$7,'Ocorrências'!$F$5:$F$604,"Incidente",'Ocorrências'!$L$5:$L$604,"Não")) | R14: =IF($B14="","",IF(INDEX(Pessoas!$J$5:$J$64,MATCH($A14,Pessoas!$A$5:$A$64,0))="","nunca",Config!$B$6-INDEX(Pessoas!$J$5:$J$64,MATCH($A14,Pessoas!$A$5:$A$64,0)))) | S14: =IF($B14="","",COUNTIFS('Avaliação'!$Y$5:$Y$404,$A14&"|"&Config!$B$7,'Avaliação'!$N$5:$N$404,">=2")) | T14: =IF($B14="","",COUNTIFS('Avaliação'!$Y$5:$Y$404,$A14&"|"&Config!$B$7,'Avaliação'!$V$5:$V$404,"SEM LASTRO")) | U14: =IF($B14="","",IF(AND($Q14>0,COUNTIFS('Avaliação'!$Y$5:$Y$404,$A14&"|"&Config!$B$7,'Avaliação'!$P$5:$P$404,">=3")>0),$Q14,0)) | V14: =IF($B14="","",IF($U14>0,"Nota sustentada por omissão",IF($T14>0,"Nota sem lastro",IF($J14="","Sem avaliação no ciclo",IF($S14>0,"Calibrar divergência",IF($L14<-0.3,"Abaixo da expectativa",IF($Q14>0,"Negativa não conversada",IF(OR($R14="nunca",$R14>30),"1:1 atrasada","OK")))))))) | W14: =IF(ISNUMBER($F14),$F14*Config!$B$22,0)+IF(ISNUMBER($G14),$G14*Config!$B$23,0)+IF(ISNUMBER($H14),$H14*Config!$B$24,0)+IF(ISNUMBER($I14),$I14*Config!$B$25,0) | X14: =IF(ISNUMBER($F14),Config!$B$22,0)+IF(ISNUMBER($G14),Config!$B$23,0)+IF(ISNUMBER($H14),Config!$B$24,0)+IF(ISNUMBER($I14),Config!$B$25,0)
A15: =IF(Pessoas!$B13="","",Pessoas!$A13) | B15: =IF(Pessoas!$B13="","",Pessoas!$B13) | C15: =IF(Pessoas!$B13="","",Pessoas!$D13) | D15: =IF(Pessoas!$B13="","",Pessoas!$L13) | E15: =IF(Pessoas!$B13="","",Pessoas!$M13) | F15: =IF($B15="","",IFERROR(AVERAGEIFS('Avaliação'!$P$5:$P$404,'Avaliação'!$Z$5:$Z$404,$A15&"|"&Config!$B$7&"|"&Config!$A$22),"")) | G15: =IF($B15="","",IFERROR(AVERAGEIFS('Avaliação'!$P$5:$P$404,'Avaliação'!$Z$5:$Z$404,$A15&"|"&Config!$B$7&"|"&Config!$A$23),"")) | H15: =IF($B15="","",IFERROR(AVERAGEIFS('Avaliação'!$P$5:$P$404,'Avaliação'!$Z$5:$Z$404,$A15&"|"&Config!$B$7&"|"&Config!$A$24),"")) | I15: =IF($B15="","",IFERROR(AVERAGEIFS('Avaliação'!$P$5:$P$404,'Avaliação'!$Z$5:$Z$404,$A15&"|"&Config!$B$7&"|"&Config!$A$25),"")) | J15: =IF($X15=0,"",$W15/$X15) | K15: =IFERROR(INDEX(Config!$B$30:$B$33,MATCH($C15,Config!$A$30:$A$33,0)),"") | L15: =IF(OR($J15="",$K15=""),"",$J15-$K15) | M15: =IF($J15="","",IF($J15<2.5,"Abaixo",IF($J15<3.5,"Atende",IF($J15<=4.2,"Supera","Referência")))) | N15: =IF($B15="","",COUNTIFS('Ocorrências'!$U$5:$U$604,$A15&"|"&Config!$B$7)) | O15: =IF($B15="","",COUNTIFS('Ocorrências'!$U$5:$U$604,$A15&"|"&Config!$B$7,'Ocorrências'!$F$5:$F$604,"Reconhecimento")+COUNTIFS('Ocorrências'!$U$5:$U$604,$A15&"|"&Config!$B$7,'Ocorrências'!$F$5:$F$604,"Positiva")) | P15: =IF($B15="","",COUNTIFS('Ocorrências'!$U$5:$U$604,$A15&"|"&Config!$B$7,'Ocorrências'!$F$5:$F$604,"Ponto de atenção")+COUNTIFS('Ocorrências'!$U$5:$U$604,$A15&"|"&Config!$B$7,'Ocorrências'!$F$5:$F$604,"Incidente")) | Q15: =IF($B15="","",COUNTIFS('Ocorrências'!$U$5:$U$604,$A15&"|"&Config!$B$7,'Ocorrências'!$F$5:$F$604,"Ponto de atenção",'Ocorrências'!$L$5:$L$604,"Não")+COUNTIFS('Ocorrências'!$U$5:$U$604,$A15&"|"&Config!$B$7,'Ocorrências'!$F$5:$F$604,"Incidente",'Ocorrências'!$L$5:$L$604,"Não")) | R15: =IF($B15="","",IF(INDEX(Pessoas!$J$5:$J$64,MATCH($A15,Pessoas!$A$5:$A$64,0))="","nunca",Config!$B$6-INDEX(Pessoas!$J$5:$J$64,MATCH($A15,Pessoas!$A$5:$A$64,0)))) | S15: =IF($B15="","",COUNTIFS('Avaliação'!$Y$5:$Y$404,$A15&"|"&Config!$B$7,'Avaliação'!$N$5:$N$404,">=2")) | T15: =IF($B15="","",COUNTIFS('Avaliação'!$Y$5:$Y$404,$A15&"|"&Config!$B$7,'Avaliação'!$V$5:$V$404,"SEM LASTRO")) | U15: =IF($B15="","",IF(AND($Q15>0,COUNTIFS('Avaliação'!$Y$5:$Y$404,$A15&"|"&Config!$B$7,'Avaliação'!$P$5:$P$404,">=3")>0),$Q15,0)) | V15: =IF($B15="","",IF($U15>0,"Nota sustentada por omissão",IF($T15>0,"Nota sem lastro",IF($J15="","Sem avaliação no ciclo",IF($S15>0,"Calibrar divergência",IF($L15<-0.3,"Abaixo da expectativa",IF($Q15>0,"Negativa não conversada",IF(OR($R15="nunca",$R15>30),"1:1 atrasada","OK")))))))) | W15: =IF(ISNUMBER($F15),$F15*Config!$B$22,0)+IF(ISNUMBER($G15),$G15*Config!$B$23,0)+IF(ISNUMBER($H15),$H15*Config!$B$24,0)+IF(ISNUMBER($I15),$I15*Config!$B$25,0) | X15: =IF(ISNUMBER($F15),Config!$B$22,0)+IF(ISNUMBER($G15),Config!$B$23,0)+IF(ISNUMBER($H15),Config!$B$24,0)+IF(ISNUMBER($I15),Config!$B$25,0)
A16: =IF(Pessoas!$B14="","",Pessoas!$A14) | B16: =IF(Pessoas!$B14="","",Pessoas!$B14) | C16: =IF(Pessoas!$B14="","",Pessoas!$D14) | D16: =IF(Pessoas!$B14="","",Pessoas!$L14) | E16: =IF(Pessoas!$B14="","",Pessoas!$M14) | F16: =IF($B16="","",IFERROR(AVERAGEIFS('Avaliação'!$P$5:$P$404,'Avaliação'!$Z$5:$Z$404,$A16&"|"&Config!$B$7&"|"&Config!$A$22),"")) | G16: =IF($B16="","",IFERROR(AVERAGEIFS('Avaliação'!$P$5:$P$404,'Avaliação'!$Z$5:$Z$404,$A16&"|"&Config!$B$7&"|"&Config!$A$23),"")) | H16: =IF($B16="","",IFERROR(AVERAGEIFS('Avaliação'!$P$5:$P$404,'Avaliação'!$Z$5:$Z$404,$A16&"|"&Config!$B$7&"|"&Config!$A$24),"")) | I16: =IF($B16="","",IFERROR(AVERAGEIFS('Avaliação'!$P$5:$P$404,'Avaliação'!$Z$5:$Z$404,$A16&"|"&Config!$B$7&"|"&Config!$A$25),"")) | J16: =IF($X16=0,"",$W16/$X16) | K16: =IFERROR(INDEX(Config!$B$30:$B$33,MATCH($C16,Config!$A$30:$A$33,0)),"") | L16: =IF(OR($J16="",$K16=""),"",$J16-$K16) | M16: =IF($J16="","",IF($J16<2.5,"Abaixo",IF($J16<3.5,"Atende",IF($J16<=4.2,"Supera","Referência")))) | N16: =IF($B16="","",COUNTIFS('Ocorrências'!$U$5:$U$604,$A16&"|"&Config!$B$7)) | O16: =IF($B16="","",COUNTIFS('Ocorrências'!$U$5:$U$604,$A16&"|"&Config!$B$7,'Ocorrências'!$F$5:$F$604,"Reconhecimento")+COUNTIFS('Ocorrências'!$U$5:$U$604,$A16&"|"&Config!$B$7,'Ocorrências'!$F$5:$F$604,"Positiva")) | P16: =IF($B16="","",COUNTIFS('Ocorrências'!$U$5:$U$604,$A16&"|"&Config!$B$7,'Ocorrências'!$F$5:$F$604,"Ponto de atenção")+COUNTIFS('Ocorrências'!$U$5:$U$604,$A16&"|"&Config!$B$7,'Ocorrências'!$F$5:$F$604,"Incidente")) | Q16: =IF($B16="","",COUNTIFS('Ocorrências'!$U$5:$U$604,$A16&"|"&Config!$B$7,'Ocorrências'!$F$5:$F$604,"Ponto de atenção",'Ocorrências'!$L$5:$L$604,"Não")+COUNTIFS('Ocorrências'!$U$5:$U$604,$A16&"|"&Config!$B$7,'Ocorrências'!$F$5:$F$604,"Incidente",'Ocorrências'!$L$5:$L$604,"Não")) | R16: =IF($B16="","",IF(INDEX(Pessoas!$J$5:$J$64,MATCH($A16,Pessoas!$A$5:$A$64,0))="","nunca",Config!$B$6-INDEX(Pessoas!$J$5:$J$64,MATCH($A16,Pessoas!$A$5:$A$64,0)))) | S16: =IF($B16="","",COUNTIFS('Avaliação'!$Y$5:$Y$404,$A16&"|"&Config!$B$7,'Avaliação'!$N$5:$N$404,">=2")) | T16: =IF($B16="","",COUNTIFS('Avaliação'!$Y$5:$Y$404,$A16&"|"&Config!$B$7,'Avaliação'!$V$5:$V$404,"SEM LASTRO")) | U16: =IF($B16="","",IF(AND($Q16>0,COUNTIFS('Avaliação'!$Y$5:$Y$404,$A16&"|"&Config!$B$7,'Avaliação'!$P$5:$P$404,">=3")>0),$Q16,0)) | V16: =IF($B16="","",IF($U16>0,"Nota sustentada por omissão",IF($T16>0,"Nota sem lastro",IF($J16="","Sem avaliação no ciclo",IF($S16>0,"Calibrar divergência",IF($L16<-0.3,"Abaixo da expectativa",IF($Q16>0,"Negativa não conversada",IF(OR($R16="nunca",$R16>30),"1:1 atrasada","OK")))))))) | W16: =IF(ISNUMBER($F16),$F16*Config!$B$22,0)+IF(ISNUMBER($G16),$G16*Config!$B$23,0)+IF(ISNUMBER($H16),$H16*Config!$B$24,0)+IF(ISNUMBER($I16),$I16*Config!$B$25,0) | X16: =IF(ISNUMBER($F16),Config!$B$22,0)+IF(ISNUMBER($G16),Config!$B$23,0)+IF(ISNUMBER($H16),Config!$B$24,0)+IF(ISNUMBER($I16),Config!$B$25,0)
A17: =IF(Pessoas!$B15="","",Pessoas!$A15) | B17: =IF(Pessoas!$B15="","",Pessoas!$B15) | C17: =IF(Pessoas!$B15="","",Pessoas!$D15) | D17: =IF(Pessoas!$B15="","",Pessoas!$L15) | E17: =IF(Pessoas!$B15="","",Pessoas!$M15) | F17: =IF($B17="","",IFERROR(AVERAGEIFS('Avaliação'!$P$5:$P$404,'Avaliação'!$Z$5:$Z$404,$A17&"|"&Config!$B$7&"|"&Config!$A$22),"")) | G17: =IF($B17="","",IFERROR(AVERAGEIFS('Avaliação'!$P$5:$P$404,'Avaliação'!$Z$5:$Z$404,$A17&"|"&Config!$B$7&"|"&Config!$A$23),"")) | H17: =IF($B17="","",IFERROR(AVERAGEIFS('Avaliação'!$P$5:$P$404,'Avaliação'!$Z$5:$Z$404,$A17&"|"&Config!$B$7&"|"&Config!$A$24),"")) | I17: =IF($B17="","",IFERROR(AVERAGEIFS('Avaliação'!$P$5:$P$404,'Avaliação'!$Z$5:$Z$404,$A17&"|"&Config!$B$7&"|"&Config!$A$25),"")) | J17: =IF($X17=0,"",$W17/$X17) | K17: =IFERROR(INDEX(Config!$B$30:$B$33,MATCH($C17,Config!$A$30:$A$33,0)),"") | L17: =IF(OR($J17="",$K17=""),"",$J17-$K17) | M17: =IF($J17="","",IF($J17<2.5,"Abaixo",IF($J17<3.5,"Atende",IF($J17<=4.2,"Supera","Referência")))) | N17: =IF($B17="","",COUNTIFS('Ocorrências'!$U$5:$U$604,$A17&"|"&Config!$B$7)) | O17: =IF($B17="","",COUNTIFS('Ocorrências'!$U$5:$U$604,$A17&"|"&Config!$B$7,'Ocorrências'!$F$5:$F$604,"Reconhecimento")+COUNTIFS('Ocorrências'!$U$5:$U$604,$A17&"|"&Config!$B$7,'Ocorrências'!$F$5:$F$604,"Positiva")) | P17: =IF($B17="","",COUNTIFS('Ocorrências'!$U$5:$U$604,$A17&"|"&Config!$B$7,'Ocorrências'!$F$5:$F$604,"Ponto de atenção")+COUNTIFS('Ocorrências'!$U$5:$U$604,$A17&"|"&Config!$B$7,'Ocorrências'!$F$5:$F$604,"Incidente")) | Q17: =IF($B17="","",COUNTIFS('Ocorrências'!$U$5:$U$604,$A17&"|"&Config!$B$7,'Ocorrências'!$F$5:$F$604,"Ponto de atenção",'Ocorrências'!$L$5:$L$604,"Não")+COUNTIFS('Ocorrências'!$U$5:$U$604,$A17&"|"&Config!$B$7,'Ocorrências'!$F$5:$F$604,"Incidente",'Ocorrências'!$L$5:$L$604,"Não")) | R17: =IF($B17="","",IF(INDEX(Pessoas!$J$5:$J$64,MATCH($A17,Pessoas!$A$5:$A$64,0))="","nunca",Config!$B$6-INDEX(Pessoas!$J$5:$J$64,MATCH($A17,Pessoas!$A$5:$A$64,0)))) | S17: =IF($B17="","",COUNTIFS('Avaliação'!$Y$5:$Y$404,$A17&"|"&Config!$B$7,'Avaliação'!$N$5:$N$404,">=2")) | T17: =IF($B17="","",COUNTIFS('Avaliação'!$Y$5:$Y$404,$A17&"|"&Config!$B$7,'Avaliação'!$V$5:$V$404,"SEM LASTRO")) | U17: =IF($B17="","",IF(AND($Q17>0,COUNTIFS('Avaliação'!$Y$5:$Y$404,$A17&"|"&Config!$B$7,'Avaliação'!$P$5:$P$404,">=3")>0),$Q17,0)) | V17: =IF($B17="","",IF($U17>0,"Nota sustentada por omissão",IF($T17>0,"Nota sem lastro",IF($J17="","Sem avaliação no ciclo",IF($S17>0,"Calibrar divergência",IF($L17<-0.3,"Abaixo da expectativa",IF($Q17>0,"Negativa não conversada",IF(OR($R17="nunca",$R17>30),"1:1 atrasada","OK")))))))) | W17: =IF(ISNUMBER($F17),$F17*Config!$B$22,0)+IF(ISNUMBER($G17),$G17*Config!$B$23,0)+IF(ISNUMBER($H17),$H17*Config!$B$24,0)+IF(ISNUMBER($I17),$I17*Config!$B$25,0) | X17: =IF(ISNUMBER($F17),Config!$B$22,0)+IF(ISNUMBER($G17),Config!$B$23,0)+IF(ISNUMBER($H17),Config!$B$24,0)+IF(ISNUMBER($I17),Config!$B$25,0)
A18: =IF(Pessoas!$B16="","",Pessoas!$A16) | B18: =IF(Pessoas!$B16="","",Pessoas!$B16) | C18: =IF(Pessoas!$B16="","",Pessoas!$D16) | D18: =IF(Pessoas!$B16="","",Pessoas!$L16) | E18: =IF(Pessoas!$B16="","",Pessoas!$M16) | F18: =IF($B18="","",IFERROR(AVERAGEIFS('Avaliação'!$P$5:$P$404,'Avaliação'!$Z$5:$Z$404,$A18&"|"&Config!$B$7&"|"&Config!$A$22),"")) | G18: =IF($B18="","",IFERROR(AVERAGEIFS('Avaliação'!$P$5:$P$404,'Avaliação'!$Z$5:$Z$404,$A18&"|"&Config!$B$7&"|"&Config!$A$23),"")) | H18: =IF($B18="","",IFERROR(AVERAGEIFS('Avaliação'!$P$5:$P$404,'Avaliação'!$Z$5:$Z$404,$A18&"|"&Config!$B$7&"|"&Config!$A$24),"")) | I18: =IF($B18="","",IFERROR(AVERAGEIFS('Avaliação'!$P$5:$P$404,'Avaliação'!$Z$5:$Z$404,$A18&"|"&Config!$B$7&"|"&Config!$A$25),"")) | J18: =IF($X18=0,"",$W18/$X18) | K18: =IFERROR(INDEX(Config!$B$30:$B$33,MATCH($C18,Config!$A$30:$A$33,0)),"") | L18: =IF(OR($J18="",$K18=""),"",$J18-$K18) | M18: =IF($J18="","",IF($J18<2.5,"Abaixo",IF($J18<3.5,"Atende",IF($J18<=4.2,"Supera","Referência")))) | N18: =IF($B18="","",COUNTIFS('Ocorrências'!$U$5:$U$604,$A18&"|"&Config!$B$7)) | O18: =IF($B18="","",COUNTIFS('Ocorrências'!$U$5:$U$604,$A18&"|"&Config!$B$7,'Ocorrências'!$F$5:$F$604,"Reconhecimento")+COUNTIFS('Ocorrências'!$U$5:$U$604,$A18&"|"&Config!$B$7,'Ocorrências'!$F$5:$F$604,"Positiva")) | P18: =IF($B18="","",COUNTIFS('Ocorrências'!$U$5:$U$604,$A18&"|"&Config!$B$7,'Ocorrências'!$F$5:$F$604,"Ponto de atenção")+COUNTIFS('Ocorrências'!$U$5:$U$604,$A18&"|"&Config!$B$7,'Ocorrências'!$F$5:$F$604,"Incidente")) | Q18: =IF($B18="","",COUNTIFS('Ocorrências'!$U$5:$U$604,$A18&"|"&Config!$B$7,'Ocorrências'!$F$5:$F$604,"Ponto de atenção",'Ocorrências'!$L$5:$L$604,"Não")+COUNTIFS('Ocorrências'!$U$5:$U$604,$A18&"|"&Config!$B$7,'Ocorrências'!$F$5:$F$604,"Incidente",'Ocorrências'!$L$5:$L$604,"Não")) | R18: =IF($B18="","",IF(INDEX(Pessoas!$J$5:$J$64,MATCH($A18,Pessoas!$A$5:$A$64,0))="","nunca",Config!$B$6-INDEX(Pessoas!$J$5:$J$64,MATCH($A18,Pessoas!$A$5:$A$64,0)))) | S18: =IF($B18="","",COUNTIFS('Avaliação'!$Y$5:$Y$404,$A18&"|"&Config!$B$7,'Avaliação'!$N$5:$N$404,">=2")) | T18: =IF($B18="","",COUNTIFS('Avaliação'!$Y$5:$Y$404,$A18&"|"&Config!$B$7,'Avaliação'!$V$5:$V$404,"SEM LASTRO")) | U18: =IF($B18="","",IF(AND($Q18>0,COUNTIFS('Avaliação'!$Y$5:$Y$404,$A18&"|"&Config!$B$7,'Avaliação'!$P$5:$P$404,">=3")>0),$Q18,0)) | V18: =IF($B18="","",IF($U18>0,"Nota sustentada por omissão",IF($T18>0,"Nota sem lastro",IF($J18="","Sem avaliação no ciclo",IF($S18>0,"Calibrar divergência",IF($L18<-0.3,"Abaixo da expectativa",IF($Q18>0,"Negativa não conversada",IF(OR($R18="nunca",$R18>30),"1:1 atrasada","OK")))))))) | W18: =IF(ISNUMBER($F18),$F18*Config!$B$22,0)+IF(ISNUMBER($G18),$G18*Config!$B$23,0)+IF(ISNUMBER($H18),$H18*Config!$B$24,0)+IF(ISNUMBER($I18),$I18*Config!$B$25,0) | X18: =IF(ISNUMBER($F18),Config!$B$22,0)+IF(ISNUMBER($G18),Config!$B$23,0)+IF(ISNUMBER($H18),Config!$B$24,0)+IF(ISNUMBER($I18),Config!$B$25,0)
... A64: =IF(Pessoas!$B62="","",Pessoas!$A62) | B64: =IF(Pessoas!$B62="","",Pessoas!$B62) | C64: =IF(Pessoas!$B62="","",Pessoas!$D62) | D64: =IF(Pessoas!$B62="","",Pessoas!$L62) | E64: =IF(Pessoas!$B62="","",Pessoas!$M62) | F64: =IF($B64="","",IFERROR(AVERAGEIFS('Avaliação'!$P$5:$P$404,'Avaliação'!$Z$5:$Z$404,$A64&"|"&Config!$B$7&"|"&Config!$A$22),"")) | G64: =IF($B64="","",IFERROR(AVERAGEIFS('Avaliação'!$P$5:$P$404,'Avaliação'!$Z$5:$Z$404,$A64&"|"&Config!$B$7&"|"&Config!$A$23),"")) | H64: =IF($B64="","",IFERROR(AVERAGEIFS('Avaliação'!$P$5:$P$404,'Avaliação'!$Z$5:$Z$404,$A64&"|"&Config!$B$7&"|"&Config!$A$24),"")) | I64: =IF($B64="","",IFERROR(AVERAGEIFS('Avaliação'!$P$5:$P$404,'Avaliação'!$Z$5:$Z$404,$A64&"|"&Config!$B$7&"|"&Config!$A$25),"")) | J64: =IF($X64=0,"",$W64/$X64) | K64: =IFERROR(INDEX(Config!$B$30:$B$33,MATCH($C64,Config!$A$30:$A$33,0)),"") | L64: =IF(OR($J64="",$K64=""),"",$J64-$K64) | M64: =IF($J64="","",IF($J64<2.5,"Abaixo",IF($J64<3.5,"Atende",IF($J64<=4.2,"Supera","Referência")))) | N64: =IF($B64="","",COUNTIFS('Ocorrências'!$U$5:$U$604,$A64&"|"&Config!$B$7)) | O64: =IF($B64="","",COUNTIFS('Ocorrências'!$U$5:$U$604,$A64&"|"&Config!$B$7,'Ocorrências'!$F$5:$F$604,"Reconhecimento")+COUNTIFS('Ocorrências'!$U$5:$U$604,$A64&"|"&Config!$B$7,'Ocorrências'!$F$5:$F$604,"Positiva")) | P64: =IF($B64="","",COUNTIFS('Ocorrências'!$U$5:$U$604,$A64&"|"&Config!$B$7,'Ocorrências'!$F$5:$F$604,"Ponto de atenção")+COUNTIFS('Ocorrências'!$U$5:$U$604,$A64&"|"&Config!$B$7,'Ocorrências'!$F$5:$F$604,"Incidente")) | Q64: =IF($B64="","",COUNTIFS('Ocorrências'!$U$5:$U$604,$A64&"|"&Config!$B$7,'Ocorrências'!$F$5:$F$604,"Ponto de atenção",'Ocorrências'!$L$5:$L$604,"Não")+COUNTIFS('Ocorrências'!$U$5:$U$604,$A64&"|"&Config!$B$7,'Ocorrências'!$F$5:$F$604,"Incidente",'Ocorrências'!$L$5:$L$604,"Não")) | R64: =IF($B64="","",IF(INDEX(Pessoas!$J$5:$J$64,MATCH($A64,Pessoas!$A$5:$A$64,0))="","nunca",Config!$B$6-INDEX(Pessoas!$J$5:$J$64,MATCH($A64,Pessoas!$A$5:$A$64,0)))) | S64: =IF($B64="","",COUNTIFS('Avaliação'!$Y$5:$Y$404,$A64&"|"&Config!$B$7,'Avaliação'!$N$5:$N$404,">=2")) | T64: =IF($B64="","",COUNTIFS('Avaliação'!$Y$5:$Y$404,$A64&"|"&Config!$B$7,'Avaliação'!$V$5:$V$404,"SEM LASTRO")) | U64: =IF($B64="","",IF(AND($Q64>0,COUNTIFS('Avaliação'!$Y$5:$Y$404,$A64&"|"&Config!$B$7,'Avaliação'!$P$5:$P$404,">=3")>0),$Q64,0)) | V64: =IF($B64="","",IF($U64>0,"Nota sustentada por omissão",IF($T64>0,"Nota sem lastro",IF($J64="","Sem avaliação no ciclo",IF($S64>0,"Calibrar divergência",IF($L64<-0.3,"Abaixo da expectativa",IF($Q64>0,"Negativa não conversada",IF(OR($R64="nunca",$R64>30),"1:1 atrasada","OK")))))))) | W64: =IF(ISNUMBER($F64),$F64*Config!$B$22,0)+IF(ISNUMBER($G64),$G64*Config!$B$23,0)+IF(ISNUMBER($H64),$H64*Config!$B$24,0)+IF(ISNUMBER($I64),$I64*Config!$B$25,0) | X64: =IF(ISNUMBER($F64),Config!$B$22,0)+IF(ISNUMBER($G64),Config!$B$23,0)+IF(ISNUMBER($H64),Config!$B$24,0)+IF(ISNUMBER($I64),Config!$B$25,0)

Sheet Ocorrências
A1: Ocorrências — o registro contínuo
A2: Bloco rápido (A–J): alvo de 45 segundos, um único campo de texto. Bloco de sinalização (K–S): só para Ponto de atenção e Incidente.
A3: O FATO não aceita adjetivo de personalidade. "Subiu hotfix sem aprovação na sexta 18h" ✔ · "É descuidado" ✘. Nada de saúde, vida pessoal, motivo de ausência ou conduta — conduta vai para o RH, em processo próprio.
A4: Data do fato | B4: Pessoa | C4: ID_PESSOA | D4: Registrado por | E4: Papel do autor | F4: Tipo | G4: Competência | H4: Fato observável | I4: Impacto | J4: Confidenc. | K4: Consequência observada | L4: Comunicado? | M4: Data da comunicação | N4: Quem comunicou | O4: Expectativa declarada | P4: Prazo dado | Q4: Reavaliação em | R4: Reação da pessoa | S4: Desfecho | T4: Idx ciclo | U4: chave ID|ciclo | V4: chave ID|ciclo|comp | W4: Registro válido? | X4: Viaja no handover? | Y4: novo avaliador | Z4: Exibição | AA4: negativa comunicada | AB4: seq 1a1
A5: 46212 | B5: Ana Ribeiro | C5: =IFERROR(INDEX(Pessoas!$A$5:$A$64,MATCH($B5,Pessoas!$B$5:$B$64,0)),"") | D5: Rafael Souza | E5: Líder Técnico | F5: Positiva | G5: Comunicação e colaboração | H5: No PR #812 apontou uma condição de corrida no resgate de cupom antes do merge, com o trecho e a sugestão de UPDATE atômico. | I5: Entrega | J5: Squad | Q5: =IF(OR($M5="",$P5=""),"",$M5+IF($P5="7 dias",7,IF($P5="14 dias",14,90))) | T5: =IF($A5="","",YEAR($A5)*4+ROUNDUP(MONTH($A5)/3,0)) | U5: =IF($C5="","",$C5&"|"&$T5) | V5: =IF($C5="","",$C5&"|"&$T5&"|"&$G5) | W5: =IF($A5="","",IF(OR($B5="",$F5="",$G5="",$H5="",$I5=""),"Faltam campos básicos",IF(AND(OR($F5="Ponto de atenção",$F5="Incidente"),OR($K5="",$L5="",$O5="",$P5="")),"Faltam campos de sinalização","OK"))) | X5: =IF($A5="","",IF(AND(OR($F5="Ponto de atenção",$F5="Incidente"),$L5<>"Sim"),"Não",IF(AND($S5="",$W5<>"OK"),"Não","Sim"))) | Y5: =IF($C5="",0,IF(COUNTIFS($C$5:$C5,$C5,$D$5:$D5,$D5)=1,1,0)) | Z5: =IF($A5="","",IF(Config!$B$7-$T5>2,"Arquivada",IF(Config!$B$7-$T5>0,"Histórico","Ativa"))) | AA5: =IF($A5="",0,IF(AND(OR($F5="Ponto de atenção",$F5="Incidente"),$L5="Sim"),1,0)) | AB5: =IF(OR($C5="",$C5<>'1a1'!$B$4,$T5<>Config!$B$7),"",COUNTIFS($C$5:$C5,'1a1'!$B$4,$T$5:$T5,Config!$B$7))
A6: 46253 | B6: Ana Ribeiro | C6: =IFERROR(INDEX(Pessoas!$A$5:$A$64,MATCH($B6,Pessoas!$B$5:$B$64,0)),"") | D6: Rafael Souza | E6: Líder Técnico | F6: Ponto de atenção | G6: Qualidade da entrega | H6: PR #857 voltou em 3 rodadas: nas duas primeiras faltava teste do caminho de erro na rota de resgate. | I6: Entrega | J6: Squad | K6: Atrasou o merge em 2 dias e consumiu 3 rodadas de review do time. | L6: Sim | M6: 46254 | N6: Rafael Souza | O6: Incluir teste de caminho de erro antes de abrir o PR, nos próximos 3 PRs de rota nova. | P6: 1 ciclo | Q6: =IF(OR($M6="",$P6=""),"",$M6+IF($P6="7 dias",7,IF($P6="14 dias",14,90))) | R6: Em acompanhamento | T6: =IF($A6="","",YEAR($A6)*4+ROUNDUP(MONTH($A6)/3,0)) | U6: =IF($C6="","",$C6&"|"&$T6) | V6: =IF($C6="","",$C6&"|"&$T6&"|"&$G6) | W6: =IF($A6="","",IF(OR($B6="",$F6="",$G6="",$H6="",$I6=""),"Faltam campos básicos",IF(AND(OR($F6="Ponto de atenção",$F6="Incidente"),OR($K6="",$L6="",$O6="",$P6="")),"Faltam campos de sinalização","OK"))) | X6: =IF($A6="","",IF(AND(OR($F6="Ponto de atenção",$F6="Incidente"),$L6<>"Sim"),"Não",IF(AND($S6="",$W6<>"OK"),"Não","Sim"))) | Y6: =IF($C6="",0,IF(COUNTIFS($C$5:$C6,$C6,$D$5:$D6,$D6)=1,1,0)) | Z6: =IF($A6="","",IF(Config!$B$7-$T6>2,"Arquivada",IF(Config!$B$7-$T6>0,"Histórico","Ativa"))) | AA6: =IF($A6="",0,IF(AND(OR($F6="Ponto de atenção",$F6="Incidente"),$L6="Sim"),1,0)) | AB6: =IF(OR($C6="",$C6<>'1a1'!$B$4,$T6<>Config!$B$7),"",COUNTIFS($C$5:$C6,'1a1'!$B$4,$T$5:$T6,Config!$B$7))
A7: 46225 | B7: Bruno Tavares | C7: =IFERROR(INDEX(Pessoas!$A$5:$A$64,MATCH($B7,Pessoas!$B$5:$B$64,0)),"") | D7: Marcos Lima | E7: GP | F7: Ponto de atenção | G7: Previsibilidade | H7: Card CB-118 ficou 4 dias sem atualização e o bloqueio, falta de credencial de homologação, só foi comunicado na review. | I7: Entrega | J7: Squad | K7: A sprint fechou com o item em carry over e o PO replanejou a demo com o cliente em cima da hora. | L7: Sim | M7: 46226 | N7: Marcos Lima | O7: Comunicar bloqueio na daily do mesmo dia em que ele ocorre. | P7: 14 dias | Q7: =IF(OR($M7="",$P7=""),"",$M7+IF($P7="7 dias",7,IF($P7="14 dias",14,90))) | R7: Encerrado — comportamento mudou | T7: =IF($A7="","",YEAR($A7)*4+ROUNDUP(MONTH($A7)/3,0)) | U7: =IF($C7="","",$C7&"|"&$T7) | V7: =IF($C7="","",$C7&"|"&$T7&"|"&$G7) | W7: =IF($A7="","",IF(OR($B7="",$F7="",$G7="",$H7="",$I7=""),"Faltam campos básicos",IF(AND(OR($F7="Ponto de atenção",$F7="Incidente"),OR($K7="",$L7="",$O7="",$P7="")),"Faltam campos de sinalização","OK"))) | X7: =IF($A7="","",IF(AND(OR($F7="Ponto de atenção",$F7="Incidente"),$L7<>"Sim"),"Não",IF(AND($S7="",$W7<>"OK"),"Não","Sim"))) | Y7: =IF($C7="",0,IF(COUNTIFS($C$5:$C7,$C7,$D$5:$D7,$D7)=1,1,0)) | Z7: =IF($A7="","",IF(Config!$B$7-$T7>2,"Arquivada",IF(Config!$B$7-$T7>0,"Histórico","Ativa"))) | AA7: =IF($A7="",0,IF(AND(OR($F7="Ponto de atenção",$F7="Incidente"),$L7="Sim"),1,0)) | AB7: =IF(OR($C7="",$C7<>'1a1'!$B$4,$T7<>Config!$B$7),"",COUNTIFS($C$5:$C7,'1a1'!$B$4,$T$5:$T7,Config!$B$7))
A8: 46238 | B8: Bruno Tavares | C8: =IFERROR(INDEX(Pessoas!$A$5:$A$64,MATCH($B8,Pessoas!$B$5:$B$64,0)),"") | D8: Marcos Lima | E8: GP | F8: Positiva | G8: Comunicação e colaboração | H8: Na daily de 04/08 avisou no mesmo dia que a integração de pagamento estava fora do ar, com print do erro e a alternativa de mockar. | I8: Equipe | J8: Squad | Q8: =IF(OR($M8="",$P8=""),"",$M8+IF($P8="7 dias",7,IF($P8="14 dias",14,90))) | T8: =IF($A8="","",YEAR($A8)*4+ROUNDUP(MONTH($A8)/3,0)) | U8: =IF($C8="","",$C8&"|"&$T8) | V8: =IF($C8="","",$C8&"|"&$T8&"|"&$G8) | W8: =IF($A8="","",IF(OR($B8="",$F8="",$G8="",$H8="",$I8=""),"Faltam campos básicos",IF(AND(OR($F8="Ponto de atenção",$F8="Incidente"),OR($K8="",$L8="",$O8="",$P8="")),"Faltam campos de sinalização","OK"))) | X8: =IF($A8="","",IF(AND(OR($F8="Ponto de atenção",$F8="Incidente"),$L8<>"Sim"),"Não",IF(AND($S8="",$W8<>"OK"),"Não","Sim"))) | Y8: =IF($C8="",0,IF(COUNTIFS($C$5:$C8,$C8,$D$5:$D8,$D8)=1,1,0)) | Z8: =IF($A8="","",IF(Config!$B$7-$T8>2,"Arquivada",IF(Config!$B$7-$T8>0,"Histórico","Ativa"))) | AA8: =IF($A8="",0,IF(AND(OR($F8="Ponto de atenção",$F8="Incidente"),$L8="Sim"),1,0)) | AB8: =IF(OR($C8="",$C8<>'1a1'!$B$4,$T8<>Config!$B$7),"",COUNTIFS($C$5:$C8,'1a1'!$B$4,$T$5:$T8,Config!$B$7))
A9: 46259 | B9: Carla Nunes | C9: =IFERROR(INDEX(Pessoas!$A$5:$A$64,MATCH($B9,Pessoas!$B$5:$B$64,0)),"") | D9: Rafael Souza | E9: Líder Técnico | F9: Reconhecimento | G9: Autonomia e ownership | H9: Escreveu a ADR-07 sobre o advisory lock no cooldown e conduziu a sessão de 40 min com as squads Alfa e Beta. | I9: Equipe | J9: Squad | Q9: =IF(OR($M9="",$P9=""),"",$M9+IF($P9="7 dias",7,IF($P9="14 dias",14,90))) | T9: =IF($A9="","",YEAR($A9)*4+ROUNDUP(MONTH($A9)/3,0)) | U9: =IF($C9="","",$C9&"|"&$T9) | V9: =IF($C9="","",$C9&"|"&$T9&"|"&$G9) | W9: =IF($A9="","",IF(OR($B9="",$F9="",$G9="",$H9="",$I9=""),"Faltam campos básicos",IF(AND(OR($F9="Ponto de atenção",$F9="Incidente"),OR($K9="",$L9="",$O9="",$P9="")),"Faltam campos de sinalização","OK"))) | X9: =IF($A9="","",IF(AND(OR($F9="Ponto de atenção",$F9="Incidente"),$L9<>"Sim"),"Não",IF(AND($S9="",$W9<>"OK"),"Não","Sim"))) | Y9: =IF($C9="",0,IF(COUNTIFS($C$5:$C9,$C9,$D$5:$D9,$D9)=1,1,0)) | Z9: =IF($A9="","",IF(Config!$B$7-$T9>2,"Arquivada",IF(Config!$B$7-$T9>0,"Histórico","Ativa"))) | AA9: =IF($A9="",0,IF(AND(OR($F9="Ponto de atenção",$F9="Incidente"),$L9="Sim"),1,0)) | AB9: =IF(OR($C9="",$C9<>'1a1'!$B$4,$T9<>Config!$B$7),"",COUNTIFS($C$5:$C9,'1a1'!$B$4,$T$5:$T9,Config!$B$7))
A10: 46246 | B10: Carla Nunes | C10: =IFERROR(INDEX(Pessoas!$A$5:$A$64,MATCH($B10,Pessoas!$B$5:$B$64,0)),"") | D10: Marcos Lima | E10: GP | F10: Contexto atenuante | G10: Previsibilidade | H10: Assumiu o on-call do Contrato B por duas semanas cobrindo férias, além dos 50% de alocação no Motor de Cobrança. | I10: Entrega | J10: Squad | Q10: =IF(OR($M10="",$P10=""),"",$M10+IF($P10="7 dias",7,IF($P10="14 dias",14,90))) | T10: =IF($A10="","",YEAR($A10)*4+ROUNDUP(MONTH($A10)/3,0)) | U10: =IF($C10="","",$C10&"|"&$T10) | V10: =IF($C10="","",$C10&"|"&$T10&"|"&$G10) | W10: =IF($A10="","",IF(OR($B10="",$F10="",$G10="",$H10="",$I10=""),"Faltam campos básicos",IF(AND(OR($F10="Ponto de atenção",$F10="Incidente"),OR($K10="",$L10="",$O10="",$P10="")),"Faltam campos de sinalização","OK"))) | X10: =IF($A10="","",IF(AND(OR($F10="Ponto de atenção",$F10="Incidente"),$L10<>"Sim"),"Não",IF(AND($S10="",$W10<>"OK"),"Não","Sim"))) | Y10: =IF($C10="",0,IF(COUNTIFS($C$5:$C10,$C10,$D$5:$D10,$D10)=1,1,0)) | Z10: =IF($A10="","",IF(Config!$B$7-$T10>2,"Arquivada",IF(Config!$B$7-$T10>0,"Histórico","Ativa"))) | AA10: =IF($A10="",0,IF(AND(OR($F10="Ponto de atenção",$F10="Incidente"),$L10="Sim"),1,0)) | AB10: =IF(OR($C10="",$C10<>'1a1'!$B$4,$T10<>Config!$B$7),"",COUNTIFS($C$5:$C10,'1a1'!$B$4,$T$5:$T10,Config!$B$7))
C11: =IFERROR(INDEX(Pessoas!$A$5:$A$64,MATCH($B11,Pessoas!$B$5:$B$64,0)),"") | Q11: =IF(OR($M11="",$P11=""),"",$M11+IF($P11="7 dias",7,IF($P11="14 dias",14,90))) | T11: =IF($A11="","",YEAR($A11)*4+ROUNDUP(MONTH($A11)/3,0)) | U11: =IF($C11="","",$C11&"|"&$T11) | V11: =IF($C11="","",$C11&"|"&$T11&"|"&$G11) | W11: =IF($A11="","",IF(OR($B11="",$F11="",$G11="",$H11="",$I11=""),"Faltam campos básicos",IF(AND(OR($F11="Ponto de atenção",$F11="Incidente"),OR($K11="",$L11="",$O11="",$P11="")),"Faltam campos de sinalização","OK"))) | X11: =IF($A11="","",IF(AND(OR($F11="Ponto de atenção",$F11="Incidente"),$L11<>"Sim"),"Não",IF(AND($S11="",$W11<>"OK"),"Não","Sim"))) | Y11: =IF($C11="",0,IF(COUNTIFS($C$5:$C11,$C11,$D$5:$D11,$D11)=1,1,0)) | Z11: =IF($A11="","",IF(Config!$B$7-$T11>2,"Arquivada",IF(Config!$B$7-$T11>0,"Histórico","Ativa"))) | AA11: =IF($A11="",0,IF(AND(OR($F11="Ponto de atenção",$F11="Incidente"),$L11="Sim"),1,0)) | AB11: =IF(OR($C11="",$C11<>'1a1'!$B$4,$T11<>Config!$B$7),"",COUNTIFS($C$5:$C11,'1a1'!$B$4,$T$5:$T11,Config!$B$7))
C12: =IFERROR(INDEX(Pessoas!$A$5:$A$64,MATCH($B12,Pessoas!$B$5:$B$64,0)),"") | Q12: =IF(OR($M12="",$P12=""),"",$M12+IF($P12="7 dias",7,IF($P12="14 dias",14,90))) | T12: =IF($A12="","",YEAR($A12)*4+ROUNDUP(MONTH($A12)/3,0)) | U12: =IF($C12="","",$C12&"|"&$T12) | V12: =IF($C12="","",$C12&"|"&$T12&"|"&$G12) | W12: =IF($A12="","",IF(OR($B12="",$F12="",$G12="",$H12="",$I12=""),"Faltam campos básicos",IF(AND(OR($F12="Ponto de atenção",$F12="Incidente"),OR($K12="",$L12="",$O12="",$P12="")),"Faltam campos de sinalização","OK"))) | X12: =IF($A12="","",IF(AND(OR($F12="Ponto de atenção",$F12="Incidente"),$L12<>"Sim"),"Não",IF(AND($S12="",$W12<>"OK"),"Não","Sim"))) | Y12: =IF($C12="",0,IF(COUNTIFS($C$5:$C12,$C12,$D$5:$D12,$D12)=1,1,0)) | Z12: =IF($A12="","",IF(Config!$B$7-$T12>2,"Arquivada",IF(Config!$B$7-$T12>0,"Histórico","Ativa"))) | AA12: =IF($A12="",0,IF(AND(OR($F12="Ponto de atenção",$F12="Incidente"),$L12="Sim"),1,0)) | AB12: =IF(OR($C12="",$C12<>'1a1'!$B$4,$T12<>Config!$B$7),"",COUNTIFS($C$5:$C12,'1a1'!$B$4,$T$5:$T12,Config!$B$7))
C13: =IFERROR(INDEX(Pessoas!$A$5:$A$64,MATCH($B13,Pessoas!$B$5:$B$64,0)),"") | Q13: =IF(OR($M13="",$P13=""),"",$M13+IF($P13="7 dias",7,IF($P13="14 dias",14,90))) | T13: =IF($A13="","",YEAR($A13)*4+ROUNDUP(MONTH($A13)/3,0)) | U13: =IF($C13="","",$C13&"|"&$T13) | V13: =IF($C13="","",$C13&"|"&$T13&"|"&$G13) | W13: =IF($A13="","",IF(OR($B13="",$F13="",$G13="",$H13="",$I13=""),"Faltam campos básicos",IF(AND(OR($F13="Ponto de atenção",$F13="Incidente"),OR($K13="",$L13="",$O13="",$P13="")),"Faltam campos de sinalização","OK"))) | X13: =IF($A13="","",IF(AND(OR($F13="Ponto de atenção",$F13="Incidente"),$L13<>"Sim"),"Não",IF(AND($S13="",$W13<>"OK"),"Não","Sim"))) | Y13: =IF($C13="",0,IF(COUNTIFS($C$5:$C13,$C13,$D$5:$D13,$D13)=1,1,0)) | Z13: =IF($A13="","",IF(Config!$B$7-$T13>2,"Arquivada",IF(Config!$B$7-$T13>0,"Histórico","Ativa"))) | AA13: =IF($A13="",0,IF(AND(OR($F13="Ponto de atenção",$F13="Incidente"),$L13="Sim"),1,0)) | AB13: =IF(OR($C13="",$C13<>'1a1'!$B$4,$T13<>Config!$B$7),"",COUNTIFS($C$5:$C13,'1a1'!$B$4,$T$5:$T13,Config!$B$7))
C14: =IFERROR(INDEX(Pessoas!$A$5:$A$64,MATCH($B14,Pessoas!$B$5:$B$64,0)),"") | Q14: =IF(OR($M14="",$P14=""),"",$M14+IF($P14="7 dias",7,IF($P14="14 dias",14,90))) | T14: =IF($A14="","",YEAR($A14)*4+ROUNDUP(MONTH($A14)/3,0)) | U14: =IF($C14="","",$C14&"|"&$T14) | V14: =IF($C14="","",$C14&"|"&$T14&"|"&$G14) | W14: =IF($A14="","",IF(OR($B14="",$F14="",$G14="",$H14="",$I14=""),"Faltam campos básicos",IF(AND(OR($F14="Ponto de atenção",$F14="Incidente"),OR($K14="",$L14="",$O14="",$P14="")),"Faltam campos de sinalização","OK"))) | X14: =IF($A14="","",IF(AND(OR($F14="Ponto de atenção",$F14="Incidente"),$L14<>"Sim"),"Não",IF(AND($S14="",$W14<>"OK"),"Não","Sim"))) | Y14: =IF($C14="",0,IF(COUNTIFS($C$5:$C14,$C14,$D$5:$D14,$D14)=1,1,0)) | Z14: =IF($A14="","",IF(Config!$B$7-$T14>2,"Arquivada",IF(Config!$B$7-$T14>0,"Histórico","Ativa"))) | AA14: =IF($A14="",0,IF(AND(OR($F14="Ponto de atenção",$F14="Incidente"),$L14="Sim"),1,0)) | AB14: =IF(OR($C14="",$C14<>'1a1'!$B$4,$T14<>Config!$B$7),"",COUNTIFS($C$5:$C14,'1a1'!$B$4,$T$5:$T14,Config!$B$7))
C15: =IFERROR(INDEX(Pessoas!$A$5:$A$64,MATCH($B15,Pessoas!$B$5:$B$64,0)),"") | Q15: =IF(OR($M15="",$P15=""),"",$M15+IF($P15="7 dias",7,IF($P15="14 dias",14,90))) | T15: =IF($A15="","",YEAR($A15)*4+ROUNDUP(MONTH($A15)/3,0)) | U15: =IF($C15="","",$C15&"|"&$T15) | V15: =IF($C15="","",$C15&"|"&$T15&"|"&$G15) | W15: =IF($A15="","",IF(OR($B15="",$F15="",$G15="",$H15="",$I15=""),"Faltam campos básicos",IF(AND(OR($F15="Ponto de atenção",$F15="Incidente"),OR($K15="",$L15="",$O15="",$P15="")),"Faltam campos de sinalização","OK"))) | X15: =IF($A15="","",IF(AND(OR($F15="Ponto de atenção",$F15="Incidente"),$L15<>"Sim"),"Não",IF(AND($S15="",$W15<>"OK"),"Não","Sim"))) | Y15: =IF($C15="",0,IF(COUNTIFS($C$5:$C15,$C15,$D$5:$D15,$D15)=1,1,0)) | Z15: =IF($A15="","",IF(Config!$B$7-$T15>2,"Arquivada",IF(Config!$B$7-$T15>0,"Histórico","Ativa"))) | AA15: =IF($A15="",0,IF(AND(OR($F15="Ponto de atenção",$F15="Incidente"),$L15="Sim"),1,0)) | AB15: =IF(OR($C15="",$C15<>'1a1'!$B$4,$T15<>Config!$B$7),"",COUNTIFS($C$5:$C15,'1a1'!$B$4,$T$5:$T15,Config!$B$7))
C16: =IFERROR(INDEX(Pessoas!$A$5:$A$64,MATCH($B16,Pessoas!$B$5:$B$64,0)),"") | Q16: =IF(OR($M16="",$P16=""),"",$M16+IF($P16="7 dias",7,IF($P16="14 dias",14,90))) | T16: =IF($A16="","",YEAR($A16)*4+ROUNDUP(MONTH($A16)/3,0)) | U16: =IF($C16="","",$C16&"|"&$T16) | V16: =IF($C16="","",$C16&"|"&$T16&"|"&$G16) | W16: =IF($A16="","",IF(OR($B16="",$F16="",$G16="",$H16="",$I16=""),"Faltam campos básicos",IF(AND(OR($F16="Ponto de atenção",$F16="Incidente"),OR($K16="",$L16="",$O16="",$P16="")),"Faltam campos de sinalização","OK"))) | X16: =IF($A16="","",IF(AND(OR($F16="Ponto de atenção",$F16="Incidente"),$L16<>"Sim"),"Não",IF(AND($S16="",$W16<>"OK"),"Não","Sim"))) | Y16: =IF($C16="",0,IF(COUNTIFS($C$5:$C16,$C16,$D$5:$D16,$D16)=1,1,0)) | Z16: =IF($A16="","",IF(Config!$B$7-$T16>2,"Arquivada",IF(Config!$B$7-$T16>0,"Histórico","Ativa"))) | AA16: =IF($A16="",0,IF(AND(OR($F16="Ponto de atenção",$F16="Incidente"),$L16="Sim"),1,0)) | AB16: =IF(OR($C16="",$C16<>'1a1'!$B$4,$T16<>Config!$B$7),"",COUNTIFS($C$5:$C16,'1a1'!$B$4,$T$5:$T16,Config!$B$7))
C17: =IFERROR(INDEX(Pessoas!$A$5:$A$64,MATCH($B17,Pessoas!$B$5:$B$64,0)),"") | Q17: =IF(OR($M17="",$P17=""),"",$M17+IF($P17="7 dias",7,IF($P17="14 dias",14,90))) | T17: =IF($A17="","",YEAR($A17)*4+ROUNDUP(MONTH($A17)/3,0)) | U17: =IF($C17="","",$C17&"|"&$T17) | V17: =IF($C17="","",$C17&"|"&$T17&"|"&$G17) | W17: =IF($A17="","",IF(OR($B17="",$F17="",$G17="",$H17="",$I17=""),"Faltam campos básicos",IF(AND(OR($F17="Ponto de atenção",$F17="Incidente"),OR($K17="",$L17="",$O17="",$P17="")),"Faltam campos de sinalização","OK"))) | X17: =IF($A17="","",IF(AND(OR($F17="Ponto de atenção",$F17="Incidente"),$L17<>"Sim"),"Não",IF(AND($S17="",$W17<>"OK"),"Não","Sim"))) | Y17: =IF($C17="",0,IF(COUNTIFS($C$5:$C17,$C17,$D$5:$D17,$D17)=1,1,0)) | Z17: =IF($A17="","",IF(Config!$B$7-$T17>2,"Arquivada",IF(Config!$B$7-$T17>0,"Histórico","Ativa"))) | AA17: =IF($A17="",0,IF(AND(OR($F17="Ponto de atenção",$F17="Incidente"),$L17="Sim"),1,0)) | AB17: =IF(OR($C17="",$C17<>'1a1'!$B$4,$T17<>Config!$B$7),"",COUNTIFS($C$5:$C17,'1a1'!$B$4,$T$5:$T17,Config!$B$7))
